Workbook
Name AC_KM: DATA!$Q$3:$Q$1385
Name BP_KM: DATA_BP!$K$2:$K$1043
Name AC_TKCO: DATA!$I$3:$I$1385
Name NHOM_QL: 'THAM CHIẾU'!$L$3:$L$60
Name AC_NHOMQL: DATA!$P$3:$P$1385
Name BP_QUY: DATA_BP!$C$2:$C$1043
Name MA_DOI: 'THAM CHIẾU'!$R$3:$R$35
Name AC_PHAITRA: DATA!$M$3:$M$1385
Name SDCDK: CDPS!$F$5:$F$222
Name SDNCK: CDPS!$I$5:$I$222
Name MA_DUAN: 'THAM CHIẾU'!$Z$3:$Z$82
Name TF_THANG: DATA_TF!$B$2:$B$1002
Name TF_DOI: DATA_TF!$H$2:$H$1002
Name SDCCK: CDPS!$J$5:$J$222
Name AC_DOI: DATA!$AA$3:$AA$1385
Name NAME: 'Thông tin chung'!$B$3
Name BP_THANG: DATA_BP!$B$2:$B$1043
Name AC_TKNO: DATA!$H$3:$H$1385
Name AC_QUY: DATA!$B$3:$B$1385
Name DM_NV: 'THAM CHIẾU'!$P$3:$S$367
Name MA_NV: 'THAM CHIẾU'!$P$3:$P$113
Name AC_SOTIEN: DATA!$J$3:$J$1385
Name MA_BP: 'THAM CHIẾU'!$U$3:$U$10
Name NHOM_KM: 'THAM CHIẾU'!$J$3:$J$60
Name DM_KM: 'THAM CHIẾU'!$H$3:$M$60
Name BP_DOI: DATA_BP!$H$2:$H$1043
Name BP_DA: DATA_BP!$E$2:$E$1043
Name MATK: CDPS!$B$5:$B$222
Name TF_KM: DATA_TF!$L$2:$L$1002
Name AC: DATA!$A$3:$AI$1385
Name TF_DA: DATA_TF!$E$2:$E$1002
Name THANG: 'THAM CHIẾU'!$D$3:$D$20
Name SDNDK: CDPS!$E$5:$E$222
Name MA_CODE: CDPS!$C$5:$C$222
Name NGHIEPVU: 'Quy chuẩn hạch toán'!$B$2:$B$100
Name AC_PHAITHU: DATA!$K$3:$K$1385
Name MA_KM: 'THAM CHIẾU'!$H$3:$H$60
Name AC_NGAY: DATA!$D$3:$D$1385
Name NGAY: 'THAM CHIẾU'!$A$3:$A$367
Name MA_DONGTIEN: DONGTIEN!$C$6:$C$80
Name DM_BP: 'THAM CHIẾU'!$U$3:$V$10
Name DM_DUAN: 'THAM CHIẾU'!$Z$3:$AC$367
Name MA_SP: 'THAM CHIẾU'!$X$3:$X$85
Name BP_SOTIEN: DATA_BP!$N$2:$N$1043
Name DM_SP: 'THAM CHIẾU'!$X$3:$Y$85
Name DM_DOI: 'THAM CHIẾU'!$R$3:$R$70
Name DM_CDT: 'THAM CHIẾU'!$AB$3:$AC$82
Name MA_CDT: 'THAM CHIẾU'!$AB$3:$AB$82
Name AC_THANG: DATA!$C$3:$C$1385
Name TF_QUY: DATA_TF!$C$2:$C$1002
Name TF_SOTIEN: DATA_TF!$N$2:$N$1002
Name AC_DA: DATA!$U$3:$U$1385

Sheet Thông tin chung
A1: THÔNG TIN CHUNG | D1: Phân quyền
C2: GHI CHÚ | D2: Nhập liệu | E2: Xem
A3: Tên công ty: | B3: Công Ty CP BĐS Đại Hùng Thịnh
A4: Địa chỉ: | B4: 46B Đường Trung Mỹ Tây 14A, Tổ 40, Khu phố 5, Phường Trung Mỹ Tây, Quận 12, TP. HCM
A5: VPGD: | B5: 482 Trường Chinh, P. Tân Hưng Thuận, Quận 12
A6: Mã số thuế | B6: 0316039733
A7: Điện thoại:
A8: Giám đốc | B8: Bùi Thị Tuyết Lan | E8: Tất cả
A9: Mail: | B9: tuyetlan.0238@gmail.com
A10: Kế toán trưởng | B10: Trần Thị Nguyệt Ánh
A11: Kế toán tổng hợp | D11: Tất cả
A12: Kế toán thuế | B12: Phan Thị Hồng Yến
A13: Thủ quỹ | B13: Trần Thị Nguyệt Ánh
A14: Ngành nghề kinh doanh chính | B14: Bất Động Sản
A15: Ngành nghề phụ
A16: Tài khoản ngân hàng 1: | B16: 60238560554 | C16: Sacombank-chi nhánh Quận 12
A17: Tài khoản ngân hàng 2:
A18: Tài khoản ngân hàng 3:
A19: Tài khoản ngân hàng 4

Sheet NOTE
A1: STT | B1: Ngày yêu cầu | C1: Cấp độ | D1: Nội dung | E1: Vấn đề | F1: Cần cải tiến | G1: Trạng thái | H1: Deadline | I1: Ngày hoàn thành | J1: Link hình ảnh
D2: Form tạo bút toán | E2: hình thức các ô và khoảng cách thông tin rộng nên để xem hết thông tin phải kéo thanh trượt xuống không thuận tiện - Các nội dung cần bố trí sắp xếp theo thứ tự phát sinh và thứ tự ưu tiên | G2: TRUE | I2: Cần tối ưu cả từ tiêu đề. Lấy kích thước chuẩn của dòng trong Excel để thiết kế theo
D3: Báo cáo thống kê | F3: Tổng hợp số lượng, giá trị theo yếu tố | G3: FALSE
G4: FALSE
B5: 46038 | D5: Thêm mới tài khoản | E5: Khi nhập sai -> không cho sửa -> Xóa nhập lại không cho phép nhập lại TK đã bị xóa | F5: 1. Cho phép sửa (sau này phân quyền quản lý cho phép mới đc sửa) | G5: TRUE | I5: Ok
B6: 46038 | D6: Thêm mới tài khoản | E6: Loại tài khoản | F6: Tên đúng là Nhóm tài khoản Danh mục gồm : Nợ Có Lưỡng tính (Số dư 2 bên) Không có số dư | G6: TRUE | I6: Ok
B7: 46038 | D7: Thêm mới tài khoản | E7: Nhóm tài khoản | F7: Tên đúng là Loại tài khoản gồm Tài sản Nợ phải trả Vốn chủ sở hữu Doanh thu Chi phí Thu nhập khác Chi phí khác Xác định kết quả kinh doanh | G7: TRUE | I7: Ok
B8: 46038 | D8: Thêm mới tài khoản | E8: Hiển thị danh sách theo thứ tự cập nhật | F8: Hiển thị theo thứ tự tài khoản từ nhỏ đến lớn | G8: TRUE | I8: Ok | J8: https://drive.google.com/file/d/1pNt0dop6MyupVnU7fcmHW-hV__S7wEXM/view?usp=drive_link
B9: 46038 | D9: Tài khoản kế toán | E9: Hiển thị 50 dòng | F9: Hiển thị 100 dòng 1 lần | G9: TRUE | I9: Ok | J9: https://drive.google.com/file/d/1-ylmpZm4I4pXZgl5mqQbyNCxDRTQlr_g/view?usp=drive_link
B10: 46038 | D10: Tên trên menu | E10: Chứng từ trùng tên của 1 nội dung khác | F10: Đổi tên Chứng từ thành DỮ LIỆU TỔNG HỢP | G10: FALSE | I10: Ok | J10: https://drive.google.com/file/d/1-1rHIjgzzNbLY35MTh-zmxxEg4PsO5b8/view?usp=drive_link
B11: 46038 | D11: Tên tiêu đề dữ liệu tổng hợp | F11: Đổi từ Loại CT thành LOẠI GIAO DỊCH Loại GD thành NGHIỆP VỤ | G11: FALSE | I11: Ok | J11: https://drive.google.com/file/d/1PZpyBl2tBqZ7z60XMT084kSh0pO_64Rz/view?usp=drive_link
B12: 46038 | D12: Tạo bút toán mới | E12: Tên tiêu đề các nội dung | F12: Đổi từ Loại CT thành LOẠI GIAO DỊCH Loại GD thành NGHIỆP VỤ | G12: FALSE | I12: Ok | J12: https://drive.google.com/file/d/1gW7rwp4NsGT0QUWcK-_k3BfQfQMMaAZO/view?usp=drive_link
B13: 46038 | D13: Tạo bút toán mới | E13: Thiếu các phần nhập thông tin bổ sung | F13: Giao diện đầy đủ | G13: FALSE | I13: Ok | J13: https://drive.google.com/file/d/1qa5MgXniKkQgesSpS_MzM-L5TLl8DJ4p/view?usp=drive_link
B14: 46038 | D14: Thêm quy chuẩn hạch toán | E14: Tài khoản Nợ và TK Có chưa hiển thị các tài khoản được thêm mới và tài khoản con | F14: Hiển thị để lựa chọn Nếu TK nào có TK con thì danh mục hiển thị là TK con (hiển thị cấp nhỏ nhất) Nếu TK nào không có TK con thì hiển thị TK cha | G14: FALSE | I14: Quy chuẩn hạch toán là 1 dạng quy định chuyên môn k để ở mục cài đặt ứng dụng Chưa chọn được tài khoản
B15: 46038 | D15: Phân quyền | E15: Chưa có vai trò của Giám đốc; Kế toán trưởng | F15: Bổ sung vai trò của Giám đốc; Kế toán trưởng Thay kiểm toán = kiểm soát | G15: FALSE | I15: Nên để mở cho DN tự tạo vị trí chức năng theo sơ đồ tổ chức của họ | J15: https://drive.google.com/file/d/1Q4_7_4bWH6x8v55110n1TXCch8ezRD2L/view?usp=drive_link
B16: 46038 | D16: Menu chính | E16: Chưa đủ nhóm theo cơ cấu | F16: Phân làm 3 nhóm chính 1. Tổng quan (mặc định mở phần mềm lên sẽ nhìn thấy giao diện tổng quan tất cả) 2. Nhóm làm việc thường xuyên gồm - Chứng từ - Trung tâm dữ liệu (các kho dữ liệu ) - Báo cáo - Phân tích 3. Nhóm chỉ phát sinh nhập 1 lần gồm - Danh mục - Quy chế - Chính sách - Biểu mẫu - Hướng dẫn **** Phần cấu hình, cài đặt, phân quyền chuyển lên thanh công cụ ngang và ẩn trong biểu tượng hình bánh răng | G16: FALSE | I16: Ok | J16: https://drive.google.com/file/d/1QjODKjB-EDR4CUXVpb7E44n5Ahgrcoxz/view?usp=drive_link
B17: 46038 | D17: Khoản mục | E17: Nhóm khoản mục cứng nhưng sai thông tin | F17: Tạo danh mục nhóm khoản mục để kế toán tự tạo và thêm tùy theo yêu cầu quản lý từng DN | G17: FALSE | I17: Chưa chọn được nhóm KM | J17: https://drive.google.com/file/d/1_fYg_aYkCnUouhMi21SV-1Ww5K01nUua/view?usp=drive_link
B18: 46038 | D18: Thêm đối tượng | E18: Mã số thuế tự nguyện | F18: Mã số thuế để trạng thái bắt buộc | G18: TRUE | I18: Ok | J18: https://drive.google.com/file/d/1nMCUWROUFtwYBpnEj-kfh_uvEO72lECn/view?usp=drive_link
B19: 46039 | D19: Danh mục hợp đồng | E19: Chưa có | F19: Bổ sung danh mục hợp đồng (lưu ý mã hợp đồng để dài hơn 20 ký tự | G19: TRUE | I19: Ok | J19: https://docs.google.com/spreadsheets/d/1zOIjlZHAJdqlLKizt3NXUUB7_A3WzMF713_Zyu2G-cs/edit?gid=681765774#gid=681765774
D20: Số dư đầu kỳ | E20: Chưa có cột số dư đầu của dữ liệu, với các Cty làm giữa chừng | F20: Tạo danh mục số dư đầu kỳ | G20: FALSE
G21: FALSE
G22: FALSE
G23: FALSE
G24: FALSE
G25: FALSE
G26: FALSE
G27: FALSE
G28: FALSE
G29: FALSE

Sheet DATA
A1: Nhập tay | D1: Chọn | E1: Nhập tay | F1: Chọn | G1: Chọn | H1: Tự động theo nghiệp vụ | J1: Nhập tay | K1: Chọn | L1: Tự động theo mã phải thu | M1: Chọn | N1: Tự động theo mã phải trả | O1: Tự động theo nghiệp vụ | Q1: Chọn | R1: Tự động theo nghiệp vụ | S1: Chọn | T1: Tự động theo mã CĐT | U1: Chọn | V1: Tự động theo mã dự án | W1: Chọn | X1: Tự động theo mã sản phẩm | Y1: Chọn | Z1: Tự động theo mã bộ phận | AA1: Chọn | AB1: Tự động theo mã đội | AC1: Chọn | AD1: Tự động theo mã nhân viên | AE1: Chọn | AF1: Tự động theo mã dòng tiền | AG1: Nhập tay | AH1: Nhập tay | AI1: Nhập tay | AJ1: Nhập tay | AK1: Nhập tay | AL1: Chọn | AM1: Chọn | AN1: Chọn | AO1: Nhập tay | AP1: Nhập tay | AQ1: Nhập tay | AR1: Chọn | AS1: Chọn | AT1: Chọn
A2: Số PHIẾU | B2: QUÝ | C2: Tháng | D2: Ngày | E2: DIỄN GIẢI | F2: Loại giao dịch | G2: NGHIỆP VỤ/GIAO DỊCH | H2: TK NỢ | I2: TK CÓ | J2: Số tiền | K2: Mã phải thu | L2: Tên đối tượng phải thu | M2: Mã phải trả | N2: Tên đối tượng phải trả | O2: NHÓM KM | P2: NHÓM QL | Q2: Mã KHOẢN MỤC | R2: Tên khoản mục | S2: Mã CHỦ ĐẦU TƯ | T2: Tên chủ đầu tư | U2: DỰ ÁN | V2: Tên dự án | W2: SẢN PHẨM | X2: Tên sản phẩm | Y2: BỘ PHẬN | Z2: Tên bộ phận | AA2: ĐỘI | AB2: Tên đội | AC2: Mã NV | AD2: Tên nhân viên | AE2: Mã DÒNG TIỀN | AF2: Tên dòng tiền | AG2: Người giao dịch | AH2: Địa chỉ | AI2: Ghi chú | AJ2: Seri | AK2: Số | AL2: Ngày | AM2: KH/Nhà cung cấp | AN2: MST | AO2: Tên hàng hóa | AP2: Tiền hàng | AQ2: Tiền thuế | AR2: Kỳ kê khai | AS2: Biên tập hồ sơ | AT2: Ý KIẾN KIỂM SOÁT VIÊN
B3: =IF(D3="","",VLOOKUP(D3,'THAM CHIẾU'!$A:$B,2,0)) -> #N/A | C3: =if(D3<>0,TEXT(D3,"mm/yyyy"),"") -> 01/2022 | D3: 44563 | E3: Góp vốn kinh doanh bằng tài sản công cụ đầu tư ban đầu | G3: Góp vốn kinh doanh bằng công cụ, dụng cụ | H3: =IF(G3="","",VLOOKUP($G3,'Quy chuẩn hạch toán'!$B:$E,2,0)) -> 1531 | I3: =IF(H3="","",VLOOKUP($G3,'Quy chuẩn hạch toán'!$B:$E,3,0)) -> 4111 | J3: 1350000000 | AT3: Không được trừ
A4: PT | B4: =IF(D4="","",VLOOKUP(D4,'THAM CHIẾU'!$A:$B,2,0)) -> #N/A | C4: =if(D4<>0,TEXT(D4,"mm/yyyy"),"") -> 01/2022 | D4: 44563 | E4: Thu tiền hàng | G4: Phải thu vốn góp kinh doanh | H4: =IF(G4="","",VLOOKUP($G4,'Quy chuẩn hạch toán'!$B:$E,2,0)) -> 1385 | I4: =IF(H4="","",VLOOKUP($G4,'Quy chuẩn hạch toán'!$B:$E,3,0)) -> 4111 | J4: 500000000 | K4: Cường | Q4: MKT | AT4: Hợp lệ
B5: =IF(D5="","",VLOOKUP(D5,'THAM CHIẾU'!$A:$B,2,0)) -> #N/A | C5: =if(D5<>0,TEXT(D5,"mm/yyyy"),"") -> 01/2022 | D5: 44563 | H5: =IF(G5="","",VLOOKUP($G5,'Quy chuẩn hạch toán'!$B:$E,2,0)) | I5: =IF(H5="","",VLOOKUP($G5,'Quy chuẩn hạch toán'!$B:$E,3,0))
B6: =IF(D6="","",VLOOKUP(D6,'THAM CHIẾU'!$A:$B,2,0)) -> #N/A | C6: =if(D6<>0,TEXT(D6,"mm/yyyy"),"") -> 01/2022 | D6: 44563 | G6: Thu khách hàng trả trước HĐ bằng TM | H6: 112 | I6: =IF(H6="","",VLOOKUP($G6,'Quy chuẩn hạch toán'!$B:$E,3,0)) -> 131 | J6: 783565
B7: =IF(D7="","",VLOOKUP(D7,'THAM CHIẾU'!$A:$B,2,0)) -> #N/A | C7: =if(D7<>0,TEXT(D7,"mm/yyyy"),"") -> 01/2022 | D7: 44563 | G7: Thu khách hàng trả trước HĐ bằng TM | H7: =IF(G7="","",VLOOKUP($G7,'Quy chuẩn hạch toán'!$B:$E,2,0)) -> 1111 | I7: =IF(H7="","",VLOOKUP($G7,'Quy chuẩn hạch toán'!$B:$E,3,0)) -> 131
B8: =IF(D8="","",VLOOKUP(D8,'THAM CHIẾU'!$A:$B,2,0)) -> #N/A | C8: =if(D8<>0,TEXT(D8,"mm/yyyy"),"") -> 01/2022 | D8: 44563 | H8: =IF(G8="","",VLOOKUP($G8,'Quy chuẩn hạch toán'!$B:$E,2,0)) | I8: =IF(H8="","",VLOOKUP($G8,'Quy chuẩn hạch toán'!$B:$E,3,0))
B9: =IF(D9="","",VLOOKUP(D9,'THAM CHIẾU'!$A:$B,2,0)) -> #N/A | C9: =if(D9<>0,TEXT(D9,"mm/yyyy"),"") -> 01/2022 | D9: 44563 | H9: =IF(G9="","",VLOOKUP($G9,'Quy chuẩn hạch toán'!$B:$E,2,0)) | I9: =IF(H9="","",VLOOKUP($G9,'Quy chuẩn hạch toán'!$B:$E,3,0))
B10: =IF(D10="","",VLOOKUP(D10,'THAM CHIẾU'!$A:$B,2,0)) -> #N/A | C10: =if(D10<>0,TEXT(D10,"mm/yyyy"),"") -> 01/2022 | D10: 44563 | H10: =IF(G10="","",VLOOKUP($G10,'Quy chuẩn hạch toán'!$B:$E,2,0)) | I10: =IF(H10="","",VLOOKUP($G10,'Quy chuẩn hạch toán'!$B:$E,3,0))
B11: =IF(D11="","",VLOOKUP(D11,'THAM CHIẾU'!$A:$B,2,0)) -> #N/A | C11: =if(D11<>0,TEXT(D11,"mm/yyyy"),"") -> 01/2022 | D11: 44563 | H11: =IF(G11="","",VLOOKUP($G11,'Quy chuẩn hạch toán'!$B:$E,2,0)) | I11: =IF(H11="","",VLOOKUP($G11,'Quy chuẩn hạch toán'!$B:$E,3,0))
B12: =IF(D12="","",VLOOKUP(D12,'THAM CHIẾU'!$A:$B,2,0)) -> #N/A | C12: =if(D12<>0,TEXT(D12,"mm/yyyy"),"") -> 01/2022 | D12: 44563 | H12: =IF(G12="","",VLOOKUP($G12,'Quy chuẩn hạch toán'!$B:$E,2,0)) | I12: =IF(H12="","",VLOOKUP($G12,'Quy chuẩn hạch toán'!$B:$E,3,0))
B13: =IF(D13="","",VLOOKUP(D13,'THAM CHIẾU'!$A:$B,2,0)) -> #N/A | C13: =if(D13<>0,TEXT(D13,"mm/yyyy"),"") -> 01/2022 | D13: 44563 | E13: (c Xuân) Đón 482-Phước Đông- Hồ Tràm- Cảng cá =2.500 đội Quân | G13: Chi phí bán hàng chưa thanh toán | H13: =IF(G13="","",VLOOKUP($G13,'Quy chuẩn hạch toán'!$B:$E,2,0)) -> 641 | I13: =IF(H13="","",VLOOKUP($G13,'Quy chuẩn hạch toán'!$B:$E,3,0)) -> 331 | J13: 2500000 | O13: =IF($Q13<>0,VLOOKUP($Q13,DM_KM,3,0),"") -> #N/A | P13: =IF($Q13<>0,VLOOKUP($Q13,DM_KM,5,0),"") -> #N/A | Q13: THUEXE | R13: =IF(S13<>0,VLOOKUP(S13,DM_DUAN,3,0),"") -> #N/A | S13: =IF(U13<>0,VLOOKUP(U13,DM_DUAN,3,0),"") -> THANHNAM | U13: PHUOCHOI | V13: =IF(W13<>0,VLOOKUP(W13,DM_DUAN,3,0),"") | X13: =IF(Y13<>0,VLOOKUP(Y13,DM_DUAN,3,0),"") -> #N/A | Y13: BP.KD | Z13: =IF(AA13<>0,VLOOKUP(AA13,DM_DUAN,3,0),"") -> #N/A | AA13: QUAN | AB13: =IF(AC13<>0,VLOOKUP(AC13,DM_DUAN,3,0),"") -> #N/A | AC13: L0006 | AD13: =IF(AC13<>0,VLOOKUP(AC13,DM_NV,2,0),"") -> Lê Hoàng Quân | AF13: =IF(AE13<>0,VLOOKUP(AE13,DM_NV,2,0),"")
B14: =IF(D14="","",VLOOKUP(D14,'THAM CHIẾU'!$A:$B,2,0)) -> #N/A | C14: =if(D14<>0,TEXT(D14,"mm/yyyy"),"") -> 01/2022 | D14: 44563 | E14: LK5-15 - Vy - Chiết khấu | G14: Chiết khấu hàng bán | H14: =IF(G14="","",VLOOKUP($G14,'Quy chuẩn hạch toán'!$B:$E,2,0)) -> 521 | I14: =IF(H14="","",VLOOKUP($G14,'Quy chuẩn hạch toán'!$B:$E,3,0)) -> 131 | J14: 8000000 | O14: =IF($Q14<>0,VLOOKUP($Q14,DM_KM,3,0),"") -> #N/A | P14: =IF($Q14<>0,VLOOKUP($Q14,DM_KM,5,0),"") -> #N/A | Q14: CHIETKHAU | U14: PHUOCHOI | W14: PH.LK5-15 | Y14: BP.KD | AA14: VY | AD14: =IF(AC14<>0,VLOOKUP(AC14,DM_NV,2,0),"") | AF14: =IF(AE14<>0,VLOOKUP(AE14,DM_NV,2,0),"") | AG14: TT online
B15: =IF(D15="","",VLOOKUP(D15,'THAM CHIẾU'!$A:$B,2,0)) -> #N/A | C15: =if(D15<>0,TEXT(D15,"mm/yyyy"),"") -> 01/2022 | D15: 44563 | E15: LK5-15 - Vy - HH Sàn | G15: Ghi nhận doanh thu bán hàng chưa thu tiền | H15: =IF(G15="","",VLOOKUP($G15,'Quy chuẩn hạch toán'!$B:$E,2,0)) -> 131 | I15: =IF(H15="","",VLOOKUP($G15,'Quy chuẩn hạch toán'!$B:$E,3,0)) -> 5113 | J15: 160000000 | O15: =IF($Q15<>0,VLOOKUP($Q15,DM_KM,3,0),"") -> 511_TK | P15: =IF($Q15<>0,VLOOKUP($Q15,DM_KM,5,0),"") -> 511 | Q15: DOANHTHU | R15: =IF(S15<>0,VLOOKUP(S15,DM_DUAN,3,0),"") -> #N/A | S15: =IF(U15<>0,VLOOKUP(U15,DM_DUAN,3,0),"") -> THANHNAM | U15: PHUOCHOI | V15: =IF(W15<>0,VLOOKUP(W15,DM_DUAN,3,0),"") -> #N/A | W15: PH.LK5-15 | X15: =IF(Y15<>0,VLOOKUP(Y15,DM_DUAN,3,0),"") | Z15: =IF(AA15<>0,VLOOKUP(AA15,DM_DUAN,3,0),"") -> #N/A | AA15: VY | AB15: =IF(AC15<>0,VLOOKUP(AC15,DM_DUAN,3,0),"") | AD15: =IF(AC15<>0,VLOOKUP(AC15,DM_NV,2,0),"") | AF15: =IF(AE15<>0,VLOOKUP(AE15,DM_NV,2,0),"")
B16: =IF(D16="","",VLOOKUP(D16,'THAM CHIẾU'!$A:$B,2,0)) -> #N/A | C16: =if(D16<>0,TEXT(D16,"mm/yyyy"),"") -> 01/2022 | D16: 44563 | E16: LK5-15 - Vy - HHNV | G16: Phải trả hoa hồng nhân viên | H16: =IF(G16="","",VLOOKUP($G16,'Quy chuẩn hạch toán'!$B:$E,2,0)) -> 154 | I16: =IF(H16="","",VLOOKUP($G16,'Quy chuẩn hạch toán'!$B:$E,3,0)) -> 3345 | J16: 62000000 | O16: =IF($Q16<>0,VLOOKUP($Q16,DM_KM,3,0),"") -> #N/A | P16: =IF($Q16<>0,VLOOKUP($Q16,DM_KM,5,0),"") -> #N/A | Q16: HOAHONGNV | R16: =IF(S16<>0,VLOOKUP(S16,DM_DUAN,3,0),"") -> #N/A | S16: =IF(U16<>0,VLOOKUP(U16,DM_DUAN,3,0),"") -> THANHNAM | U16: PHUOCHOI | V16: =IF(W16<>0,VLOOKUP(W16,DM_DUAN,3,0),"") -> #N/A | W16: PH.LK5-15 | X16: =IF(Y16<>0,VLOOKUP(Y16,DM_DUAN,3,0),"") -> #N/A | Y16: BP.KD | Z16: =IF(AA16<>0,VLOOKUP(AA16,DM_DUAN,3,0),"") -> #N/A | AA16: VY | AB16: =IF(AC16<>0,VLOOKUP(AC16,DM_DUAN,3,0),"") -> #N/A | AC16: L0004 | AD16: =IF(AC16<>0,VLOOKUP(AC16,DM_NV,2,0),"") -> Nguyễn Anh Vy | AF16: =IF(AE16<>0,VLOOKUP(AE16,DM_NV,2,0),"")
B17: =IF(D17="","",VLOOKUP(D17,'THAM CHIẾU'!$A:$B,2,0)) -> #N/A | C17: =if(D17<>0,TEXT(D17,"mm/yyyy"),"") -> 01/2022 | D17: 44563 | E17: LK5-15 - Vy - HHTP | G17: Phải trả hoa hồng trưởng phòng | H17: =IF(G17="","",VLOOKUP($G17,'Quy chuẩn hạch toán'!$B:$E,2,0)) -> 154 | I17: =IF(H17="","",VLOOKUP($G17,'Quy chuẩn hạch toán'!$B:$E,3,0)) -> 3344 | J17: 4500000 | O17: =IF($Q17<>0,VLOOKUP($Q17,DM_KM,3,0),"") -> #N/A | P17: =IF($Q17<>0,VLOOKUP($Q17,DM_KM,5,0),"") -> #N/A | Q17: HOAHONGLD | R17: =IF(S17<>0,VLOOKUP(S17,DM_DUAN,3,0),"") -> #N/A | S17: =IF(U17<>0,VLOOKUP(U17,DM_DUAN,3,0),"") -> THANHNAM | U17: PHUOCHOI | V17: =IF(W17<>0,VLOOKUP(W17,DM_DUAN,3,0),"") -> #N/A | W17: PH.LK5-15 | X17: =IF(Y17<>0,VLOOKUP(Y17,DM_DUAN,3,0),"") -> #N/A | Y17: BP.KD | Z17: =IF(AA17<>0,VLOOKUP(AA17,DM_DUAN,3,0),"") -> #N/A | AA17: VY | AB17: =IF(AC17<>0,VLOOKUP(AC17,DM_DUAN,3,0),"") -> #N/A | AC17: S0011 | AD17: =IF(AC17<>0,VLOOKUP(AC17,DM_NV,2,0),"") -> Phan Thị Thùy Mai | AF17: =IF(AE17<>0,VLOOKUP(AE17,DM_NV,2,0),"")
B18: =IF(D18="","",VLOOKUP(D18,'THAM CHIẾU'!$A:$B,2,0)) -> #N/A | C18: =if(D18<>0,TEXT(D18,"mm/yyyy"),"") -> 01/2022 | D18: 44563 | E18: LK5-15 - Vy - Ký HĐ | G18: Ghi nhận doanh số hàng bán | H18: =IF(G18="","",VLOOKUP($G18,'Quy chuẩn hạch toán'!$B:$E,2,0)) -> #N/A | I18: =IF(H18="","",VLOOKUP($G18,'Quy chuẩn hạch toán'!$B:$E,3,0)) -> #N/A | J18: 1750000000 | O18: =IF($Q18<>0,VLOOKUP($Q18,DM_KM,3,0),"") -> #N/A | P18: =IF($Q18<>0,VLOOKUP($Q18,DM_KM,5,0),"") -> #N/A | Q18: DOANHSO | R18: =IF(S18<>0,VLOOKUP(S18,DM_DUAN,3,0),"") -> #N/A | S18: =IF(U18<>0,VLOOKUP(U18,DM_DUAN,3,0),"") -> THANHNAM | U18: PHUOCHOI | V18: =IF(W18<>0,VLOOKUP(W18,DM_DUAN,3,0),"") -> #N/A | W18: PH.LK5-15 | X18: =IF(Y18<>0,VLOOKUP(Y18,DM_DUAN,3,0),"") -> #N/A | Y18: BP.KD | Z18: =IF(AA18<>0,VLOOKUP(AA18,DM_DUAN,3,0),"") -> #N/A | AA18: VY | AB18: =IF(AC18<>0,VLOOKUP(AC18,DM_DUAN,3,0),"") -> #N/A | AC18: L0004 | AD18: =IF(AC18<>0,VLOOKUP(AC18,DM_NV,2,0),"") -> Nguyễn Anh Vy | AF18: =IF(AE18<>0,VLOOKUP(AE18,DM_NV,2,0),"") | AG18: TT online
B19: =IF(D19="","",VLOOKUP(D19,'THAM CHIẾU'!$A:$B,2,0)) -> #N/A | C19: =if(D19<>0,TEXT(D19,"mm/yyyy"),"") -> 01/2022 | D19: 44563 | E19: LK5-15 - Vy - Phí hỗ trợ | G19: Chi phí hỗ trợ quản lý | H19: =IF(G19="","",VLOOKUP($G19,'Quy chuẩn hạch toán'!$B:$E,2,0)) -> 154 | I19: =IF(H19="","",VLOOKUP($G19,'Quy chuẩn hạch toán'!$B:$E,3,0)) -> 3343 | J19: 1000000 | O19: =IF($Q19<>0,VLOOKUP($Q19,DM_KM,3,0),"") -> #N/A | P19: =IF($Q19<>0,VLOOKUP($Q19,DM_KM,5,0),"") -> #N/A | Q19: HTQL | U19: PHUOCHOI | W19: PH.LK5-15 | AA19: VY | AD19: =IF(AC19<>0,VLOOKUP(AC19,DM_NV,2,0),"") | AF19: =IF(AE19<>0,VLOOKUP(AE19,DM_NV,2,0),"")
B20: =IF(D20="","",VLOOKUP(D20,'THAM CHIẾU'!$A:$B,2,0)) -> #N/A | C20: =if(D20<>0,TEXT(D20,"mm/yyyy"),"") -> 01/2022 | D20: 44563 | E20: LK5-15 - Vy - Trích 8% | H20: =IF(G20="","",VLOOKUP($G20,'Quy chuẩn hạch toán'!$B:$E,2,0)) | I20: =IF(H20="","",VLOOKUP($G20,'Quy chuẩn hạch toán'!$B:$E,3,0)) | J20: 12000000 | O20: =IF($Q20<>0,VLOOKUP($Q20,DM_KM,3,0),"") -> #N/A | P20: =IF($Q20<>0,VLOOKUP($Q20,DM_KM,5,0),"") -> #N/A | Q20: QUY8% | R20: =IF(S20<>0,VLOOKUP(S20,DM_DUAN,3,0),"") -> #N/A | S20: =IF(U20<>0,VLOOKUP(U20,DM_DUAN,3,0),"") -> THANHNAM | U20: PHUOCHOI | V20: =IF(W20<>0,VLOOKUP(W20,DM_DUAN,3,0),"") -> #N/A | W20: PH.LK5-15 | X20: =IF(Y20<>0,VLOOKUP(Y20,DM_DUAN,3,0),"") | Z20: =IF(AA20<>0,VLOOKUP(AA20,DM_DUAN,3,0),"") -> #N/A | AA20: VY | AB20: =IF(AC20<>0,VLOOKUP(AC20,DM_DUAN,3,0),"") | AD20: =IF(AC20<>0,VLOOKUP(AC20,DM_NV,2,0),"") | AF20: =IF(AE20<>0,VLOOKUP(AE20,DM_NV,2,0),"")
B21: =IF(D21="","",VLOOKUP(D21,'THAM CHIẾU'!$A:$B,2,0)) -> #N/A | C21: =if(D21<>0,TEXT(D21,"mm/yyyy"),"") -> 01/2022 | D21: 44563 | E21: Thanh toán cước Internet - line 1: t008_gftth_thynna8 | G21: Thanh toán tiền mua DV ngoài cho công tác Quản lý | H21: =IF(G21="","",VLOOKUP($G21,'Quy chuẩn hạch toán'!$B:$E,2,0)) -> 642 | I21: =IF(H21="","",VLOOKUP($G21,'Quy chuẩn hạch toán'!$B:$E,3,0)) -> 1111 | J21: 57143 | O21: =IF($Q21<>0,VLOOKUP($Q21,DM_KM,3,0),"") -> #N/A | P21: =IF($Q21<>0,VLOOKUP($Q21,DM_KM,5,0),"") -> #N/A | Q21: INTERNET | R21: =IF(S21<>0,VLOOKUP(S21,DM_DUAN,3,0),"") -> #N/A | S21: =IF(U21<>0,VLOOKUP(U21,DM_DUAN,3,0),"") | V21: =IF(W21<>0,VLOOKUP(W21,DM_DUAN,3,0),"") | X21: =IF(Y21<>0,VLOOKUP(Y21,DM_DUAN,3,0),"") -> #N/A | Y21: BP.HC-NS | Z21: =IF(AA21<>0,VLOOKUP(AA21,DM_DUAN,3,0),"") -> #N/A | AA21: THU | AB21: =IF(AC21<>0,VLOOKUP(AC21,DM_DUAN,3,0),"") | AD21: =IF(AC21<>0,VLOOKUP(AC21,DM_NV,2,0),"") | AE21: VIENTHONG | AF21: =IF(AE21<>0,VLOOKUP(AE21,DM_NV,2,0),"") -> #N/A
B22: =IF(D22="","",VLOOKUP(D22,'THAM CHIẾU'!$A:$B,2,0)) -> #N/A | C22: =if(D22<>0,TEXT(D22,"mm/yyyy"),"") -> 01/2022 | D22: 44563 | E22: Thanh toán cước Internet - line 1: t008_gftth_thynna8 | G22: Thanh toán tiền mua DV ngoài cho công tác Quản lý | H22: =IF(G22="","",VLOOKUP($G22,'Quy chuẩn hạch toán'!$B:$E,2,0)) -> 642 | I22: =IF(H22="","",VLOOKUP($G22,'Quy chuẩn hạch toán'!$B:$E,3,0)) -> 1111 | J22: 38095 | O22: =IF($Q22<>0,VLOOKUP($Q22,DM_KM,3,0),"") -> #N/A | P22: =IF($Q22<>0,VLOOKUP($Q22,DM_KM,5,0),"") -> #N/A | Q22: INTERNET | R22: =IF(S22<>0,VLOOKUP(S22,DM_DUAN,3,0),"") -> #N/A | S22: =IF(U22<>0,VLOOKUP(U22,DM_DUAN,3,0),"") | V22: =IF(W22<>0,VLOOKUP(W22,DM_DUAN,3,0),"") | X22: =IF(Y22<>0,VLOOKUP(Y22,DM_DUAN,3,0),"") -> #N/A | Y22: BP.HC-NS | Z22: =IF(AA22<>0,VLOOKUP(AA22,DM_DUAN,3,0),"") -> #N/A | AA22: NAM | AB22: =IF(AC22<>0,VLOOKUP(AC22,DM_DUAN,3,0),"") | AD22: =IF(AC22<>0,VLOOKUP(AC22,DM_NV,2,0),"") | AE22: VIENTHONG | AF22: =IF(AE22<>0,VLOOKUP(AE22,DM_NV,2,0),"") -> #N/A
B23: =IF(D23="","",VLOOKUP(D23,'THAM CHIẾU'!$A:$B,2,0)) -> #N/A | C23: =if(D23<>0,TEXT(D23,"mm/yyyy"),"") -> 01/2022 | D23: 44563 | E23: Thanh toán cước Internet - line 1: t008_gftth_thynna8 | G23: Thanh toán tiền mua DV ngoài cho công tác Quản lý | H23: =IF(G23="","",VLOOKUP($G23,'Quy chuẩn hạch toán'!$B:$E,2,0)) -> 642 | I23: =IF(H23="","",VLOOKUP($G23,'Quy chuẩn hạch toán'!$B:$E,3,0)) -> 1111 | J23: 76190 | O23: =IF($Q23<>0,VLOOKUP($Q23,DM_KM,3,0),"") -> #N/A | P23: =IF($Q23<>0,VLOOKUP($Q23,DM_KM,5,0),"") -> #N/A | Q23: INTERNET | R23: =IF(S23<>0,VLOOKUP(S23,DM_DUAN,3,0),"") -> #N/A | S23: =IF(U23<>0,VLOOKUP(U23,DM_DUAN,3,0),"") | V23: =IF(W23<>0,VLOOKUP(W23,DM_DUAN,3,0),"") | X23: =IF(Y23<>0,VLOOKUP(Y23,DM_DUAN,3,0),"") -> #N/A | Y23: BP.HC-NS | Z23: =IF(AA23<>0,VLOOKUP(AA23,DM_DUAN,3,0),"") -> #N/A | AA23: VY | AB23: =IF(AC23<>0,VLOOKUP(AC23,DM_DUAN,3,0),"") | AD23: =IF(AC23<>0,VLOOKUP(AC23,DM_NV,2,0),"") | AE23: VIENTHONG | AF23: =IF(AE23<>0,VLOOKUP(AE23,DM_NV,2,0),"") -> #N/A
B24: =IF(D24="","",VLOOKUP(D24,'THAM CHIẾU'!$A:$B,2,0)) -> #N/A | C24: =if(D24<>0,TEXT(D24,"mm/yyyy"),"") -> 01/2022 | D24: 44563 | E24: Thanh toán cước Internet - line 1: t008_gftth_thynna8 | G24: Thanh toán tiền mua DV ngoài cho công tác Quản lý | H24: =IF(G24="","",VLOOKUP($G24,'Quy chuẩn hạch toán'!$B:$E,2,0)) -> 642 | I24: =IF(H24="","",VLOOKUP($G24,'Quy chuẩn hạch toán'!$B:$E,3,0)) -> 1111 | J24: 28571 | O24: =IF($Q24<>0,VLOOKUP($Q24,DM_KM,3,0),"") -> #N/A | P24: =IF($Q24<>0,VLOOKUP($Q24,DM_KM,5,0),"") -> #N/A | Q24: INTERNET | R24: =IF(S24<>0,VLOOKUP(S24,DM_DUAN,3,0),"") -> #N/A | S24: =IF(U24<>0,VLOOKUP(U24,DM_DUAN,3,0),"") | V24: =IF(W24<>0,VLOOKUP(W24,DM_DUAN,3,0),"") | X24: =IF(Y24<>0,VLOOKUP(Y24,DM_DUAN,3,0),"") -> #N/A | Y24: BP.HC-NS | Z24: =IF(AA24<>0,VLOOKUP(AA24,DM_DUAN,3,0),"") -> #N/A | AA24: QUAN | AB24: =IF(AC24<>0,VLOOKUP(AC24,DM_DUAN,3,0),"") | AD24: =IF(AC24<>0,VLOOKUP(AC24,DM_NV,2,0),"") | AE24: VIENTHONG | AF24: =IF(AE24<>0,VLOOKUP(AE24,DM_NV,2,0),"") -> #N/A | AG24: Anh
B25: =IF(D25="","",VLOOKUP(D25,'THAM CHIẾU'!$A:$B,2,0)) -> #N/A | C25: =if(D25<>0,TEXT(D25,"mm/yyyy"),"") -> 01/2022 | D25: 44563 | E25: Thanh toán cước Internet - line 2: t008_gftth_thuntm408 | G25: Thanh toán tiền mua DV ngoài cho công tác Quản lý | H25: =IF(G25="","",VLOOKUP($G25,'Quy chuẩn hạch toán'!$B:$E,2,0)) -> 642 | I25: =IF(H25="","",VLOOKUP($G25,'Quy chuẩn hạch toán'!$B:$E,3,0)) -> 1111 | J25: 251429 | O25: =IF($Q25<>0,VLOOKUP($Q25,DM_KM,3,0),"") -> #N/A | P25: =IF($Q25<>0,VLOOKUP($Q25,DM_KM,5,0),"") -> #N/A | Q25: INTERNET | R25: =IF(S25<>0,VLOOKUP(S25,DM_DUAN,3,0),"") -> #N/A | S25: =IF(U25<>0,VLOOKUP(U25,DM_DUAN,3,0),"") | V25: =IF(W25<>0,VLOOKUP(W25,DM_DUAN,3,0),"") | X25: =IF(Y25<>0,VLOOKUP(Y25,DM_DUAN,3,0),"") -> #N/A | Y25: BP.HC-NS | Z25: =IF(AA25<>0,VLOOKUP(AA25,DM_DUAN,3,0),"") -> #N/A | AA25: THU | AB25: =IF(AC25<>0,VLOOKUP(AC25,DM_DUAN,3,0),"") | AD25: =IF(AC25<>0,VLOOKUP(AC25,DM_NV,2,0),"") | AE25: VIENTHONG | AF25: =IF(AE25<>0,VLOOKUP(AE25,DM_NV,2,0),"") -> #N/A
B26: =IF(D26="","",VLOOKUP(D26,'THAM CHIẾU'!$A:$B,2,0)) -> #N/A | C26: =if(D26<>0,TEXT(D26,"mm/yyyy"),"") -> 01/2022 | D26: 44563 | E26: Thanh toán cước Internet - line 2: t008_gftth_thuntm408 | G26: Thanh toán tiền mua DV ngoài cho công tác Quản lý | H26: =IF(G26="","",VLOOKUP($G26,'Quy chuẩn hạch toán'!$B:$E,2,0)) -> 642 | I26: =IF(H26="","",VLOOKUP($G26,'Quy chuẩn hạch toán'!$B:$E,3,0)) -> 1111 | J26: 167619 | O26: =IF($Q26<>0,VLOOKUP($Q26,DM_KM,3,0),"") -> #N/A | P26: =IF($Q26<>0,VLOOKUP($Q26,DM_KM,5,0),"") -> #N/A | Q26: INTERNET | R26: =IF(S26<>0,VLOOKUP(S26,DM_DUAN,3,0),"") -> #N/A | S26: =IF(U26<>0,VLOOKUP(U26,DM_DUAN,3,0),"") | V26: =IF(W26<>0,VLOOKUP(W26,DM_DUAN,3,0),"") | X26: =IF(Y26<>0,VLOOKUP(Y26,DM_DUAN,3,0),"") -> #N/A | Y26: BP.HC-NS | Z26: =IF(AA26<>0,VLOOKUP(AA26,DM_DUAN,3,0),"") -> #N/A | AA26: NAM | AB26: =IF(AC26<>0,VLOOKUP(AC26,DM_DUAN,3,0),"") | AD26: =IF(AC26<>0,VLOOKUP(AC26,DM_NV,2,0),"") | AE26: VIENTHONG | AF26: =IF(AE26<>0,VLOOKUP(AE26,DM_NV,2,0),"") -> #N/A
B27: =IF(D27="","",VLOOKUP(D27,'THAM CHIẾU'!$A:$B,2,0)) -> #N/A | C27: =if(D27<>0,TEXT(D27,"mm/yyyy"),"") -> 01/2022 | D27: 44563 | E27: Thanh toán cước Internet - line 2: t008_gftth_thuntm408 | G27: Thanh toán tiền mua DV ngoài cho công tác Quản lý | H27: =IF(G27="","",VLOOKUP($G27,'Quy chuẩn hạch toán'!$B:$E,2,0)) -> 642 | I27: =IF(H27="","",VLOOKUP($G27,'Quy chuẩn hạch toán'!$B:$E,3,0)) -> 1111 | J27: 335238 | O27: =IF($Q27<>0,VLOOKUP($Q27,DM_KM,3,0),"") -> #N/A | P27: =IF($Q27<>0,VLOOKUP($Q27,DM_KM,5,0),"") -> #N/A | Q27: INTERNET | R27: =IF(S27<>0,VLOOKUP(S27,DM_DUAN,3,0),"") -> #N/A | S27: =IF(U27<>0,VLOOKUP(U27,DM_DUAN,3,0),"") | V27: =IF(W27<>0,VLOOKUP(W27,DM_DUAN,3,0),"") | X27: =IF(Y27<>0,VLOOKUP(Y27,DM_DUAN,3,0),"") -> #N/A | Y27: BP.HC-NS | Z27: =IF(AA27<>0,VLOOKUP(AA27,DM_DUAN,3,0),"") -> #N/A | AA27: VY | AB27: =IF(AC27<>0,VLOOKUP(AC27,DM_DUAN,3,0),"") | AD27: =IF(AC27<>0,VLOOKUP(AC27,DM_NV,2,0),"") | AE27: VIENTHONG | AF27: =IF(AE27<>0,VLOOKUP(AE27,DM_NV,2,0),"") -> #N/A
B28: =IF(D28="","",VLOOKUP(D28,'THAM CHIẾU'!$A:$B,2,0)) -> #N/A | C28: =if(D28<>0,TEXT(D28,"mm/yyyy"),"") -> 01/2022 | D28: 44563 | E28: Thanh toán cước Internet - line 2: t008_gftth_thuntm408 | G28: Thanh toán tiền mua DV ngoài cho công tác Quản lý | H28: =IF(G28="","",VLOOKUP($G28,'Quy chuẩn hạch toán'!$B:$E,2,0)) -> 642 | I28: =IF(H28="","",VLOOKUP($G28,'Quy chuẩn hạch toán'!$B:$E,3,0)) -> 1111 | J28: 125714 | O28: =IF($Q28<>0,VLOOKUP($Q28,DM_KM,3,0),"") -> #N/A | P28: =IF($Q28<>0,VLOOKUP($Q28,DM_KM,5,0),"") -> #N/A | Q28: INTERNET | R28: =IF(S28<>0,VLOOKUP(S28,DM_DUAN,3,0),"") -> #N/A | S28: =IF(U28<>0,VLOOKUP(U28,DM_DUAN,3,0),"") | V28: =IF(W28<>0,VLOOKUP(W28,DM_DUAN,3,0),"") | X28: =IF(Y28<>0,VLOOKUP(Y28,DM_DUAN,3,0),"") -> #N/A | Y28: BP.HC-NS | Z28: =IF(AA28<>0,VLOOKUP(AA28,DM_DUAN,3,0),"") -> #N/A | AA28: QUAN | AB28: =IF(AC28<>0,VLOOKUP(AC28,DM_DUAN,3,0),"") | AD28: =IF(AC28<>0,VLOOKUP(AC28,DM_NV,2,0),"") | AE28: VIENTHONG | AF28: =IF(AE28<>0,VLOOKUP(AE28,DM_NV,2,0),"") -> #N/A | AG28: Cô Tuyết
B29: =IF(D29="","",VLOOKUP(D29,'THAM CHIẾU'!$A:$B,2,0)) -> #N/A | C29: =if(D29<>0,TEXT(D29,"mm/yyyy"),"") -> 01/2022 | D29: 44563 | E29: Xe Nam chở khách đội Quân: 482-Q1-Phước Đông-Lê Minh Xuân BC <=> | G29: Chi phí bán hàng chưa thanh toán | H29: =IF(G29="","",VLOOKUP($G29,'Quy chuẩn hạch toán'!$B:$E,2,0)) -> 641 | I29: =IF(H29="","",VLOOKUP($G29,'Quy chuẩn hạch toán'!$B:$E,3,0)) -> 331 | J29: 1540000 | O29: =IF($Q29<>0,VLOOKUP($Q29,DM_KM,3,0),"") -> #N/A | P29: =IF($Q29<>0,VLOOKUP($Q29,DM_KM,5,0),"") -> #N/A | Q29: THUEXE | R29: =IF(S29<>0,VLOOKUP(S29,DM_DUAN,3,0),"") -> #N/A | S29: =IF(U29<>0,VLOOKUP(U29,DM_DUAN,3,0),"") -> NAMSAIGON | U29: PHUOCDONG | V29: =IF(W29<>0,VLOOKUP(W29,DM_DUAN,3,0),"") | X29: =IF(Y29<>0,VLOOKUP(Y29,DM_DUAN,3,0),"") -> #N/A | Y29: BP.KD | Z29: =IF(AA29<>0,VLOOKUP(AA29,DM_DUAN,3,0),"") -> #N/A | AA29: QUAN | AB29: =IF(AC29<>0,VLOOKUP(AC29,DM_DUAN,3,0),"") -> #N/A | AC29: L0006 | AD29: =IF(AC29<>0,VLOOKUP(AC29,DM_NV,2,0),"") -> Lê Hoàng Quân | AF29: =IF(AE29<>0,VLOOKUP(AE29,DM_NV,2,0),"")
B30: =IF(D30="","",VLOOKUP(D30,'THAM CHIẾU'!$A:$B,2,0)) -> #N/A | C30: =if(D30<>0,TEXT(D30,"mm/yyyy"),"") -> 01/2022 | D30: 44563 | E30: Xe ngoài chở khách đội Thu đi 482-Phước Đông <=> | G30: Chi phí bán hàng chưa thanh toán | H30: =IF(G30="","",VLOOKUP($G30,'Quy chuẩn hạch toán'!$B:$E,2,0)) -> 641 | I30: =IF(H30="","",VLOOKUP($G30,'Quy chuẩn hạch toán'!$B:$E,3,0)) -> 331 | J30: 1380000 | O30: =IF($Q30<>0,VLOOKUP($Q30,DM_KM,3,0),"") -> #N/A | P30: =IF($Q30<>0,VLOOKUP($Q30,DM_KM,5,0),"") -> #N/A | Q30: THUEXE | R30: =IF(S30<>0,VLOOKUP(S30,DM_DUAN,3,0),"") -> #N/A | S30: =IF(U30<>0,VLOOKUP(U30,DM_DUAN,3,0),"") -> NAMSAIGON | U30: PHUOCDONG | V30: =IF(W30<>0,VLOOKUP(W30,DM_DUAN,3,0),"") | X30: =IF(Y30<>0,VLOOKUP(Y30,DM_DUAN,3,0),"") -> #N/A | Y30: BP.KD | Z30: =IF(AA30<>0,VLOOKUP(AA30,DM_DUAN,3,0),"") -> #N/A | AA30: THU | AB30: =IF(AC30<>0,VLOOKUP(AC30,DM_DUAN,3,0),"") -> #N/A | AC30: L0002 | AD30: =IF(AC30<>0,VLOOKUP(AC30,DM_NV,2,0),"") -> Nguyễn Thị Mai Thu | AF30: =IF(AE30<>0,VLOOKUP(AE30,DM_NV,2,0),"")
B31: =IF(D31="","",VLOOKUP(D31,'THAM CHIẾU'!$A:$B,2,0)) -> #N/A | C31: =if(D31<>0,TEXT(D31,"mm/yyyy"),"") -> 01/2022 | D31: 44564 | E31: Mua hoa + trái cây ông Địa M1/12 | G31: Thanh toán tiền mua DV ngoài cho công tác Quản lý | H31: =IF(G31="","",VLOOKUP($G31,'Quy chuẩn hạch toán'!$B:$E,2,0)) -> 642 | I31: =IF(H31="","",VLOOKUP($G31,'Quy chuẩn hạch toán'!$B:$E,3,0)) -> 1111 | J31: 57143 | O31: =IF($Q31<>0,VLOOKUP($Q31,DM_KM,3,0),"") -> #N/A | P31: =IF($Q31<>0,VLOOKUP($Q31,DM_KM,5,0),"") -> #N/A | Q31: THOCUNG | R31: =IF(S31<>0,VLOOKUP(S31,DM_DUAN,3,0),"") -> #N/A | S31: =IF(U31<>0,VLOOKUP(U31,DM_DUAN,3,0),"") | V31: =IF(W31<>0,VLOOKUP(W31,DM_DUAN,3,0),"") | X31: =IF(Y31<>0,VLOOKUP(Y31,DM_DUAN,3,0),"") -> #N/A | Y31: BP.HC-NS | Z31: =IF(AA31<>0,VLOOKUP(AA31,DM_DUAN,3,0),"") -> #N/A | AA31: THU | AB31: =IF(AC31<>0,VLOOKUP(AC31,DM_DUAN,3,0),"") | AD31: =IF(AC31<>0,VLOOKUP(AC31,DM_NV,2,0),"") | AE31: MUANGOAI | AF31: =IF(AE31<>0,VLOOKUP(AE31,DM_NV,2,0),"") -> #N/A
B32: =IF(D32="","",VLOOKUP(D32,'THAM CHIẾU'!$A:$B,2,0)) -> #N/A | C32: =if(D32<>0,TEXT(D32,"mm/yyyy"),"") -> 01/2022 | D32: 44564 | E32: Mua hoa + trái cây ông Địa M1/12 | G32: Thanh toán tiền mua DV ngoài cho công tác Quản lý | H32: =IF(G32="","",VLOOKUP($G32,'Quy chuẩn hạch toán'!$B:$E,2,0)) -> 642 | I32: =IF(H32="","",VLOOKUP($G32,'Quy chuẩn hạch toán'!$B:$E,3,0)) -> 1111 | J32: 38095 | O32: =IF($Q32<>0,VLOOKUP($Q32,DM_KM,3,0),"") -> #N/A | P32: =IF($Q32<>0,VLOOKUP($Q32,DM_KM,5,0),"") -> #N/A | Q32: THOCUNG | R32: =IF(S32<>0,VLOOKUP(S32,DM_DUAN,3,0),"") -> #N/A | S32: =IF(U32<>0,VLOOKUP(U32,DM_DUAN,3,0),"") | V32: =IF(W32<>0,VLOOKUP(W32,DM_DUAN,3,0),"") | X32: =IF(Y32<>0,VLOOKUP(Y32,DM_DUAN,3,0),"") -> #N/A | Y32: BP.HC-NS | Z32: =IF(AA32<>0,VLOOKUP(AA32,DM_DUAN,3,0),"") -> #N/A | AA32: NAM | AB32: =IF(AC32<>0,VLOOKUP(AC32,DM_DUAN,3,0),"") | AD32: =IF(AC32<>0,VLOOKUP(AC32,DM_NV,2,0),"") | AE32: MUANGOAI | AF32: =IF(AE32<>0,VLOOKUP(AE32,DM_NV,2,0),"") -> #N/A
B33: =IF(D33="","",VLOOKUP(D33,'THAM CHIẾU'!$A:$B,2,0)) -> #N/A | C33: =if(D33<>0,TEXT(D33,"mm/yyyy"),"") -> 01/2022 | D33: 44564 | E33: Mua hoa + trái cây ông Địa M1/12 | G33: Thanh toán tiền mua DV ngoài cho công tác Quản lý | H33: =IF(G33="","",VLOOKUP($G33,'Quy chuẩn hạch toán'!$B:$E,2,0)) -> 642 | I33: =IF(H33="","",VLOOKUP($G33,'Quy chuẩn hạch toán'!$B:$E,3,0)) -> 1111 | J33: 76190 | O33: =IF($Q33<>0,VLOOKUP($Q33,DM_KM,3,0),"") -> #N/A | P33: =IF($Q33<>0,VLOOKUP($Q33,DM_KM,5,0),"") -> #N/A | Q33: THOCUNG | R33: =IF(S33<>0,VLOOKUP(S33,DM_DUAN,3,0),"") -> #N/A | S33: =IF(U33<>0,VLOOKUP(U33,DM_DUAN,3,0),"") | V33: =IF(W33<>0,VLOOKUP(W33,DM_DUAN,3,0),"") | X33: =IF(Y33<>0,VLOOKUP(Y33,DM_DUAN,3,0),"") -> #N/A | Y33: BP.HC-NS | Z33: =IF(AA33<>0,VLOOKUP(AA33,DM_DUAN,3,0),"") -> #N/A | AA33: VY | AB33: =IF(AC33<>0,VLOOKUP(AC33,DM_DUAN,3,0),"") | AD33: =IF(AC33<>0,VLOOKUP(AC33,DM_NV,2,0),"") | AE33: MUANGOAI | AF33: =IF(AE33<>0,VLOOKUP(AE33,DM_NV,2,0),"") -> #N/A
B34: =IF(D34="","",VLOOKUP(D34,'THAM CHIẾU'!$A:$B,2,0)) -> #N/A | C34: =if(D34<>0,TEXT(D34,"mm/yyyy"),"") -> 01/2022 | D34: 44564 | E34: Mua hoa + trái cây ông Địa M1/12 | G34: Thanh toán tiền mua DV ngoài cho công tác Quản lý | H34: =IF(G34="","",VLOOKUP($G34,'Quy chuẩn hạch toán'!$B:$E,2,0)) -> 642 | I34: =IF(H34="","",VLOOKUP($G34,'Quy chuẩn hạch toán'!$B:$E,3,0)) -> 1111 | J34: 28571 | O34: =IF($Q34<>0,VLOOKUP($Q34,DM_KM,3,0),"") -> #N/A | P34: =IF($Q34<>0,VLOOKUP($Q34,DM_KM,5,0),"") -> #N/A | Q34: THOCUNG | R34: =IF(S34<>0,VLOOKUP(S34,DM_DUAN,3,0),"") -> #N/A | S34: =IF(U34<>0,VLOOKUP(U34,DM_DUAN,3,0),"") | V34: =IF(W34<>0,VLOOKUP(W34,DM_DUAN,3,0),"") | X34: =IF(Y34<>0,VLOOKUP(Y34,DM_DUAN,3,0),"") -> #N/A | Y34: BP.HC-NS | Z34: =IF(AA34<>0,VLOOKUP(AA34,DM_DUAN,3,0),"") -> #N/A | AA34: QUAN | AB34: =IF(AC34<>0,VLOOKUP(AC34,DM_DUAN,3,0),"") | AD34: =IF(AC34<>0,VLOOKUP(AC34,DM_NV,2,0),"") | AE34: MUANGOAI | AF34: =IF(AE34<>0,VLOOKUP(AE34,DM_NV,2,0),"") -> #N/A
B35: =IF(D35="","",VLOOKUP(D35,'THAM CHIẾU'!$A:$B,2,0)) -> #N/A | C35: =if(D35<>0,TEXT(D35,"mm/yyyy"),"") -> 01/2022 | D35: 44565 | E35: Chi mua găng tay y tế + nước lau nhà | G35: Thanh toán tiền mua DV ngoài cho công tác Quản lý | H35: =IF(G35="","",VLOOKUP($G35,'Quy chuẩn hạch toán'!$B:$E,2,0)) -> 642 | I35: =IF(H35="","",VLOOKUP($G35,'Quy chuẩn hạch toán'!$B:$E,3,0)) -> 1111 | J35: 75714 | O35: =IF($Q35<>0,VLOOKUP($Q35,DM_KM,3,0),"") -> #N/A | P35: =IF($Q35<>0,VLOOKUP($Q35,DM_KM,5,0),"") -> #N/A | Q35: VESINH | R35: =IF(S35<>0,VLOOKUP(S35,DM_DUAN,3,0),"") -> #N/A | S35: =IF(U35<>0,VLOOKUP(U35,DM_DUAN,3,0),"") | V35: =IF(W35<>0,VLOOKUP(W35,DM_DUAN,3,0),"") | X35: =IF(Y35<>0,VLOOKUP(Y35,DM_DUAN,3,0),"") -> #N/A | Y35: BP.HC-NS | Z35: =IF(AA35<>0,VLOOKUP(AA35,DM_DUAN,3,0),"") -> #N/A | AA35: THU | AB35: =IF(AC35<>0,VLOOKUP(AC35,DM_DUAN,3,0),"") | AD35: =IF(AC35<>0,VLOOKUP(AC35,DM_NV,2,0),"") | AE35: VS-ANNINH | AF35: =IF(AE35<>0,VLOOKUP(AE35,DM_NV,2,0),"") -> #N/A
B36: =IF(D36="","",VLOOKUP(D36,'THAM CHIẾU'!$A:$B,2,0)) -> #N/A | C36: =if(D36<>0,TEXT(D36,"mm/yyyy"),"") -> 01/2022 | D36: 44565 | E36: Chi mua găng tay y tế + nước lau nhà | G36: Thanh toán tiền mua DV ngoài cho công tác Quản lý | H36: =IF(G36="","",VLOOKUP($G36,'Quy chuẩn hạch toán'!$B:$E,2,0)) -> 642 | I36: =IF(H36="","",VLOOKUP($G36,'Quy chuẩn hạch toán'!$B:$E,3,0)) -> 1111 | J36: 50476 | O36: =IF($Q36<>0,VLOOKUP($Q36,DM_KM,3,0),"") -> #N/A | P36: =IF($Q36<>0,VLOOKUP($Q36,DM_KM,5,0),"") -> #N/A | Q36: VESINH | R36: =IF(S36<>0,VLOOKUP(S36,DM_DUAN,3,0),"") -> #N/A | S36: =IF(U36<>0,VLOOKUP(U36,DM_DUAN,3,0),"") | V36: =IF(W36<>0,VLOOKUP(W36,DM_DUAN,3,0),"") | X36: =IF(Y36<>0,VLOOKUP(Y36,DM_DUAN,3,0),"") -> #N/A | Y36: BP.HC-NS | Z36: =IF(AA36<>0,VLOOKUP(AA36,DM_DUAN,3,0),"") -> #N/A | AA36: NAM | AB36: =IF(AC36<>0,VLOOKUP(AC36,DM_DUAN,3,0),"") | AD36: =IF(AC36<>0,VLOOKUP(AC36,DM_NV,2,0),"") | AE36: VS-ANNINH | AF36: =IF(AE36<>0,VLOOKUP(AE36,DM_NV,2,0),"") -> #N/A
B37: =IF(D37="","",VLOOKUP(D37,'THAM CHIẾU'!$A:$B,2,0)) -> #N/A | C37: =if(D37<>0,TEXT(D37,"mm/yyyy"),"") -> 01/2022 | D37: 44565 | E37: Chi mua găng tay y tế + nước lau nhà | G37: Thanh toán tiền mua DV ngoài cho công tác Quản lý | H37: =IF(G37="","",VLOOKUP($G37,'Quy chuẩn hạch toán'!$B:$E,2,0)) -> 642 | I37: =IF(H37="","",VLOOKUP($G37,'Quy chuẩn hạch toán'!$B:$E,3,0)) -> 1111 | J37: 100952 | O37: =IF($Q37<>0,VLOOKUP($Q37,DM_KM,3,0),"") -> #N/A | P37: =IF($Q37<>0,VLOOKUP($Q37,DM_KM,5,0),"") -> #N/A | Q37: VESINH | R37: =IF(S37<>0,VLOOKUP(S37,DM_DUAN,3,0),"") -> #N/A | S37: =IF(U37<>0,VLOOKUP(U37,DM_DUAN,3,0),"") | V37: =IF(W37<>0,VLOOKUP(W37,DM_DUAN,3,0),"") | X37: =IF(Y37<>0,VLOOKUP(Y37,DM_DUAN,3,0),"") -> #N/A | Y37: BP.HC-NS | Z37: =IF(AA37<>0,VLOOKUP(AA37,DM_DUAN,3,0),"") -> #N/A | AA37: VY | AB37: =IF(AC37<>0,VLOOKUP(AC37,DM_DUAN,3,0),"") | AD37: =IF(AC37<>0,VLOOKUP(AC37,DM_NV,2,0),"") | AE37: VS-ANNINH | AF37: =IF(AE37<>0,VLOOKUP(AE37,DM_NV,2,0),"") -> #N/A
B38: =IF(D38="","",VLOOKUP(D38,'THAM CHIẾU'!$A:$B,2,0)) -> #N/A | C38: =if(D38<>0,TEXT(D38,"mm/yyyy"),"") -> 01/2022 | D38: 44565 | E38: Chi mua găng tay y tế + nước lau nhà | G38: Thanh toán tiền mua DV ngoài cho công tác Quản lý | H38: =IF(G38="","",VLOOKUP($G38,'Quy chuẩn hạch toán'!$B:$E,2,0)) -> 642 | I38: =IF(H38="","",VLOOKUP($G38,'Quy chuẩn hạch toán'!$B:$E,3,0)) -> 1111 | J38: 37857 | O38: =IF($Q38<>0,VLOOKUP($Q38,DM_KM,3,0),"") -> #N/A | P38: =IF($Q38<>0,VLOOKUP($Q38,DM_KM,5,0),"") -> #N/A | Q38: VESINH | R38: =IF(S38<>0,VLOOKUP(S38,DM_DUAN,3,0),"") -> #N/A | S38: =IF(U38<>0,VLOOKUP(U38,DM_DUAN,3,0),"") | V38: =IF(W38<>0,VLOOKUP(W38,DM_DUAN,3,0),"") | X38: =IF(Y38<>0,VLOOKUP(Y38,DM_DUAN,3,0),"") -> #N/A | Y38: BP.HC-NS | Z38: =IF(AA38<>0,VLOOKUP(AA38,DM_DUAN,3,0),"") -> #N/A | AA38: QUAN | AB38: =IF(AC38<>0,VLOOKUP(AC38,DM_DUAN,3,0),"") | AD38: =IF(AC38<>0,VLOOKUP(AC38,DM_NV,2,0),"") | AE38: VS-ANNINH | AF38: =IF(AE38<>0,VLOOKUP(AE38,DM_NV,2,0),"") -> #N/A
B39: =IF(D39="","",VLOOKUP(D39,'THAM CHIẾU'!$A:$B,2,0)) -> #N/A | C39: =if(D39<>0,TEXT(D39,"mm/yyyy"),"") -> 01/2022 | D39: 44565 | E39: Chi tiền mua nước suối xe | G39: Thanh toán tiền mua DV ngoài cho công tác Bán hàng | H39: =IF(G39="","",VLOOKUP($G39,'Quy chuẩn hạch toán'!$B:$E,2,0)) -> 154 | I39: =IF(H39="","",VLOOKUP($G39,'Quy chuẩn hạch toán'!$B:$E,3,0)) -> 1111 | J39: 87698 | O39: =IF($Q39<>0,VLOOKUP($Q39,DM_KM,3,0),"") -> #N/A | P39: =IF($Q39<>0,VLOOKUP($Q39,DM_KM,5,0),"") -> #N/A | Q39: NUOC.UONG | R39: =IF(S39<>0,VLOOKUP(S39,DM_DUAN,3,0),"") -> #N/A | S39: =IF(U39<>0,VLOOKUP(U39,DM_DUAN,3,0),"") | V39: =IF(W39<>0,VLOOKUP(W39,DM_DUAN,3,0),"") | X39: =IF(Y39<>0,VLOOKUP(Y39,DM_DUAN,3,0),"") -> #N/A | Y39: BP.KD | Z39: =IF(AA39<>0,VLOOKUP(AA39,DM_DUAN,3,0),"") -> #N/A | AA39: THU | AB39: =IF(AC39<>0,VLOOKUP(AC39,DM_DUAN,3,0),"") | AD39: =IF(AC39<>0,VLOOKUP(AC39,DM_NV,2,0),"") | AE39: DIENNUOC | AF39: =IF(AE39<>0,VLOOKUP(AE39,DM_NV,2,0),"") -> #N/A
B40: =IF(D40="","",VLOOKUP(D40,'THAM CHIẾU'!$A:$B,2,0)) -> #N/A | C40: =if(D40<>0,TEXT(D40,"mm/yyyy"),"") -> 01/2022 | D40: 44565 | E40: Chi tiền mua nước suối xe | G40: Thanh toán tiền mua DV ngoài cho công tác Bán hàng | H40: =IF(G40="","",VLOOKUP($G40,'Quy chuẩn hạch toán'!$B:$E,2,0)) -> 154 | I40: =IF(H40="","",VLOOKUP($G40,'Quy chuẩn hạch toán'!$B:$E,3,0)) -> 1111 | J40: 58466 | O40: =IF($Q40<>0,VLOOKUP($Q40,DM_KM,3,0),"") -> #N/A | P40: =IF($Q40<>0,VLOOKUP($Q40,DM_KM,5,0),"") -> #N/A | Q40: NUOC.UONG | R40: =IF(S40<>0,VLOOKUP(S40,DM_DUAN,3,0),"") -> #N/A | S40: =IF(U40<>0,VLOOKUP(U40,DM_DUAN,3,0),"") | V40: =IF(W40<>0,VLOOKUP(W40,DM_DUAN,3,0),"") | X40: =IF(Y40<>0,VLOOKUP(Y40,DM_DUAN,3,0),"") -> #N/A | Y40: BP.KD | Z40: =IF(AA40<>0,VLOOKUP(AA40,DM_DUAN,3,0),"") -> #N/A | AA40: NAM | AB40: =IF(AC40<>0,VLOOKUP(AC40,DM_DUAN,3,0),"") | AD40: =IF(AC40<>0,VLOOKUP(AC40,DM_NV,2,0),"") | AE40: DIENNUOC | AF40: =IF(AE40<>0,VLOOKUP(AE40,DM_NV,2,0),"") -> #N/A
...

Sheet Hệ thống tài khoản TT133
A1: SỐ HIỆU TK TT | C1: TÊN TÀI KHOẢN | D1: Tính chất | E1: Trạng thái | F1: Chức năng | G1: Theo dõi chi tiết theo
A2: Cấp 1 | B2: Cấp 2 | G2: Đối tượng | H2: Hợp đồng mua | I2: Hợp đồng bán | J2: Đơn hàng | K2: Tài khoản ngân hàng | L2: Khoản mục CP | M2: Dự án | N2: Sản phẩm | O2: Dòng tiền
C3: LOẠI TÀI KHOẢN TÀI SẢN
A4: 111 | C4: Tiền mặt | D4: Dư Nợ | E4: Sử dụng
B5: 1111 | C5: Tiền Việt Nam | D5: Dư Nợ | E5: Sử dụng
B6: 1112 | C6: Ngoại tệ | D6: Dư Nợ | E6: Sử dụng
A7: 112 | C7: Tiền gửi không kỳ hạn | D7: Dư Nợ | E7: Sử dụng | K7: Bắt buộc
B8: 1121 | C8: Tiền Việt Nam | D8: Dư Nợ | E8: Sử dụng
C9: Tài khoản Vpank 1224343
C10: Tài khaorn VCB 121323
B12: 1122 | C12: Ngoại tệ | D12: Dư Nợ | E12: Sử dụng
A13: 121 | C13: Chứng khoán kinh doanh | D13: Dư Nợ
A14: 128 | C14: Đầu tư nắm giữ đến ngày đáo hạn | D14: Dư Nợ
B15: 1281 | C15: Tiền gửi có kỳ hạn | D15: Dư Nợ
B16: 1288 | C16: Các khoản đầu tư khác nắm giữ đến ngày đáo hạn | D16: Dư Nợ
A17: 131 | C17: Phải thu của khách hàng | D17: Lưỡng tính | E17: Sử dụng | G17: Khách hàng
A18: 133 | C18: Thuế GTGT được khấu trừ | D18: Dư Nợ | E18: Sử dụng
B19: 1331 | C19: Thuế GTGT được khấu trừ của hàng hóa, dịch vụ | D19: Dư Nợ
B20: 1332 | C20: Thuế GTGT được khấu trừ của TSCĐ | D20: Dư Nợ
A21: 136 | C21: Phải thu nội bộ | D21: Dư Nợ
B22: 1361 | C22: Vốn kinh doanh ở đơn vị trực thuộc | D22: Dư Nợ
B23: 1368 | C23: Phải thu nội bộ khác | D23: Dư Nợ
A24: 138 | C24: Phải thu khác | D24: Dư Nợ | E24: Sử dụng
B25: 1381 | C25: Tài sản thiếu chờ xử lý | D25: Dư Nợ | E25: Sử dụng
B26: 1386 | C26: Cầm cố, thế chấp, ký quỹ, ký cược | D26: Dư Nợ
B27: 1388 | C27: Phải thu khác | D27: Dư Nợ | E27: Sử dụng
A28: 141 | C28: Tạm ứng | D28: Dư Nợ | E28: Sử dụng | G28: Nhân viên | K28: Bắt buộc
A29: 151 | C29: Hàng mua đang đi đường | D29: Dư Nợ
A30: 152 | C30: Nguyên liệu, vật liệu | D30: Dư Nợ
A31: 153 | C31: Công cụ, dụng cụ | D31: Dư Nợ
A32: 154 | C32: Chi phí sản xuất, kinh doanh dở dang | D32: Dư Nợ | E32: Sử dụng | L32: Bắt buộc
A33: 155 | C33: Sản phẩm | D33: Dư Nợ
A34: 156 | C34: Hàng hóa | D34: Dư Nợ
A35: 157 | C35: Hàng gửi đi bán | D35: Dư Nợ
A36: 211 | C36: Tài sản cố định hữu hình | D36: Dư Nợ
B37: 2111 | C37: TSCĐ hữu hình
B38: 2112 | C38: TSCĐ thuê tài chính
B39: 2113 | C39: TSCĐ vô hình
A40: 214 | C40: Hao mòn tài sản cố định | D40: Dư Có
B41: 2141 | C41: Hao mòn TSCĐ hữu hình | D41: Dư Có
...

Sheet DM chứng từ
B1: PHỤ LỤC I
B2: DANH MỤC VÀ BIỂU MẪU CHỨNG TỪ KẾ TOÁN
B3: (Kèm theo Thông tư số 99/2025/TT-BTC ngày 27 tháng 10 năm 2025 của Bộ trưởng Bộ Tài chính)
A4: TT | B4: TÊN CHỨNG TỪ | C4: SỐ HIỆU
B5: I. Lao động tiền lương
A6: 1 | B6: Bảng thanh toán tiền lương | C6: 01 - LĐTL
A7: 2 | B7: Bảng thanh toán tiền thưởng | C7: 02 - LĐTL
A8: 3 | B8: Bảng thanh toán tiền làm thêm giờ | C8: 03 - LĐTL
A9: 4 | B9: Bảng thanh toán tiền thuê ngoài | C9: 04 - LĐTL
A10: 5 | B10: Hợp đồng giao khoán | C10: 05 - LĐTL
A11: 6 | B11: Biên bản thanh lý (nghiệm thu) hợp đồng giao khoán | C11: 06 - LĐTL
A12: 7 | B12: Bảng kê trích nộp các khoản theo lương | C12: 07 - LĐTL
A13: 8 | B13: Bảng phân bổ tiền lương và các khoản trích theo lương | C13: 08 - LĐTL
B14: II. Hàng tồn kho
A15: 1 | B15: Phiếu nhập kho | C15: 01 - VT
A16: 2 | B16: Phiếu xuất kho | C16: 02 - VT
A17: 3 | B17: Biên bản kiểm nghiệm vật tư, công cụ, sản phẩm, hàng hóa | C17: 03 - VT
A18: 4 | B18: Bảng kê chi tiết vật tư còn lại cuối kỳ | C18: 04 - VT
A19: 5 | B19: Biên bản tổng hợp kiểm kê vật tư, công cụ, sản phẩm, hàng hóa | C19: 05 - VT
A20: 6 | B20: Bảng kê mua hàng | C20: 06 - VT
A21: 7 | B21: Bảng phân bổ nguyên liệu, vật liệu, công cụ, dụng cụ | C21: 07 - VT
B22: III. Bán hàng
A23: 1 | B23: Bảng thanh toán hàng đại lý, ký gửi | C23: 01 - BH
A24: 2 | B24: Thẻ quầy hàng | C24: 02 - BH
B25: IV. Tiền tệ
A26: 1 | B26: Phiếu thu | C26: 01 - TT
A27: 2 | B27: Phiếu chi | C27: 02 - TT
A28: 3 | B28: Giấy đề nghị tạm ứng | C28: 03 - TT
A29: 4 | B29: Giấy thanh toán tiền tạm ứng | C29: 04 - TT
A30: 5 | B30: Giấy đề nghị thanh toán | C30: 05 - TT
A31: 6 | B31: Biên lai thu tiền | C31: 06 - TT
A32: 7 | B32: Bảng kê vàng tiền tệ | C32: 07 - TT
A33: 8 | B33: Bảng kiểm kê quỹ (dùng cho VND) | C33: 08a - TT
A34: 9 | B34: Bảng kiểm kê quỹ (dùng cho ngoại tệ, vàng tiền tệ) | C34: 08b - TT
A35: 10 | B35: Bảng kê chi tiền | C35: 09 - TT
B36: V. Tài sản cố định
A37: 1 | B37: Biên bản giao nhận TSCĐ | C37: 01 - TSCĐ
A38: 2 | B38: Biên bản thanh lý TSCĐ | C38: 02 - TSCĐ
A39: 3 | B39: Biên bản bàn giao TSCĐ sửa chữa, bảo dưỡng hoặc nâng cấp, cải tạo hoàn thành | C39: 03 - TSCĐ
A40: 4 | B40: Biên bản đánh giá lại TSCĐ | C40: 04 - TSCĐ
...

Sheet DM sổ
B1: PHỤ LỤC III
B2: SỔ KẾ TOÁN
B3: (Kèm theo Thông tư số 99/2025/TT-BTC ngày 27 tháng 10 năm 2025 của Bộ trưởng Bộ Tài chính)
B4: PHẦN A - DANH MỤC BIỂU MẪU SỔ KẾ TOÁN
A5: Số TT | B5: Tên sổ | C5: Ký hiệu | D5: Hình thức kế toán
D6: Nhật ký chung
A7: 1 | B7: 2 | C7: 3 | D7: 4
A8: 5 | B8: Sổ Nhật ký chung | C8: S03a-DN | D8: x
A9: 6 | B9: Sổ Nhật ký thu tiền | C9: S03a1-DN | D9: x
A10: 7 | B10: Sổ Nhật ký chi tiền | C10: S03a2-DN | D10: x
A11: 8 | B11: Sổ Nhật ký mua hàng | C11: S03a3-DN | D11: x
A12: 9 | B12: Sổ Nhật ký bán hàng | C12: S03a4-DN | D12: x
A13: 10 | B13: Sổ Cái (dùng cho hình thức Nhật ký chung) | C13: S03b-DN | D13: x
A14: 13 | B14: Bảng cân đối số phát sinh | C14: S06-DN | D14: x
A15: 14 | B15: Sổ quỹ tiền mặt | C15: S07-DN | D15: x
A16: 15 | B16: Sổ kế toán chi tiết quỹ tiền mặt | C16: S07a-DN | D16: x
A17: 16 | B17: Sổ tiền gửi không kỳ hạn | C17: S08-DN | D17: x
A18: 17 | B18: Sổ chi tiết vật liệu, dụng cụ (sản phẩm, hàng hóa) | C18: S10-DN | D18: x
A19: 18 | B19: Bảng tổng hợp chi tiết vật liệu, dụng cụ, sản phẩm, hàng hóa | C19: S11-DN | D19: x
... A43: 42 | B43: Sổ chi tiết thuế GTGT được miễn giảm | C43: S63-DN | D43: x
B44: Các sổ chi tiết khác theo yêu cầu quản lý của doanh nghiệp

Sheet Hệ thống tài khoản TT99
A1: SỐ HIỆU TK TT | C1: TÊN TÀI KHOẢN | D1: Tính chất | E1: Trạng thái | F1: Chức năng | G1: Theo dõi chi tiết theo
A2: Cấp 1 | B2: Cấp 2 | G2: Đối tượng | H2: Hợp đồng mua | I2: Hợp đồng bán | J2: Đơn hàng | K2: Tài khoản ngân hàng | L2: Khoản mục CP | M2: Dự án | N2: Sản phẩm | O2: Dòng tiền
C3: LOẠI TÀI KHOẢN TÀI SẢN
A4: 111 | C4: Tiền mặt | D4: Dư Nợ | E4: Sử dụng
A5: 112 | C5: Tiền gửi không kỳ hạn | D5: Dư Nợ | E5: Sử dụng | K5: Bắt buộc
A6: 113 | C6: Tiền đang chuyển | D6: Dư Nợ
A7: 121 | C7: Chứng khoán kinh doanh | D7: Dư Nợ
A8: 128 | C8: Đầu tư nắm giữ đến ngày đáo hạn | D8: Dư Nợ
B9: 1281 | C9: Tiền gửi có kỳ hạn | D9: Dư Nợ
B10: 1282 | C10: Trái phiếu | D10: Dư Nợ
B11: 1283 | C11: Cho vay | D11: Dư Nợ
B12: 1288 | C12: Các khoản đầu tư khác nắm giữ đến ngày đáo hạn | D12: Dư Nợ
A13: 131 | C13: Phải thu của khách hàng | D13: Lưỡng tính | E13: Sử dụng | G13: Khách hàng
A14: 133 | C14: Thuế GTGT được khấu trừ | D14: Dư Nợ | E14: Sử dụng
B15: 1331 | C15: Thuế GTGT được khấu trừ của hàng hóa, dịch vụ | D15: Dư Nợ
B16: 1332 | C16: Thuế GTGT được khấu trừ của TSCĐ | D16: Dư Nợ
A17: 136 | C17: Phải thu nội bộ | D17: Dư Nợ
B18: 1361 | C18: Vốn kinh doanh ở đơn vị trực thuộc | D18: Dư Nợ
B19: 1362 | C19: Phải thu nội bộ về chênh lệch tỷ giá | D19: Dư Nợ
B20: 1363 | C20: Phải thu nội bộ về chi phí đi vay đủ điều kiện được vốn hoá | D20: Dư Nợ
B21: 1368 | C21: Phải thu nội bộ khác | D21: Dư Nợ
A22: 138 | C22: Phải thu khác | D22: Dư Nợ | E22: Sử dụng
B23: 1381 | C23: Tài sản thiếu chờ xử lý | D23: Dư Nợ | E23: Sử dụng
B24: 1383 | C24: Thuế TTĐB của hàng nhập khẩu | D24: Dư Nợ
B25: 1388 | C25: Phải thu khác | D25: Dư Nợ | E25: Sử dụng
A26: 141 | C26: Tạm ứng | D26: Dư Nợ | E26: Sử dụng | G26: Nhân viên
A27: 151 | C27: Hàng mua đang đi đường | D27: Dư Nợ
A28: 152 | C28: Nguyên liệu, vật liệu | D28: Dư Nợ
A29: 153 | C29: Công cụ, dụng cụ | D29: Dư Nợ
A30: 154 | C30: Chi phí sản xuất, kinh doanh dở dang | D30: Dư Nợ | E30: Sử dụng
A31: 155 | C31: Sản phẩm | D31: Dư Nợ
A32: 156 | C32: Hàng hóa | D32: Dư Nợ
A33: 157 | C33: Hàng gửi đi bán | D33: Dư Nợ
A34: 158 | C34: Nguyên liệu, vật tư tại kho bảo thuế | D34: Dư Nợ
A35: 171 | C35: Giao dịch mua, bán lại trái phiếu chính phủ | D35: Lưỡng tính
A36: 211 | C36: Tài sản cố định hữu hình | D36: Dư Nợ
A37: 212 | C37: Tài sản cố định thuê tài chính | D37: Dư Nợ
A38: 213 | C38: Tài sản cố định vô hình | D38: Dư Nợ
A39: 214 | C39: Hao mòn tài sản cố định | D39: Dư Có
B40: 2141 | C40: Hao mòn TSCĐ hữu hình | D40: Dư Có
...

Sheet Sổ chi tiết TK
A1: Đơn vị: ……………… Địa chỉ: ………..…….. | H1: Mẫu số S38-DN (Kèm theo Thông tư số 99/2025/TT-BTC ngày 27 tháng 10 năm 2025 của Bộ trưởng Bộ Tài chính)
E2: SỔ CHI TIẾT TÀI KHOẢN
E3: (1) Tài khoản: ………………………….
E4: (2) Đối tượng: …………………………
E5: Loại tiền: VNĐ
A6: Ngày, tháng ghi sổ | B6: Chứng từ | D6: Diễn giải | E6: (3) TK đối ứng | F6: (4) Số phát sinh | H6: (5) Số dư
B7: Số hiệu | C7: Ngày tháng | F7: Nợ | G7: Có | H7: Nợ | I7: Có
A8: A | B8: B | C8: C | D8: D | E8: E | F8: 1 | G8: 2 | H8: 3 | I8: 4
D9: - Số dư đầu kỳ | E9: x | F9: x | G9: x
D13: - Cộng số phát sinh | E13: x | H13: x | I13: x
D14: - Số dư cuối kỳ | E14: x | F14: x | G14: x
A15: - Sổ này có ... trang, đánh số từ trang 01 đến trang ...
A16: - Ngày mở sổ:...
B17: Người ghi sổ (Ký, họ tên) | E17: Kế toán trưởng (Ký, họ tên) | H17: Ngày..... tháng.... năm …. Người đại diện theo pháp luật (Ký, họ tên, đóng dấu)
A18: -1
A19: (1) Tài khoản: …………………………. | D19: Lọc theo danh mục tài khoản
A20: (2) Đối tượng: ………………………… | D20: Lọc theo danh mục đối tượng (Khách hàng, Nhà cung cấp, nhân viên)
A21: (3) TK đối ứng | D21: Tài khoản đối ứng với dòng có cùng tài khoản được lọc. VD: Nghiệp vụ ghi Nợ TK 133; Có TK 111. Khi lọc TK 111 thì TK đối ứng là TK 133: Dữ liệu lấy từ Kho dữ liệu tổng
A22: (4) Số phát sinh | D22: Nếu tài khoản lọc là bên Nợ thì số tiền phát sinh hiển thị bên Nợ, Nếu TK lọc là bên Có thì số tiền hiển thị bên Có
A23: (5) Số dư

Sheet Sổ chi tiết công nợ
A1: Đơn vị: ……………… Địa chỉ: ………..……..
E2: SỔ CHI TIẾT CÔNG NỢ
E3: (1) Tài khoản: ………………………….
E4: (2) Đối tượng: …………………………
E5: Loại tiền: VNĐ
A6: Ngày, tháng ghi sổ | B6: Chứng từ | D6: Diễn giải | E6: (3) TK đối ứng | F6: (4) Số phát sinh | H6: (5) Số dư
B7: Số hiệu | C7: Ngày tháng | F7: Phải thu | G7: Phải trả | H7: Phải thu | I7: Phải trả
A8: A | B8: B | C8: C | D8: D | E8: E | F8: 1 | G8: 2 | H8: 3 | I8: 4
D9: - Số dư đầu kỳ | E9: x | F9: x | G9: x
D14: - Cộng số phát sinh | E14: x | H14: x | I14: x
D15: - Số dư cuối kỳ | E15: x | F15: x | G15: x
A16: - Sổ này có ... trang, đánh số từ trang 01 đến trang ...
A17: - Ngày mở sổ:...
B18: Người ghi sổ (Ký, họ tên) | E18: Kế toán trưởng (Ký, họ tên) | H18: Ngày..... tháng.... năm …. Người đại diện theo pháp luật (Ký, họ tên, đóng dấu)
A19: -1
A20: (1) Tài khoản: …………………………. | D20: Lọc theo danh mục tài khoản (Có thể chọn 1 TK hoặc nhiều TK hoặc chọn tất cả)
A21: (2) Đối tượng: ………………………… | D21: Lọc theo danh mục đối tượng (Khách hàng, Nhà cung cấp, nhân viên) (Có thể chọn 1 đối tượng, hoặc chọn nhiều đối tượng hoặc chọn tất cả)
A22: (3) TK đối ứng | D22: Tài khoản đối ứng với dòng có cùng tài khoản được lọc. VD: Nghiệp vụ ghi Nợ TK 133; Có TK 111. Khi lọc TK 111 thì TK đối ứng là TK 133: Dữ liệu lấy từ Kho dữ liệu tổng
A23: (4) Số phát sinh | D23: Nếu tài khoản lọc là bên Nợ thì số tiền phát sinh hiển thị bên Nợ, Nếu TK lọc là bên Có thì số tiền hiển thị bên Có
A24: (5) Số dư
A25: Phải thu | B25: Tương ứng lấy dữ liệu bên TK Nợ
A26: Phải trả | B26: Tương ứng lấy dữ liệu bên TK Có

Sheet Tổng hợp công nợ
A1: =NAME -> #NAME?
G2: BẢNG TỔNG HỢP CÔNG NỢ
F3: (1) Tài khoản: ………………………….
D4: Cột này nhập trực tiếp số cuối kỳ trước chuyển sang | F4: (2) Đối tượng: ………………………… | H4: =CDPS!K4
A5: Mã | B5: MÃ ĐỐI TƯỢNG | C5: Tên đôi tượng | D5: Số dư năm trước chuyển sang | F5: Số dư đầu kỳ | H5: Số phát sinh | J5: Số dư cuối kỳ | L5: Mã
A6: TK | D6: Nợ | E6: Có | F6: Phải thu | G6: Phải trả | H6: Phải thu | I6: Phải trả | J6: Phải thu | K6: Phải trả | L6: Xử lý
F7: =SUMIF($L$8:$L$113,"SUM",F$8:F$113) -> 0 | G7: =SUMIF($L$8:$L$113,"SUM",G$8:G$113) -> 0 | H7: =SUMIF($L$8:$L$113,"SUM",H$8:H$113) -> 0 | I7: =SUMIF($L$8:$L$113,"SUM",I$8:I$113) -> 0 | J7: =SUMIF($L$8:$L$113,"SUM",J$8:J$113) -> 0 | K7: =SUMIF($L$8:$L$113,"SUM",K$8:K$113) -> 0 | L7: =IF(SUM(J7:K7)>0,"X","")
B8: 1311 | C8: CÔNG NỢ PHẢI THU CỦA KHÁCH HÀNG | F8: =SUMIF($A:$A,$B8,F:F) -> 0 | G8: =SUMIF($A:$A,$B8,G:G) -> 0 | H8: =SUMIF($A:$A,$B8,H:H) -> 0 | I8: =SUMIF($A:$A,$B8,I:I) -> 0 | J8: =SUMIF($A:$A,$B8,J:J) -> 0 | K8: =SUMIF($A:$A,$B8,K:K) -> 0 | L8: SUM
A9: 1311 | B9: DHT | F9: =if($D9+SUMIFS(AC_SOTIEN,AC_TKNO,$A9,AC_PHAITHU,$B9,AC_NGAY,"<"&$F$4)-($E9+SUMIFS(AC_SOTIEN,AC_TKCO,$A9,AC_PHAITRA,$B9,AC_NGAY,"<"&$F$4))>0,$D9+SUMIFS(AC_SOTIEN,AC_TKNO,$A9,AC_PHAITHU,$B9,AC_NGAY,"<"&$F$4)-($E9+SUMIFS(AC_SOTIEN,AC_TKCO,$A9,AC_PHAITRA,$B9,AC_NGAY,"<"&$F$4)),"") | G9: =IF($E9+SUMIFS(AC_SOTIEN,AC_TKCO,$A9,AC_PHAITRA,$B9, AC_NGAY,"<"&$F$4)-($D9+SUMIFS(AC_SOTIEN,AC_TKNO,$A9,AC_PHAITHU,$B9,AC_NGAY,"<"&$F$4))>0,$E9+SUMIFS(AC_SOTIEN,AC_TKCO,$A9,AC_PHAITRA,$B9,AC_NGAY,"<"&$F$4)-($D9+SUMIFS(AC_SOTIEN,AC_TKNO,$A9,AC_PHAITHU,$B9,AC_NGAY,"<"&$F$4)),"") | H9: =SUMIFS(AC_SOTIEN,AC_TKNO,$A9 ,AC_PHAITHU,$B9,AC_NGAY,">="&$F$4,AC_NGAY,"<="&$H$4) -> 0 | I9: =SUMIFS(AC_SOTIEN,AC_TKCO,$A9,AC_PHAITRA, $B9,AC_NGAY,">="&$F$4,AC_NGAY,"<="&$H$4) -> 0 | J9: =IF(F9+H9-G9-I9>=0,F9+H9-G9-I9,0) -> 0 | K9: =IF(G9+I9-H9-F9>=0,G9+I9-H9-F9,0) -> 0 | L9: =IF(SUM(J9:K9)>0,"X","")
A10: 1311 | F10: =if($D10+SUMIFS(AC_SOTIEN,AC_TKNO,$A10,AC_PHAITHU,$B10,AC_NGAY,"<"&$F$4)-($E10+SUMIFS(AC_SOTIEN,AC_TKCO,$A10,AC_PHAITRA,$B10,AC_NGAY,"<"&$F$4))>0,$D10+SUMIFS(AC_SOTIEN,AC_TKNO,$A10,AC_PHAITHU,$B10,AC_NGAY,"<"&$F$4)-($E10+SUMIFS(AC_SOTIEN,AC_TKCO,$A10,AC_PHAITRA,$B10,AC_NGAY,"<"&$F$4)),"") | G10: =IF($E10+SUMIFS(AC_SOTIEN,AC_TKCO,$A10,AC_PHAITRA,$B10, AC_NGAY,"<"&$F$4)-($D10+SUMIFS(AC_SOTIEN,AC_TKNO,$A10,AC_PHAITHU,$B10,AC_NGAY,"<"&$F$4))>0,$E10+SUMIFS(AC_SOTIEN,AC_TKCO,$A10,AC_PHAITRA,$B10,AC_NGAY,"<"&$F$4)-($D10+SUMIFS(AC_SOTIEN,AC_TKNO,$A10,AC_PHAITHU,$B10,AC_NGAY,"<"&$F$4)),"") | H10: =SUMIFS(AC_SOTIEN,AC_TKNO,$A10 ,AC_PHAITHU,$B10,AC_NGAY,">="&$F$4,AC_NGAY,"<="&$H$4) -> 0 | I10: =SUMIFS(AC_SOTIEN,AC_TKCO,$A10,AC_PHAITRA, $B10,AC_NGAY,">="&$F$4,AC_NGAY,"<="&$H$4) -> 0 | J10: =IF(F10+H10-G10-I10>=0,F10+H10-G10-I10,0) -> 0 | K10: =IF(G10+I10-H10-F10>=0,G10+I10-H10-F10,0) -> 0 | L10: =IF(SUM(J10:K10)>0,"X","")
A11: 1311 | F11: =if($D11+SUMIFS(AC_SOTIEN,AC_TKNO,$A11,AC_PHAITHU,$B11,AC_NGAY,"<"&$F$4)-($E11+SUMIFS(AC_SOTIEN,AC_TKCO,$A11,AC_PHAITRA,$B11,AC_NGAY,"<"&$F$4))>0,$D11+SUMIFS(AC_SOTIEN,AC_TKNO,$A11,AC_PHAITHU,$B11,AC_NGAY,"<"&$F$4)-($E11+SUMIFS(AC_SOTIEN,AC_TKCO,$A11,AC_PHAITRA,$B11,AC_NGAY,"<"&$F$4)),"") | G11: =IF($E11+SUMIFS(AC_SOTIEN,AC_TKCO,$A11,AC_PHAITRA,$B11, AC_NGAY,"<"&$F$4)-($D11+SUMIFS(AC_SOTIEN,AC_TKNO,$A11,AC_PHAITHU,$B11,AC_NGAY,"<"&$F$4))>0,$E11+SUMIFS(AC_SOTIEN,AC_TKCO,$A11,AC_PHAITRA,$B11,AC_NGAY,"<"&$F$4)-($D11+SUMIFS(AC_SOTIEN,AC_TKNO,$A11,AC_PHAITHU,$B11,AC_NGAY,"<"&$F$4)),"") | H11: =SUMIFS(AC_SOTIEN,AC_TKNO,$A11 ,AC_PHAITHU,$B11,AC_NGAY,">="&$F$4,AC_NGAY,"<="&$H$4) -> 0 | I11: =SUMIFS(AC_SOTIEN,AC_TKCO,$A11,AC_PHAITRA, $B11,AC_NGAY,">="&$F$4,AC_NGAY,"<="&$H$4) -> 0 | J11: =IF(F11+H11-G11-I11>=0,F11+H11-G11-I11,0) -> 0 | K11: =IF(G11+I11-H11-F11>=0,G11+I11-H11-F11,0) -> 0 | L11: =IF(SUM(J11:K11)>0,"X","")
A12: 1311 | F12: =if($D12+SUMIFS(AC_SOTIEN,AC_TKNO,$A12,AC_PHAITHU,$B12,AC_NGAY,"<"&$F$4)-($E12+SUMIFS(AC_SOTIEN,AC_TKCO,$A12,AC_PHAITRA,$B12,AC_NGAY,"<"&$F$4))>0,$D12+SUMIFS(AC_SOTIEN,AC_TKNO,$A12,AC_PHAITHU,$B12,AC_NGAY,"<"&$F$4)-($E12+SUMIFS(AC_SOTIEN,AC_TKCO,$A12,AC_PHAITRA,$B12,AC_NGAY,"<"&$F$4)),"") | G12: =IF($E12+SUMIFS(AC_SOTIEN,AC_TKCO,$A12,AC_PHAITRA,$B12, AC_NGAY,"<"&$F$4)-($D12+SUMIFS(AC_SOTIEN,AC_TKNO,$A12,AC_PHAITHU,$B12,AC_NGAY,"<"&$F$4))>0,$E12+SUMIFS(AC_SOTIEN,AC_TKCO,$A12,AC_PHAITRA,$B12,AC_NGAY,"<"&$F$4)-($D12+SUMIFS(AC_SOTIEN,AC_TKNO,$A12,AC_PHAITHU,$B12,AC_NGAY,"<"&$F$4)),"") | H12: =SUMIFS(AC_SOTIEN,AC_TKNO,$A12 ,AC_PHAITHU,$B12,AC_NGAY,">="&$F$4,AC_NGAY,"<="&$H$4) -> 0 | I12: =SUMIFS(AC_SOTIEN,AC_TKCO,$A12,AC_PHAITRA, $B12,AC_NGAY,">="&$F$4,AC_NGAY,"<="&$H$4) -> 0 | J12: =IF(F12+H12-G12-I12>=0,F12+H12-G12-I12,0) -> 0 | K12: =IF(G12+I12-H12-F12>=0,G12+I12-H12-F12,0) -> 0 | L12: =IF(SUM(J12:K12)>0,"X","")
A13: 1311 | F13: =if($D13+SUMIFS(AC_SOTIEN,AC_TKNO,$A13,AC_PHAITHU,$B13,AC_NGAY,"<"&$F$4)-($E13+SUMIFS(AC_SOTIEN,AC_TKCO,$A13,AC_PHAITRA,$B13,AC_NGAY,"<"&$F$4))>0,$D13+SUMIFS(AC_SOTIEN,AC_TKNO,$A13,AC_PHAITHU,$B13,AC_NGAY,"<"&$F$4)-($E13+SUMIFS(AC_SOTIEN,AC_TKCO,$A13,AC_PHAITRA,$B13,AC_NGAY,"<"&$F$4)),"") | G13: =IF($E13+SUMIFS(AC_SOTIEN,AC_TKCO,$A13,AC_PHAITRA,$B13, AC_NGAY,"<"&$F$4)-($D13+SUMIFS(AC_SOTIEN,AC_TKNO,$A13,AC_PHAITHU,$B13,AC_NGAY,"<"&$F$4))>0,$E13+SUMIFS(AC_SOTIEN,AC_TKCO,$A13,AC_PHAITRA,$B13,AC_NGAY,"<"&$F$4)-($D13+SUMIFS(AC_SOTIEN,AC_TKNO,$A13,AC_PHAITHU,$B13,AC_NGAY,"<"&$F$4)),"") | H13: =SUMIFS(AC_SOTIEN,AC_TKNO,$A13 ,AC_PHAITHU,$B13,AC_NGAY,">="&$F$4,AC_NGAY,"<="&$H$4) -> 0 | I13: =SUMIFS(AC_SOTIEN,AC_TKCO,$A13,AC_PHAITRA, $B13,AC_NGAY,">="&$F$4,AC_NGAY,"<="&$H$4) -> 0 | J13: =IF(F13+H13-G13-I13>=0,F13+H13-G13-I13,0) -> 0 | K13: =IF(G13+I13-H13-F13>=0,G13+I13-H13-F13,0) -> 0 | L13: =IF(SUM(J13:K13)>0,"X","")
A14: 1311 | F14: =if($D14+SUMIFS(AC_SOTIEN,AC_TKNO,$A14,AC_PHAITHU,$B14,AC_NGAY,"<"&$F$4)-($E14+SUMIFS(AC_SOTIEN,AC_TKCO,$A14,AC_PHAITRA,$B14,AC_NGAY,"<"&$F$4))>0,$D14+SUMIFS(AC_SOTIEN,AC_TKNO,$A14,AC_PHAITHU,$B14,AC_NGAY,"<"&$F$4)-($E14+SUMIFS(AC_SOTIEN,AC_TKCO,$A14,AC_PHAITRA,$B14,AC_NGAY,"<"&$F$4)),"") | G14: =IF($E14+SUMIFS(AC_SOTIEN,AC_TKCO,$A14,AC_PHAITRA,$B14, AC_NGAY,"<"&$F$4)-($D14+SUMIFS(AC_SOTIEN,AC_TKNO,$A14,AC_PHAITHU,$B14,AC_NGAY,"<"&$F$4))>0,$E14+SUMIFS(AC_SOTIEN,AC_TKCO,$A14,AC_PHAITRA,$B14,AC_NGAY,"<"&$F$4)-($D14+SUMIFS(AC_SOTIEN,AC_TKNO,$A14,AC_PHAITHU,$B14,AC_NGAY,"<"&$F$4)),"") | H14: =SUMIFS(AC_SOTIEN,AC_TKNO,$A14 ,AC_PHAITHU,$B14,AC_NGAY,">="&$F$4,AC_NGAY,"<="&$H$4) -> 0 | I14: =SUMIFS(AC_SOTIEN,AC_TKCO,$A14,AC_PHAITRA, $B14,AC_NGAY,">="&$F$4,AC_NGAY,"<="&$H$4) -> 0 | J14: =IF(F14+H14-G14-I14>=0,F14+H14-G14-I14,0) -> 0 | K14: =IF(G14+I14-H14-F14>=0,G14+I14-H14-F14,0) -> 0 | L14: =IF(SUM(J14:K14)>0,"X","")
A15: 1311 | F15: =if($D15+SUMIFS(AC_SOTIEN,AC_TKNO,$A15,AC_PHAITHU,$B15,AC_NGAY,"<"&$F$4)-($E15+SUMIFS(AC_SOTIEN,AC_TKCO,$A15,AC_PHAITRA,$B15,AC_NGAY,"<"&$F$4))>0,$D15+SUMIFS(AC_SOTIEN,AC_TKNO,$A15,AC_PHAITHU,$B15,AC_NGAY,"<"&$F$4)-($E15+SUMIFS(AC_SOTIEN,AC_TKCO,$A15,AC_PHAITRA,$B15,AC_NGAY,"<"&$F$4)),"") | G15: =IF($E15+SUMIFS(AC_SOTIEN,AC_TKCO,$A15,AC_PHAITRA,$B15, AC_NGAY,"<"&$F$4)-($D15+SUMIFS(AC_SOTIEN,AC_TKNO,$A15,AC_PHAITHU,$B15,AC_NGAY,"<"&$F$4))>0,$E15+SUMIFS(AC_SOTIEN,AC_TKCO,$A15,AC_PHAITRA,$B15,AC_NGAY,"<"&$F$4)-($D15+SUMIFS(AC_SOTIEN,AC_TKNO,$A15,AC_PHAITHU,$B15,AC_NGAY,"<"&$F$4)),"") | H15: =SUMIFS(AC_SOTIEN,AC_TKNO,$A15 ,AC_PHAITHU,$B15,AC_NGAY,">="&$F$4,AC_NGAY,"<="&$H$4) -> 0 | I15: =SUMIFS(AC_SOTIEN,AC_TKCO,$A15,AC_PHAITRA, $B15,AC_NGAY,">="&$F$4,AC_NGAY,"<="&$H$4) -> 0 | J15: =IF(F15+H15-G15-I15>=0,F15+H15-G15-I15,0) -> 0 | K15: =IF(G15+I15-H15-F15>=0,G15+I15-H15-F15,0) -> 0 | L15: =IF(SUM(J15:K15)>0,"X","")
A16: 1311 | F16: =if($D16+SUMIFS(AC_SOTIEN,AC_TKNO,$A16,AC_PHAITHU,$B16,AC_NGAY,"<"&$F$4)-($E16+SUMIFS(AC_SOTIEN,AC_TKCO,$A16,AC_PHAITRA,$B16,AC_NGAY,"<"&$F$4))>0,$D16+SUMIFS(AC_SOTIEN,AC_TKNO,$A16,AC_PHAITHU,$B16,AC_NGAY,"<"&$F$4)-($E16+SUMIFS(AC_SOTIEN,AC_TKCO,$A16,AC_PHAITRA,$B16,AC_NGAY,"<"&$F$4)),"") | G16: =IF($E16+SUMIFS(AC_SOTIEN,AC_TKCO,$A16,AC_PHAITRA,$B16, AC_NGAY,"<"&$F$4)-($D16+SUMIFS(AC_SOTIEN,AC_TKNO,$A16,AC_PHAITHU,$B16,AC_NGAY,"<"&$F$4))>0,$E16+SUMIFS(AC_SOTIEN,AC_TKCO,$A16,AC_PHAITRA,$B16,AC_NGAY,"<"&$F$4)-($D16+SUMIFS(AC_SOTIEN,AC_TKNO,$A16,AC_PHAITHU,$B16,AC_NGAY,"<"&$F$4)),"") | H16: =SUMIFS(AC_SOTIEN,AC_TKNO,$A16 ,AC_PHAITHU,$B16,AC_NGAY,">="&$F$4,AC_NGAY,"<="&$H$4) -> 0 | I16: =SUMIFS(AC_SOTIEN,AC_TKCO,$A16,AC_PHAITRA, $B16,AC_NGAY,">="&$F$4,AC_NGAY,"<="&$H$4) -> 0 | J16: =IF(F16+H16-G16-I16>=0,F16+H16-G16-I16,0) -> 0 | K16: =IF(G16+I16-H16-F16>=0,G16+I16-H16-F16,0) -> 0 | L16: =IF(SUM(J16:K16)>0,"X","")
