Workbook

Sheet 4.Đơn hàng
H1: BÁN HÀNG | L1: THU TIỀN | N1: CHỨNG TỪ
A2: Ngày tạo đơn | B2: Mã đơn | C2: Tên sản phẩm | D2: Mã KH | E2: KHÁCH HÀNG | F2: Giá niêm yết | G2: Chiết khấu | H2: Thành tiền | I2: Doanh thu | J2: Thuế suất | K2: Thuế | L2: Đã thu | M2: Còn phải thu | N2: Đã xuất hóa đơn | O2: Chưa xuất hóa đơn | P2: Ghi nhận doanh thu
F3: =SUM(F4:F52) -> 1707293943 | G3: =SUM(G4:G52) -> 42071560 | H3: =SUM(H4:H52) -> 1665222383 | I3: =SUM(I4:I52) -> 1541872577 | K3: =SUM(K4:K52) -> 1.2334981e+08 | L3: =SUM(L4:L52) -> 1212725415 | M3: =SUM(M4:M52) -> 452496968 | N3: =SUM(N4:N52) -> 1128755215 | O3: =SUM(O4:O52) -> 536467168
B4: DH01 | C4: NLP Master | D4: KH13 | E4: =IF(D4="","",VLOOKUP($D4,'3.Khách hàng'!$A:$I,2,0)) -> LỮ KIỀU ANH | F4: =IF(C4="","",VLOOKUP($C4,'1.Sản phẩm'!$D:$G,2,0)) -> 64784880 | G4: 17798880 | H4: =F4-G4 -> 46986000 | I4: =H4/(1+J4) -> 43505556 | J4: 0.08 | K4: =J4*I4 -> 3480444.4 | L4: =SUMIF('5.Thu tiền'!$B:$B,$B4,'5.Thu tiền'!$H:$H) -> 46986000 | M4: =H4-L4 -> 7.4505806e-09 | N4: =SUMIF('6.Hóa đơn'!$C:$C,$B4,'6.Hóa đơn'!$G:$G) -> 46986000 | O4: =H4-N4 -> 7.4505806e-09
B5: DH02 | C5: NLP Master | D5: KH14 | E5: =IF(D5="","",VLOOKUP($D5,'3.Khách hàng'!$A:$I,2,0)) -> LÊ THỊ BÍCH NGA | F5: =IF(C5="","",VLOOKUP($C5,'1.Sản phẩm'!$D:$G,2,0)) -> 64784880 | G5: 17798880 | H5: =F5-G5 -> 46986000 | I5: =H5/(1+J5) -> 43505556 | J5: 0.08 | K5: =J5*I5 -> 3480444.4 | L5: =SUMIF('5.Thu tiền'!$B:$B,$B5,'5.Thu tiền'!$H:$H) -> 46986000 | M5: =H5-L5 -> 7.4505806e-09 | N5: =SUMIF('6.Hóa đơn'!$C:$C,$B5,'6.Hóa đơn'!$G:$G) -> 46986000 | O5: =H5-N5 -> 7.4505806e-09
B6: DH03 | C6: Business in the Box | D6: KH15 | E6: =IF(D6="","",VLOOKUP($D6,'3.Khách hàng'!$A:$I,2,0)) -> NGUYỄN THỊ YẾN | F6: 81363391 | H6: =F6-G6 -> 81363391 | I6: =H6/(1+J6) -> 75336473 | J6: 0.08 | K6: =J6*I6 -> 6026917.9 | L6: =SUMIF('5.Thu tiền'!$B:$B,$B6,'5.Thu tiền'!$H:$H) -> 81363391 | M6: =H6-L6 -> 0 | N6: =SUMIF('6.Hóa đơn'!$C:$C,$B6,'6.Hóa đơn'!$G:$G) -> 81363391 | O6: =H6-N6 -> 0 | P6: Tháng 1
B7: DH04 | C7: Business in the Box | D7: KH16 | E7: =IF(D7="","",VLOOKUP($D7,'3.Khách hàng'!$A:$I,2,0)) -> CÔNG TY TNHH TINH KHÍ VIỆT | F7: 81363391 | H7: =F7-G7 -> 81363391 | I7: =H7/(1+J7) -> 75336473 | J7: 0.08 | K7: =J7*I7 -> 6026917.9 | L7: =SUMIF('5.Thu tiền'!$B:$B,$B7,'5.Thu tiền'!$H:$H) -> 81363391 | M7: =H7-L7 -> 0 | N7: =SUMIF('6.Hóa đơn'!$C:$C,$B7,'6.Hóa đơn'!$G:$G) -> 81363391 | O7: =H7-N7 -> 0 | P7: Tháng 1
B8: DH05 | C8: Lãnh đạo chuyển hóa | D8: KH17 | E8: =IF(D8="","",VLOOKUP($D8,'3.Khách hàng'!$A:$I,2,0)) -> CÔNG TY TNHH PAPASAN VIỆT NAM | F8: 1774801 | H8: =F8-G8 -> 1774801 | I8: =H8/(1+J8) -> 1643334.3 | J8: 0.08 | K8: =J8*I8 -> 131466.74 | L8: =SUMIF('5.Thu tiền'!$B:$B,$B8,'5.Thu tiền'!$H:$H) -> 1774801 | M8: =H8-L8 -> 0 | N8: =SUMIF('6.Hóa đơn'!$C:$C,$B8,'6.Hóa đơn'!$G:$G) -> 1774801 | O8: =H8-N8 -> 0 | P8: Tháng 4
B9: DH06 | C9: Lãnh đạo chuyển hóa | D9: KH18 | E9: =IF(D9="","",VLOOKUP($D9,'3.Khách hàng'!$A:$I,2,0)) -> Khách lẻ (Nguyễn Thị Thắm, Nguyễn Thu Huyền) | F9: 1972000 | H9: =F9-G9 -> 1972000 | I9: =H9/(1+J9) -> 1825925.9 | J9: 0.08 | K9: =J9*I9 -> 146074.07 | L9: =SUMIF('5.Thu tiền'!$B:$B,$B9,'5.Thu tiền'!$H:$H) -> 1972000 | M9: =H9-L9 -> 0 | N9: =SUMIF('6.Hóa đơn'!$C:$C,$B9,'6.Hóa đơn'!$G:$G) -> 1972000 | O9: =H9-N9 -> 0
B10: DH07 | C10: Lãnh đạo chuyển hóa | D10: KH19 | E10: =IF(D10="","",VLOOKUP($D10,'3.Khách hàng'!$A:$I,2,0)) -> LÊ NGỌC LINH | F10: 1972000 | H10: =F10-G10 -> 1972000 | I10: =H10/(1+J10) -> 1825925.9 | J10: 0.08 | K10: =J10*I10 -> 146074.07 | L10: =SUMIF('5.Thu tiền'!$B:$B,$B10,'5.Thu tiền'!$H:$H) -> 1972000 | M10: =H10-L10 -> 0 | N10: =SUMIF('6.Hóa đơn'!$C:$C,$B10,'6.Hóa đơn'!$G:$G) -> 1972000 | O10: =H10-N10 -> 0
B11: DH08 | C11: Business in the Box | D11: KH20 | E11: =IF(D11="","",VLOOKUP($D11,'3.Khách hàng'!$A:$I,2,0)) -> PHẠM TRẦN HẢI | F11: =IF(C11="","",VLOOKUP($C11,'1.Sản phẩm'!$D:$G,2,0)) -> 93733000 | H11: =F11-G11 -> 93733000 | I11: =H11/(1+J11) -> 86789815 | J11: 0.08 | K11: =J11*I11 -> 6943185.2 | L11: =SUMIF('5.Thu tiền'!$B:$B,$B11,'5.Thu tiền'!$H:$H) -> 93733000 | M11: =H11-L11 -> 0 | N11: =SUMIF('6.Hóa đơn'!$C:$C,$B11,'6.Hóa đơn'!$G:$G) -> 93733000 | O11: =H11-N11 -> 0 | P11: Tháng 7
B12: DH09 | C12: Business in the Box | D12: KH22 | E12: =IF(D12="","",VLOOKUP($D12,'3.Khách hàng'!$A:$I,2,0)) -> NGUYỄN THỊ HIÊN | F12: =IF(C12="","",VLOOKUP($C12,'1.Sản phẩm'!$D:$G,2,0)) -> 93733000 | H12: =F12-G12 -> 93733000 | I12: =H12/(1+J12) -> 86789815 | J12: 0.08 | K12: =J12*I12 -> 6943185.2 | L12: =SUMIF('5.Thu tiền'!$B:$B,$B12,'5.Thu tiền'!$H:$H) -> 93733000 | M12: =H12-L12 -> 0 | N12: =SUMIF('6.Hóa đơn'!$C:$C,$B12,'6.Hóa đơn'!$G:$G) -> 93733000 | O12: =H12-N12 -> 0 | P12: Tháng 7
B13: DH10 | C13: Business in the Box | D13: KH23 | E13: =IF(D13="","",VLOOKUP($D13,'3.Khách hàng'!$A:$I,2,0)) -> HỘ KINH DOANH NGUYỄN THANH HÙNG | F13: =IF(C13="","",VLOOKUP($C13,'1.Sản phẩm'!$D:$G,2,0)) -> 93733000 | H13: =F13-G13 -> 93733000 | I13: =H13/(1+J13) -> 86789815 | J13: 0.08 | K13: =J13*I13 -> 6943185.2 | L13: =SUMIF('5.Thu tiền'!$B:$B,$B13,'5.Thu tiền'!$H:$H) -> 93733000 | M13: =H13-L13 -> 0 | N13: =SUMIF('6.Hóa đơn'!$C:$C,$B13,'6.Hóa đơn'!$G:$G) -> 93733200 | O13: =H13-N13 -> -200 | P13: Tháng 7
B14: DH11 | C14: Business in the Box | D14: KH29 | E14: =IF(D14="","",VLOOKUP($D14,'3.Khách hàng'!$A:$I,2,0)) -> NGUYỄN THỊ NGỌC HÀ | F14: =IF(C14="","",VLOOKUP($C14,'1.Sản phẩm'!$D:$G,2,0)) -> 93733000 | H14: =F14-G14 -> 93733000 | I14: =H14/(1+J14) -> 86789815 | J14: 0.08 | K14: =J14*I14 -> 6943185.2 | L14: =SUMIF('5.Thu tiền'!$B:$B,$B14,'5.Thu tiền'!$H:$H) -> 10000000 | M14: =H14-L14 -> 83733000 | N14: =SUMIF('6.Hóa đơn'!$C:$C,$B14,'6.Hóa đơn'!$G:$G) -> 0 | O14: =H14-N14 -> 93733000
B15: DH12 | C15: NLP Practitioner | D15: KH28 | E15: =IF(D15="","",VLOOKUP($D15,'3.Khách hàng'!$A:$I,2,0)) -> VÕ TẤN LỢI | F15: =IF(C15="","",VLOOKUP($C15,'1.Sản phẩm'!$D:$G,2,0)) -> 49664880 | H15: =F15-G15 -> 49664880 | I15: =H15/(1+J15) -> 45986000 | J15: 0.08 | K15: =J15*I15 -> 3678880 | L15: =SUMIF('5.Thu tiền'!$B:$B,$B15,'5.Thu tiền'!$H:$H) -> 37894392 | M15: =H15-L15 -> 11770488 | N15: =SUMIF('6.Hóa đơn'!$C:$C,$B15,'6.Hóa đơn'!$G:$G) -> 37894392 | O15: =H15-N15 -> 11770488
B16: DH13 | C16: NLP Practitioner | D16: KH25 | E16: =IF(D16="","",VLOOKUP($D16,'3.Khách hàng'!$A:$I,2,0)) -> NGUYỄN NGỌC HÀ | F16: =IF(C16="","",VLOOKUP($C16,'1.Sản phẩm'!$D:$G,2,0)) -> 49664880 | H16: =F16-G16 -> 49664880 | I16: =H16/(1+J16) -> 45986000 | J16: 0.08 | K16: =J16*I16 -> 3678880 | L16: =SUMIF('5.Thu tiền'!$B:$B,$B16,'5.Thu tiền'!$H:$H) -> 19972440 | M16: =H16-L16 -> 29692440 | N16: =SUMIF('6.Hóa đơn'!$C:$C,$B16,'6.Hóa đơn'!$G:$G) -> 19972440 | O16: =H16-N16 -> 29692440
B17: DH14 | C17: NLP Master | D17: KH22 | E17: =IF(D17="","",VLOOKUP($D17,'3.Khách hàng'!$A:$I,2,0)) -> NGUYỄN THỊ HIÊN | F17: 46986000 | H17: =F17-G17 -> 46986000 | I17: =H17/(1+J17) -> 43505556 | J17: 0.08 | K17: =J17*I17 -> 3480444.4 | L17: =SUMIF('5.Thu tiền'!$B:$B,$B17,'5.Thu tiền'!$H:$H) -> 51986000 | M17: =H17-L17 -> -5000000 | N17: =SUMIF('6.Hóa đơn'!$C:$C,$B17,'6.Hóa đơn'!$G:$G) -> 46986000 | O17: =H17-N17 -> 0
B18: DH15 | C18: Train The Trainer | D18: KH23 | E18: =IF(D18="","",VLOOKUP($D18,'3.Khách hàng'!$A:$I,2,0)) -> HỘ KINH DOANH NGUYỄN THANH HÙNG | F18: 139310000 | H18: =F18-G18 -> 139310000 | I18: =H18/(1+J18) -> 1.2899074e+08 | J18: 0.08 | K18: =J18*I18 -> 10319259 | L18: =SUMIF('5.Thu tiền'!$B:$B,$B18,'5.Thu tiền'!$H:$H) -> 139310000 | M18: =H18-L18 -> 0 | N18: =SUMIF('6.Hóa đơn'!$C:$C,$B18,'6.Hóa đơn'!$G:$G) -> 139310000 | O18: =H18-N18 -> 0
B19: DH16 | C19: NLP Practitioner | D19: KH22 | E19: =IF(D19="","",VLOOKUP($D19,'3.Khách hàng'!$A:$I,2,0)) -> NGUYỄN THỊ HIÊN | F19: 35087000 | H19: =F19-G19 -> 35087000 | I19: =H19/(1+J19) -> 32487963 | J19: 0.08 | K19: =J19*I19 -> 2599037 | L19: =SUMIF('5.Thu tiền'!$B:$B,$B19,'5.Thu tiền'!$H:$H) -> 35087000 | M19: =H19-L19 -> 0 | N19: =SUMIF('6.Hóa đơn'!$C:$C,$B19,'6.Hóa đơn'!$G:$G) -> 0 | O19: =H19-N19 -> 35087000
B20: DH17 | C20: Train The Trainer | D20: KH20 | E20: =IF(D20="","",VLOOKUP($D20,'3.Khách hàng'!$A:$I,2,0)) -> PHẠM TRẦN HẢI | F20: 120986000 | H20: =F20-G20 -> 120986000 | I20: =H20/(1+J20) -> 1.1202407e+08 | J20: 0.08 | K20: =J20*I20 -> 8961925.9 | L20: =SUMIF('5.Thu tiền'!$B:$B,$B20,'5.Thu tiền'!$H:$H) -> 120986000 | M20: =H20-L20 -> 0 | N20: =SUMIF('6.Hóa đơn'!$C:$C,$B20,'6.Hóa đơn'!$G:$G) -> 120986000 | O20: =H20-N20 -> 0 | P20: Tháng 7
B21: DH18 | C21: NLP Master | D21: KH24 | E21: =IF(D21="","",VLOOKUP($D21,'3.Khách hàng'!$A:$I,2,0)) -> CÔNG TY CỔ PHẦN DỊCH VỤ TÀI CHÍNH MINH TRÍ | F21: =IF(C21="","",VLOOKUP($C21,'1.Sản phẩm'!$D:$G,2,0)) -> 64784880 | H21: =F21-G21 -> 64784880 | I21: =H21/(1+J21) -> 59986000 | J21: 0.08 | K21: =J21*I21 -> 4798880 | L21: =SUMIF('5.Thu tiền'!$B:$B,$B21,'5.Thu tiền'!$H:$H) -> 50744800 | M21: =H21-L21 -> 14040080 | N21: =SUMIF('6.Hóa đơn'!$C:$C,$B21,'6.Hóa đơn'!$G:$G) -> 50744800 | O21: =H21-N21 -> 14040080
B22: DH19 | C22: NLP Practitioner | D22: KH24 | E22: =IF(D22="","",VLOOKUP($D22,'3.Khách hàng'!$A:$I,2,0)) -> CÔNG TY CỔ PHẦN DỊCH VỤ TÀI CHÍNH MINH TRÍ | F22: =IF(C22="","",VLOOKUP($C22,'1.Sản phẩm'!$D:$G,2,0)) -> 49664880 | H22: =F22-G22 -> 49664880 | I22: =H22/(1+J22) -> 45986000 | J22: 0.08 | K22: =J22*I22 -> 3678880 | L22: =SUMIF('5.Thu tiền'!$B:$B,$B22,'5.Thu tiền'!$H:$H) -> 36986000 | M22: =H22-L22 -> 12678880 | N22: =SUMIF('6.Hóa đơn'!$C:$C,$B22,'6.Hóa đơn'!$G:$G) -> 36986000 | O22: =H22-N22 -> 12678880
B23: DH20 | C23: NLP Master | D23: KH27 | E23: =IF(D23="","",VLOOKUP($D23,'3.Khách hàng'!$A:$I,2,0)) -> CÔNG TY TNHH JEJU SKIN VIỆT NAM | F23: =IF(C23="","",VLOOKUP($C23,'1.Sản phẩm'!$D:$G,2,0)) -> 64784880 | H23: =F23-G23 -> 64784880 | I23: =H23/(1+J23) -> 59986000 | J23: 0.08 | K23: =J23*I23 -> 4798880 | L23: =SUMIF('5.Thu tiền'!$B:$B,$B23,'5.Thu tiền'!$H:$H) -> 25000000 | M23: =H23-L23 -> 39784880 | N23: =SUMIF('6.Hóa đơn'!$C:$C,$B23,'6.Hóa đơn'!$G:$G) -> 25000000 | O23: =H23-N23 -> 39784880
B24: DH21 | C24: NLP Practitioner | D24: KH27 | E24: =IF(D24="","",VLOOKUP($D24,'3.Khách hàng'!$A:$I,2,0)) -> CÔNG TY TNHH JEJU SKIN VIỆT NAM | F24: =IF(C24="","",VLOOKUP($C24,'1.Sản phẩm'!$D:$G,2,0)) -> 49664880 | H24: =F24-G24 -> 49664880 | I24: =H24/(1+J24) -> 45986000 | J24: 0.08 | K24: =J24*I24 -> 3678880 | L24: =SUMIF('5.Thu tiền'!$B:$B,$B24,'5.Thu tiền'!$H:$H) -> 33287400 | M24: =H24-L24 -> 16377480 | N24: =SUMIF('6.Hóa đơn'!$C:$C,$B24,'6.Hóa đơn'!$G:$G) -> 33287400 | O24: =H24-N24 -> 16377480
B25: DH22 | E25: =IF(D25="","",VLOOKUP($D25,'3.Khách hàng'!$A:$I,2,0)) | H25: =F25-G25 -> 0 | I25: =H25/(1+J25) -> 0 | J25: 0.08 | K25: =J25*I25 -> 0 | L25: =SUMIF('5.Thu tiền'!$B:$B,$B25,'5.Thu tiền'!$H:$H) -> 0 | M25: =H25-L25 -> 0 | N25: =SUMIF('6.Hóa đơn'!$C:$C,$B25,'6.Hóa đơn'!$G:$G) -> 0 | O25: =H25-N25 -> 0
B26: DH23 | E26: =IF(D26="","",VLOOKUP($D26,'3.Khách hàng'!$A:$I,2,0)) | F26: =IF(C26="","",VLOOKUP($C26,'1.Sản phẩm'!$D:$G,2,0)) | H26: =F26-G26 -> 0 | I26: =H26/(1+J26) -> 0 | J26: 0.08 | K26: =J26*I26 -> 0 | L26: =SUMIF('5.Thu tiền'!$B:$B,$B26,'5.Thu tiền'!$H:$H) -> 0 | M26: =H26-L26 -> 0 | N26: =SUMIF('6.Hóa đơn'!$C:$C,$B26,'6.Hóa đơn'!$G:$G) -> 0 | O26: =H26-N26 -> 0
B27: DH24 | C27: Lãnh đạo chuyển hóa | D27: KH02 | E27: =IF(D27="","",VLOOKUP($D27,'3.Khách hàng'!$A:$I,2,0)) -> PHAN THI NGOC | F27: =IF(C27="","",VLOOKUP($C27,'1.Sản phẩm'!$D:$G,2,0)) -> 1064880 | G27: 78880 | H27: =F27-G27 -> 986000 | I27: =H27/(1+J27) -> 912962.96 | J27: 0.08 | K27: =J27*I27 -> 73037.037 | L27: =SUMIF('5.Thu tiền'!$B:$B,$B27,'5.Thu tiền'!$H:$H) -> 986000 | M27: =H27-L27 -> 0 | N27: =SUMIF('6.Hóa đơn'!$C:$C,$B27,'6.Hóa đơn'!$G:$G) -> 0 | O27: =H27-N27 -> 986000
B28: DH25 | C28: Lãnh đạo chuyển hóa | D28: KH03 | E28: =IF(D28="","",VLOOKUP($D28,'3.Khách hàng'!$A:$I,2,0)) -> PHAM THI BICH HUONG | F28: =IF(C28="","",VLOOKUP($C28,'1.Sản phẩm'!$D:$G,2,0)) -> 1064880 | G28: 865880 | H28: =F28-G28 -> 199000 | I28: =H28/(1+J28) -> 184259.26 | J28: 0.08 | K28: =J28*I28 -> 14740.741 | L28: =SUMIF('5.Thu tiền'!$B:$B,$B28,'5.Thu tiền'!$H:$H) -> 199000 | M28: =H28-L28 -> 0 | N28: =SUMIF('6.Hóa đơn'!$C:$C,$B28,'6.Hóa đơn'!$G:$G) -> 0 | O28: =H28-N28 -> 199000
B29: DH26 | C29: Lãnh đạo chuyển hóa | D29: KH04 | E29: =IF(D29="","",VLOOKUP($D29,'3.Khách hàng'!$A:$I,2,0)) -> NGUYEN THI THU HUONG | F29: =IF(C29="","",VLOOKUP($C29,'1.Sản phẩm'!$D:$G,2,0)) -> 1064880 | G29: 664880 | H29: =F29-G29 -> 400000 | I29: =H29/(1+J29) -> 370370.37 | J29: 0.08 | K29: =J29*I29 -> 29629.63 | L29: =SUMIF('5.Thu tiền'!$B:$B,$B29,'5.Thu tiền'!$H:$H) -> 400000 | M29: =H29-L29 -> 0 | N29: =SUMIF('6.Hóa đơn'!$C:$C,$B29,'6.Hóa đơn'!$G:$G) -> 0 | O29: =H29-N29 -> 400000
B30: DH27 | C30: Lãnh đạo chuyển hóa | D30: KH07 | E30: =IF(D30="","",VLOOKUP($D30,'3.Khách hàng'!$A:$I,2,0)) -> DAM THI PHUONG THAO | F30: =IF(C30="","",VLOOKUP($C30,'1.Sản phẩm'!$D:$G,2,0)) -> 1064880 | G30: 267880 | H30: =F30-G30 -> 797000 | I30: =H30/(1+J30) -> 737962.96 | J30: 0.08 | K30: =J30*I30 -> 59037.037 | L30: =SUMIF('5.Thu tiền'!$B:$B,$B30,'5.Thu tiền'!$H:$H) -> 797000 | M30: =H30-L30 -> 0 | N30: =SUMIF('6.Hóa đơn'!$C:$C,$B30,'6.Hóa đơn'!$G:$G) -> 597000 | O30: =H30-N30 -> 200000
B31: DH28 | C31: Lãnh đạo chuyển hóa | D31: KH08 | E31: =IF(D31="","",VLOOKUP($D31,'3.Khách hàng'!$A:$I,2,0)) -> TRAN QUANG NGHIEP | F31: =IF(C31="","",VLOOKUP($C31,'1.Sản phẩm'!$D:$G,2,0)) -> 1064880 | G31: 664880 | H31: =F31-G31 -> 400000 | I31: =H31/(1+J31) -> 370370.37 | J31: 0.08 | K31: =J31*I31 -> 29629.63 | L31: =SUMIF('5.Thu tiền'!$B:$B,$B31,'5.Thu tiền'!$H:$H) -> 400000 | M31: =H31-L31 -> 0 | N31: =SUMIF('6.Hóa đơn'!$C:$C,$B31,'6.Hóa đơn'!$G:$G) -> 0 | O31: =H31-N31 -> 400000
B32: DH29 | C32: Lãnh đạo chuyển hóa | D32: KH09 | E32: =IF(D32="","",VLOOKUP($D32,'3.Khách hàng'!$A:$I,2,0)) -> MAI THỊ THANH QUY | F32: =IF(C32="","",VLOOKUP($C32,'1.Sản phẩm'!$D:$G,2,0)) -> 1064880 | G32: 865880 | H32: =F32-G32 -> 199000 | I32: =H32/(1+J32) -> 184259.26 | J32: 0.08 | K32: =J32*I32 -> 14740.741 | L32: =SUMIF('5.Thu tiền'!$B:$B,$B32,'5.Thu tiền'!$H:$H) -> 199000 | M32: =H32-L32 -> 0 | N32: =SUMIF('6.Hóa đơn'!$C:$C,$B32,'6.Hóa đơn'!$G:$G) -> 0 | O32: =H32-N32 -> 199000
B33: DH30 | C33: Lãnh đạo chuyển hóa | D33: KH10 | E33: =IF(D33="","",VLOOKUP($D33,'3.Khách hàng'!$A:$I,2,0)) -> PHAM XUAN THUY | F33: =IF(C33="","",VLOOKUP($C33,'1.Sản phẩm'!$D:$G,2,0)) -> 1064880 | G33: 865880 | H33: =F33-G33 -> 199000 | I33: =H33/(1+J33) -> 184259.26 | J33: 0.08 | K33: =J33*I33 -> 14740.741 | L33: =SUMIF('5.Thu tiền'!$B:$B,$B33,'5.Thu tiền'!$H:$H) -> 199000 | M33: =H33-L33 -> 0 | N33: =SUMIF('6.Hóa đơn'!$C:$C,$B33,'6.Hóa đơn'!$G:$G) -> 0 | O33: =H33-N33 -> 199000
B34: DH31 | C34: Lãnh đạo chuyển hóa | D34: KH11 | E34: =IF(D34="","",VLOOKUP($D34,'3.Khách hàng'!$A:$I,2,0)) -> NGUYEN TRUNG CHIEN | F34: =IF(C34="","",VLOOKUP($C34,'1.Sản phẩm'!$D:$G,2,0)) -> 1064880 | G34: 865880 | H34: =F34-G34 -> 199000 | I34: =H34/(1+J34) -> 184259.26 | J34: 0.08 | K34: =J34*I34 -> 14740.741 | L34: =SUMIF('5.Thu tiền'!$B:$B,$B34,'5.Thu tiền'!$H:$H) -> 199000 | M34: =H34-L34 -> 0 | N34: =SUMIF('6.Hóa đơn'!$C:$C,$B34,'6.Hóa đơn'!$G:$G) -> 0 | O34: =H34-N34 -> 199000
B35: DH32 | C35: Lãnh đạo chuyển hóa | D35: KH12 | E35: =IF(D35="","",VLOOKUP($D35,'3.Khách hàng'!$A:$I,2,0)) -> VU DINH HOANG ANH | F35: =IF(C35="","",VLOOKUP($C35,'1.Sản phẩm'!$D:$G,2,0)) -> 1064880 | G35: 865880 | H35: =F35-G35 -> 199000 | I35: =H35/(1+J35) -> 184259.26 | J35: 0.08 | K35: =J35*I35 -> 14740.741 | L35: =SUMIF('5.Thu tiền'!$B:$B,$B35,'5.Thu tiền'!$H:$H) -> 199000 | M35: =H35-L35 -> 0 | N35: =SUMIF('6.Hóa đơn'!$C:$C,$B35,'6.Hóa đơn'!$G:$G) -> 0 | O35: =H35-N35 -> 199000
B36: DH33 | C36: Lãnh đạo chuyển hóa | D36: KH21 | E36: =IF(D36="","",VLOOKUP($D36,'3.Khách hàng'!$A:$I,2,0)) -> CÔNG TY TNHH DỊCH VỤ VÀ THƯƠNG MẠI MSC | F36: =IF(C36="","",VLOOKUP($C36,'1.Sản phẩm'!$D:$G,2,0)) -> 1064880 | G36: 467880 | H36: =F36-G36 -> 597000 | I36: =H36/(1+J36) -> 552777.78 | J36: 0.08 | K36: =J36*I36 -> 44222.222 | L36: =SUMIF('5.Thu tiền'!$B:$B,$B36,'5.Thu tiền'!$H:$H) -> 597000 | M36: =H36-L36 -> 0 | N36: =SUMIF('6.Hóa đơn'!$C:$C,$B36,'6.Hóa đơn'!$G:$G) -> 0 | O36: =H36-N36 -> 597000
B37: DH34 | E37: =IF(D37="","",VLOOKUP($D37,'3.Khách hàng'!$A:$I,2,0)) | H37: =F37-G37 -> 0 | I37: =H37/(1+J37) -> 0 | J37: 0.08 | K37: =J37*I37 -> 0 | L37: =SUMIF('5.Thu tiền'!$B:$B,$B37,'5.Thu tiền'!$H:$H) -> 0 | M37: =H37-L37 -> 0 | N37: =SUMIF('6.Hóa đơn'!$C:$C,$B37,'6.Hóa đơn'!$G:$G) -> 35087000 | O37: =H37-N37 -> -35087000
B38: DH35 | C38: Train The Trainer | D38: KH01 | E38: =IF(D38="","",VLOOKUP($D38,'3.Khách hàng'!$A:$I,2,0)) -> MAI THUY PHUONG | F38: =IF(C38="","",VLOOKUP($C38,'1.Sản phẩm'!$D:$G,2,0)) -> 204104880 | H38: =F38-G38 -> 204104880 | I38: =H38/(1+J38) -> 188986000 | J38: 0.08 | K38: =J38*I38 -> 15118880 | L38: =SUMIF('5.Thu tiền'!$B:$B,$B38,'5.Thu tiền'!$H:$H) -> 5000000 | M38: =H38-L38 -> 199104880 | N38: =SUMIF('6.Hóa đơn'!$C:$C,$B38,'6.Hóa đơn'!$G:$G) -> 5000000 | O38: =H38-N38 -> 199104880
B39: DH36 | C39: NLP Practitioner | D39: KH06 | E39: =IF(D39="","",VLOOKUP($D39,'3.Khách hàng'!$A:$I,2,0)) -> DANG THANH TRA MY | F39: =IF(C39="","",VLOOKUP($C39,'1.Sản phẩm'!$D:$G,2,0)) -> 49664880 | H39: =F39-G39 -> 49664880 | I39: =H39/(1+J39) -> 45986000 | J39: 0.08 | K39: =J39*I39 -> 3678880 | L39: =SUMIF('5.Thu tiền'!$B:$B,$B39,'5.Thu tiền'!$H:$H) -> 23287400 | M39: =H39-L39 -> 26377480 | N39: =SUMIF('6.Hóa đơn'!$C:$C,$B39,'6.Hóa đơn'!$G:$G) -> 0 | O39: =H39-N39 -> 49664880
B40: DH37 | C40: NLP Practitioner | D40: KH30 | E40: =IF(D40="","",VLOOKUP($D40,'3.Khách hàng'!$A:$I,2,0)) -> VÕ THỊ MỸ LỘC | F40: =IF(C40="","",VLOOKUP($C40,'1.Sản phẩm'!$D:$G,2,0)) -> 49664880 | H40: =F40-G40 -> 49664880 | I40: =H40/(1+J40) -> 45986000 | J40: 0.08 | K40: =J40*I40 -> 3678880 | L40: =SUMIF('5.Thu tiền'!$B:$B,$B40,'5.Thu tiền'!$H:$H) -> 42105000 | M40: =H40-L40 -> 7559880 | N40: =SUMIF('6.Hóa đơn'!$C:$C,$B40,'6.Hóa đơn'!$G:$G) -> 0 | O40: =H40-N40 -> 49664880
...

Sheet 5.Thu tiền
A1: Ngày | B1: Mã đơn hàng | C1: Tên sản phẩm | D1: Mã khách hàng | E1: KHÁCH HÀNG | F1: Diễn giải | G1: Số hóa đơn | H1: Số tiền thu | I1: Doanh thu | J1: Thuế suất | K1: Thuế | L1: Đã xuất hóa đơn | M1: Chưa xuất hóa đơn | N1: Ghi chú
F2: Tổng | H2: =SUM(H3:H80) -> 1212725415 | I2: =SUM(I3:I80) -> 1122893903 | K2: =SUM(K3:K80) -> 89831512 | L2: =SUM(L3:L80) -> 1094226975 | M2: =SUM(M3:M80) -> 118498440
A3: 46027 | B3: DH01 | C3: =IF(B3="","",VLOOKUP($B3,'4.Đơn hàng'!$B:$N,2,0)) -> NLP Master | D3: =IF(C3="","",VLOOKUP($B3,'4.Đơn hàng'!$B:$E,3,0)) -> KH13 | E3: =IF(D3="","",VLOOKUP($D3,'3.Khách hàng'!$A:$I,2,0)) -> LỮ KIỀU ANH | F3: Chương trình đào taọ NLP Master | G3: 1 | H3: 46986000 | I3: =H3/(1+J3) -> 43505556 | J3: 0.08 | K3: =J3*I3 -> 3480444.4 | L3: 46986000 | M3: =H3-L3 -> 0
A4: 46028 | B4: DH02 | C4: =IF(B4="","",VLOOKUP($B4,'4.Đơn hàng'!$B:$N,2,0)) -> NLP Master | D4: =IF(C4="","",VLOOKUP($B4,'4.Đơn hàng'!$B:$E,3,0)) -> KH14 | E4: =IF(D4="","",VLOOKUP($D4,'3.Khách hàng'!$A:$I,2,0)) -> LÊ THỊ BÍCH NGA | F4: Chương trình đào taọ NLP Master | G4: 2 | H4: 46986000 | I4: =H4/(1+J4) -> 43505556 | J4: 0.08 | K4: =J4*I4 -> 3480444.4 | L4: 46986000 | M4: =H4-L4 -> 0
A5: 46041 | B5: DH03 | C5: =IF(B5="","",VLOOKUP($B5,'4.Đơn hàng'!$B:$N,2,0)) -> Business in the Box | D5: =IF(C5="","",VLOOKUP($B5,'4.Đơn hàng'!$B:$E,3,0)) -> KH15 | E5: =IF(D5="","",VLOOKUP($D5,'3.Khách hàng'!$A:$I,2,0)) -> NGUYỄN THỊ YẾN | F5: Dịch vụ tư vấn quản lý doanh nghiệp | G5: 3 | H5: 81363391 | I5: =H5/(1+J5) -> 75336473 | J5: 0.08 | K5: =J5*I5 -> 6026917.9 | L5: 81363391 | M5: =H5-L5 -> 0
A6: 46041 | B6: DH04 | C6: =IF(B6="","",VLOOKUP($B6,'4.Đơn hàng'!$B:$N,2,0)) -> Business in the Box | D6: =IF(C6="","",VLOOKUP($B6,'4.Đơn hàng'!$B:$E,3,0)) -> KH16 | E6: =IF(D6="","",VLOOKUP($D6,'3.Khách hàng'!$A:$I,2,0)) -> CÔNG TY TNHH TINH KHÍ VIỆT | F6: Dịch vụ tư vấn quản lý doanh nghiệp | G6: 4 | H6: 81363391 | I6: =H6/(1+J6) -> 75336473 | J6: 0.08 | K6: =J6*I6 -> 6026917.9 | L6: 81363391 | M6: =H6-L6 -> 0
A7: 46051 | B7: DH05 | C7: =IF(B7="","",VLOOKUP($B7,'4.Đơn hàng'!$B:$N,2,0)) -> Lãnh đạo chuyển hóa | D7: =IF(C7="","",VLOOKUP($B7,'4.Đơn hàng'!$B:$E,3,0)) -> KH17 | E7: =IF(D7="","",VLOOKUP($D7,'3.Khách hàng'!$A:$I,2,0)) -> CÔNG TY TNHH PAPASAN VIỆT NAM | F7: Dịch vụ đào tạo kỹ năng lãnh đạo chuyển hoá | G7: 5 | H7: 1774801 | I7: =H7/(1+J7) -> 1643334.3 | J7: 0.08 | K7: =J7*I7 -> 131466.74 | L7: 1774801 | M7: =H7-L7 -> 0
A8: 46051 | B8: DH06 | C8: =IF(B8="","",VLOOKUP($B8,'4.Đơn hàng'!$B:$N,2,0)) -> Lãnh đạo chuyển hóa | D8: =IF(C8="","",VLOOKUP($B8,'4.Đơn hàng'!$B:$E,3,0)) -> KH18 | E8: =IF(D8="","",VLOOKUP($D8,'3.Khách hàng'!$A:$I,2,0)) -> Khách lẻ (Nguyễn Thị Thắm, Nguyễn Thu Huyền) | F8: Dịch vụ đào tạo kỹ năng lãnh đạo chuyển hoá | G8: 6 | H8: 1972000 | I8: =H8/(1+J8) -> 1825925.9 | J8: 0.08 | K8: =J8*I8 -> 146074.07 | L8: 1972000 | M8: =H8-L8 -> 0
A9: 46051 | B9: DH07 | C9: =IF(B9="","",VLOOKUP($B9,'4.Đơn hàng'!$B:$N,2,0)) -> Lãnh đạo chuyển hóa | D9: =IF(C9="","",VLOOKUP($B9,'4.Đơn hàng'!$B:$E,3,0)) -> KH19 | E9: =IF(D9="","",VLOOKUP($D9,'3.Khách hàng'!$A:$I,2,0)) -> LÊ NGỌC LINH | F9: Dịch vụ đào tạo kỹ năng lãnh đạo chuyển hoá | G9: 7 | H9: 1972000 | I9: =H9/(1+J9) -> 1825925.9 | J9: 0.08 | K9: =J9*I9 -> 146074.07 | L9: 1972000 | M9: =H9-L9 -> 0
A10: 46136 | B10: DH17 | C10: =IF(B10="","",VLOOKUP($B10,'4.Đơn hàng'!$B:$N,2,0)) -> Train The Trainer | D10: =IF(C10="","",VLOOKUP($B10,'4.Đơn hàng'!$B:$E,3,0)) -> KH20 | E10: =IF(D10="","",VLOOKUP($D10,'3.Khách hàng'!$A:$I,2,0)) -> PHẠM TRẦN HẢI | F10: Chương trình đào tạo Train The Trainer | G10: 8 | H10: 120986000 | I10: =H10/(1+J10) -> 1.1202407e+08 | J10: 0.08 | K10: =J10*I10 -> 8961925.9 | L10: 120986000 | M10: =H10-L10 -> 0
A11: 46063 | B11: DH35 | C11: =IF(B11="","",VLOOKUP($B11,'4.Đơn hàng'!$B:$N,2,0)) -> Train The Trainer | D11: =IF(C11="","",VLOOKUP($B11,'4.Đơn hàng'!$B:$E,3,0)) -> KH01 | E11: =IF(D11="","",VLOOKUP($D11,'3.Khách hàng'!$A:$I,2,0)) -> MAI THUY PHUONG | F11: TT hoc phi khoa hoc | G11: 14 | H11: 5000000 | I11: =H11/(1+J11) -> 4629629.6 | J11: 0.08 | K11: =J11*I11 -> 370370.37 | M11: =H11-L11 -> 5000000 | N11: cccd: 038190030472 Maithuyphuong90@gmail.com
A12: 46111 | B12: DH24 | C12: =IF(B12="","",VLOOKUP($B12,'4.Đơn hàng'!$B:$N,2,0)) -> Lãnh đạo chuyển hóa | D12: =IF(C12="","",VLOOKUP($B12,'4.Đơn hàng'!$B:$E,3,0)) -> KH02 | E12: =IF(D12="","",VLOOKUP($D12,'3.Khách hàng'!$A:$I,2,0)) -> PHAN THI NGOC | F12: Nop hoc phi khoa hoc | H12: 986000 | I12: =H12/(1+J12) -> 912962.96 | J12: 0.08 | K12: =J12*I12 -> 73037.037 | M12: =H12-L12 -> 986000 | N12: Chưa xin được thông tin
A13: 46142 | B13: DH25 | C13: =IF(B13="","",VLOOKUP($B13,'4.Đơn hàng'!$B:$N,2,0)) -> Lãnh đạo chuyển hóa | D13: =IF(C13="","",VLOOKUP($B13,'4.Đơn hàng'!$B:$E,3,0)) -> KH03 | E13: =IF(D13="","",VLOOKUP($D13,'3.Khách hàng'!$A:$I,2,0)) -> PHAM THI BICH HUONG | F13: LDCH | H13: 199000 | I13: =H13/(1+J13) -> 184259.26 | J13: 0.08 | K13: =J13*I13 -> 14740.741 | M13: =H13-L13 -> 199000 | N13: ko xin đc cccd
A14: 46142 | B14: DH26 | C14: =IF(B14="","",VLOOKUP($B14,'4.Đơn hàng'!$B:$N,2,0)) -> Lãnh đạo chuyển hóa | D14: =IF(C14="","",VLOOKUP($B14,'4.Đơn hàng'!$B:$E,3,0)) -> KH04 | E14: =IF(D14="","",VLOOKUP($D14,'3.Khách hàng'!$A:$I,2,0)) -> NGUYEN THI THU HUONG | F14: NTTH Chuyen tien | H14: 400000 | I14: =H14/(1+J14) -> 370370.37 | J14: 0.08 | K14: =J14*I14 -> 29629.63 | M14: =H14-L14 -> 400000 | N14: ko xin đc cccd
A15: 46126 | B15: DH27 | C15: =IF(B15="","",VLOOKUP($B15,'4.Đơn hàng'!$B:$N,2,0)) -> Lãnh đạo chuyển hóa | D15: =IF(C15="","",VLOOKUP($B15,'4.Đơn hàng'!$B:$E,3,0)) -> KH07 | E15: =IF(D15="","",VLOOKUP($D15,'3.Khách hàng'!$A:$I,2,0)) -> DAM THI PHUONG THAO | F15: ck khoa hoc NLP | H15: 597000 | I15: =H15/(1+J15) -> 552777.78 | J15: 0.08 | K15: =J15*I15 -> 44222.222 | M15: =H15-L15 -> 597000 | N15: ko xin đc cccd
A16: 46121 | B16: DH36 | C16: =IF(B16="","",VLOOKUP($B16,'4.Đơn hàng'!$B:$N,2,0)) -> NLP Practitioner | D16: =IF(C16="","",VLOOKUP($B16,'4.Đơn hàng'!$B:$E,3,0)) -> KH06 | E16: =IF(D16="","",VLOOKUP($D16,'3.Khách hàng'!$A:$I,2,0)) -> DANG THANH TRA MY | F16: TEAMI ck nhanh qua zalo | H16: 23287400 | I16: =H16/(1+J16) -> 21562407 | J16: 0.08 | K16: =J16*I16 -> 1724992.6 | M16: =H16-L16 -> 23287400 | N16: Chưa xin được thông tin. Cuối tháng học viên đến lớp học thì có thể xin trực tiếp
A17: 46150 | B17: DH27 | C17: =IF(B17="","",VLOOKUP($B17,'4.Đơn hàng'!$B:$N,2,0)) -> Lãnh đạo chuyển hóa | D17: =IF(C17="","",VLOOKUP($B17,'4.Đơn hàng'!$B:$E,3,0)) -> KH07 | E17: =IF(D17="","",VLOOKUP($D17,'3.Khách hàng'!$A:$I,2,0)) -> DAM THI PHUONG THAO | F17: dam thi phuong thao chuyen tien qr | H17: 200000 | I17: =H17/(1+J17) -> 185185.19 | J17: 0.08 | K17: =J17*I17 -> 14814.815 | M17: =H17-L17 -> 200000 | N17: ko xin đc cccd
A18: 46150 | B18: DH28 | C18: =IF(B18="","",VLOOKUP($B18,'4.Đơn hàng'!$B:$N,2,0)) -> Lãnh đạo chuyển hóa | D18: =IF(C18="","",VLOOKUP($B18,'4.Đơn hàng'!$B:$E,3,0)) -> KH08 | E18: =IF(D18="","",VLOOKUP($D18,'3.Khách hàng'!$A:$I,2,0)) -> TRAN QUANG NGHIEP | F18: tran quang nghiep ck nhanh qua zalo | H18: 400000 | I18: =H18/(1+J18) -> 370370.37 | J18: 0.08 | K18: =J18*I18 -> 29629.63 | M18: =H18-L18 -> 400000 | N18: ko xin đc cccd
A19: 46148 | B19: DH29 | C19: =IF(B19="","",VLOOKUP($B19,'4.Đơn hàng'!$B:$N,2,0)) -> Lãnh đạo chuyển hóa | D19: =IF(C19="","",VLOOKUP($B19,'4.Đơn hàng'!$B:$E,3,0)) -> KH09 | E19: =IF(D19="","",VLOOKUP($D19,'3.Khách hàng'!$A:$I,2,0)) -> MAI THỊ THANH QUY | F19: ck nhanh qua zalo | H19: 199000 | I19: =H19/(1+J19) -> 184259.26 | J19: 0.08 | K19: =J19*I19 -> 14740.741 | M19: =H19-L19 -> 199000 | N19: ko xin đc cccd
A20: 46147 | B20: DH30 | C20: =IF(B20="","",VLOOKUP($B20,'4.Đơn hàng'!$B:$N,2,0)) -> Lãnh đạo chuyển hóa | D20: =IF(C20="","",VLOOKUP($B20,'4.Đơn hàng'!$B:$E,3,0)) -> KH10 | E20: =IF(D20="","",VLOOKUP($D20,'3.Khách hàng'!$A:$I,2,0)) -> PHAM XUAN THUY | F20: ck khoa hoc NLP | H20: 199000 | I20: =H20/(1+J20) -> 184259.26 | J20: 0.08 | K20: =J20*I20 -> 14740.741 | M20: =H20-L20 -> 199000 | N20: ko xin đc cccd
A21: 46147 | B21: DH31 | C21: =IF(B21="","",VLOOKUP($B21,'4.Đơn hàng'!$B:$N,2,0)) -> Lãnh đạo chuyển hóa | D21: =IF(C21="","",VLOOKUP($B21,'4.Đơn hàng'!$B:$E,3,0)) -> KH11 | E21: =IF(D21="","",VLOOKUP($D21,'3.Khách hàng'!$A:$I,2,0)) -> NGUYEN TRUNG CHIEN | F21: nguyen trung chien ck nhanh qua zalo | H21: 199000 | I21: =H21/(1+J21) -> 184259.26 | J21: 0.08 | K21: =J21*I21 -> 14740.741 | M21: =H21-L21 -> 199000 | N21: ko xin đc cccd
A22: 46146 | B22: DH32 | C22: =IF(B22="","",VLOOKUP($B22,'4.Đơn hàng'!$B:$N,2,0)) -> Lãnh đạo chuyển hóa | D22: =IF(C22="","",VLOOKUP($B22,'4.Đơn hàng'!$B:$E,3,0)) -> KH12 | E22: =IF(D22="","",VLOOKUP($D22,'3.Khách hàng'!$A:$I,2,0)) -> VU DINH HOANG ANH | F22: VĐHA chuyen tien hoc quan ly | H22: 199000 | I22: =H22/(1+J22) -> 184259.26 | J22: 0.08 | K22: =J22*I22 -> 14740.741 | M22: =H22-L22 -> 199000 | N22: ko xin đc cccd
A23: 46155 | B23: DH33 | C23: =IF(B23="","",VLOOKUP($B23,'4.Đơn hàng'!$B:$N,2,0)) -> Lãnh đạo chuyển hóa | D23: =IF(C23="","",VLOOKUP($B23,'4.Đơn hàng'!$B:$E,3,0)) -> KH21 | E23: =IF(D23="","",VLOOKUP($D23,'3.Khách hàng'!$A:$I,2,0)) -> CÔNG TY TNHH DỊCH VỤ VÀ THƯƠNG MẠI MSC | F23: Chương trình Lãnh Đạo Chuyển Hóa | G23: 9 | H23: 597000 | I23: =H23/(1+J23) -> 552777.78 | J23: 0.08 | K23: =J23*I23 -> 44222.222 | L23: 597000 | M23: =H23-L23 -> 0
A24: 46156 | B24: DH16 | C24: =IF(B24="","",VLOOKUP($B24,'4.Đơn hàng'!$B:$N,2,0)) -> NLP Practitioner | D24: =IF(C24="","",VLOOKUP($B24,'4.Đơn hàng'!$B:$E,3,0)) -> KH22 | E24: =IF(D24="","",VLOOKUP($D24,'3.Khách hàng'!$A:$I,2,0)) -> NGUYỄN THỊ HIÊN | F24: Chương trình NLP Practitioner | G24: 10 | H24: 35087000 | I24: =H24/(1+J24) -> 32487963 | J24: 0.08 | K24: =J24*I24 -> 2599037 | L24: 35087000 | M24: =H24-L24 -> 0
A25: 46156 | B25: DH20 | C25: =IF(B25="","",VLOOKUP($B25,'4.Đơn hàng'!$B:$N,2,0)) -> NLP Master | D25: =IF(C25="","",VLOOKUP($B25,'4.Đơn hàng'!$B:$E,3,0)) -> KH27 | E25: =IF(D25="","",VLOOKUP($D25,'3.Khách hàng'!$A:$I,2,0)) -> CÔNG TY TNHH JEJU SKIN VIỆT NAM | F25: Chương trình Master NLP Practitioner | G25: 11 | H25: 25000000 | I25: =H25/(1+J25) -> 23148148 | J25: 0.08 | K25: =J25*I25 -> 1851851.9 | L25: 25000000 | M25: =H25-L25 -> 0
A26: 46160 | B26: DH21 | C26: =IF(B26="","",VLOOKUP($B26,'4.Đơn hàng'!$B:$N,2,0)) -> NLP Practitioner | D26: =IF(C26="","",VLOOKUP($B26,'4.Đơn hàng'!$B:$E,3,0)) -> KH27 | E26: =IF(D26="","",VLOOKUP($D26,'3.Khách hàng'!$A:$I,2,0)) -> CÔNG TY TNHH JEJU SKIN VIỆT NAM | F26: 1 Chương trình Master NLP Practitioner | G26: 12 | H26: 33287400 | I26: =H26/(1+J26) -> 30821667 | J26: 0.08 | K26: =J26*I26 -> 2465733.3 | L26: 33287400 | M26: =H26-L26 -> 0
A27: 46160 | B27: DH19 | C27: =IF(B27="","",VLOOKUP($B27,'4.Đơn hàng'!$B:$N,2,0)) -> NLP Practitioner | D27: =IF(C27="","",VLOOKUP($B27,'4.Đơn hàng'!$B:$E,3,0)) -> KH24 | E27: =IF(D27="","",VLOOKUP($D27,'3.Khách hàng'!$A:$I,2,0)) -> CÔNG TY CỔ PHẦN DỊCH VỤ TÀI CHÍNH MINH TRÍ | F27: Chương trình NLP Practitioner | G27: 13 | H27: 36986000 | I27: =H27/(1+J27) -> 34246296 | J27: 0.08 | K27: =J27*I27 -> 2739703.7 | L27: 36986000 | M27: =H27-L27 -> 0
A28: 46167 | B28: DH13 | C28: =IF(B28="","",VLOOKUP($B28,'4.Đơn hàng'!$B:$N,2,0)) -> NLP Practitioner | D28: =IF(C28="","",VLOOKUP($B28,'4.Đơn hàng'!$B:$E,3,0)) -> KH25 | E28: =IF(D28="","",VLOOKUP($D28,'3.Khách hàng'!$A:$I,2,0)) -> NGUYỄN NGỌC HÀ | F28: Chương trình NLP Practitioner | G28: 15 | H28: 19972440 | I28: =H28/(1+J28) -> 18493000 | J28: 0.08 | K28: =J28*I28 -> 1479440 | L28: 19972440 | M28: =H28-L28 -> 0
A29: 46178 | B29: DH18 | C29: =IF(B29="","",VLOOKUP($B29,'4.Đơn hàng'!$B:$N,2,0)) -> NLP Master | D29: =IF(C29="","",VLOOKUP($B29,'4.Đơn hàng'!$B:$E,3,0)) -> KH24 | E29: =IF(D29="","",VLOOKUP($D29,'3.Khách hàng'!$A:$I,2,0)) -> CÔNG TY CỔ PHẦN DỊCH VỤ TÀI CHÍNH MINH TRÍ | F29: Chương trình Master NLP Practitioner | G29: 18 | H29: 50744800 | I29: =H29/(1+J29) -> 46985926 | J29: 0.08 | K29: =J29*I29 -> 3758874.1 | L29: 50744880 | M29: =H29-L29 -> -80
A30: 46178 | B30: DH14 | C30: =IF(B30="","",VLOOKUP($B30,'4.Đơn hàng'!$B:$N,2,0)) -> NLP Master | D30: =IF(C30="","",VLOOKUP($B30,'4.Đơn hàng'!$B:$E,3,0)) -> KH22 | E30: =IF(D30="","",VLOOKUP($D30,'3.Khách hàng'!$A:$I,2,0)) -> NGUYỄN THỊ HIÊN | F30: Chương trình Master NLP Practitioner | G30: 17 | H30: 46986000 | I30: =H30/(1+J30) -> 43505556 | J30: 0.08 | K30: =J30*I30 -> 3480444.4 | L30: 50744880 | M30: =H30-L30 -> -3758880
A31: 46202 | B31: DH15 | C31: =IF(B31="","",VLOOKUP($B31,'4.Đơn hàng'!$B:$N,2,0)) -> Train The Trainer | D31: =IF(C31="","",VLOOKUP($B31,'4.Đơn hàng'!$B:$E,3,0)) -> KH23 | E31: =IF(D31="","",VLOOKUP($D31,'3.Khách hàng'!$A:$I,2,0)) -> HỘ KINH DOANH NGUYỄN THANH HÙNG | F31: NGUYEN HOANG ANH hoc Trainer NLP | G31: 19 | H31: 100000000 | I31: =H31/(1+J31) -> 92592593 | J31: 0.08 | K31: =J31*I31 -> 7407407.4 | L31: 100000000 | M31: =H31-L31 -> 0
A32: 46202 | B32: DH15 | C32: =IF(B32="","",VLOOKUP($B32,'4.Đơn hàng'!$B:$N,2,0)) -> Train The Trainer | D32: =IF(C32="","",VLOOKUP($B32,'4.Đơn hàng'!$B:$E,3,0)) -> KH23 | E32: =IF(D32="","",VLOOKUP($D32,'3.Khách hàng'!$A:$I,2,0)) -> HỘ KINH DOANH NGUYỄN THANH HÙNG | F32: NGUYEN HOANG ANH hoc Trainer NLP | G32: 19 | H32: 39310000 | I32: =H32/(1+J32) -> 36398148 | J32: 0.08 | K32: =J32*I32 -> 2911851.9 | L32: 39310000 | M32: =H32-L32 -> 0
A33: 46210 | B33: DH14 | C33: =IF(B33="","",VLOOKUP($B33,'4.Đơn hàng'!$B:$N,2,0)) -> NLP Master | D33: =IF(C33="","",VLOOKUP($B33,'4.Đơn hàng'!$B:$E,3,0)) -> KH22 | E33: =IF(D33="","",VLOOKUP($D33,'3.Khách hàng'!$A:$I,2,0)) -> NGUYỄN THỊ HIÊN | F33: Chương trình Master NLP Practitioner | H33: 500000 | I33: =H33/(1+J33) -> 462962.96 | J33: 0.08 | K33: =J33*I33 -> 37037.037 | M33: =H33-L33 -> 500000
A34: 46210 | B34: DH14 | C34: =IF(B34="","",VLOOKUP($B34,'4.Đơn hàng'!$B:$N,2,0)) -> NLP Master | D34: =IF(C34="","",VLOOKUP($B34,'4.Đơn hàng'!$B:$E,3,0)) -> KH22 | E34: =IF(D34="","",VLOOKUP($D34,'3.Khách hàng'!$A:$I,2,0)) -> NGUYỄN THỊ HIÊN | F34: Chương trình Master NLP Practitioner | H34: 4500000 | I34: =H34/(1+J34) -> 4166666.7 | J34: 0.08 | K34: =J34*I34 -> 333333.33 | M34: =H34-L34 -> 4500000
A35: 46227 | B35: DH12 | C35: =IF(B35="","",VLOOKUP($B35,'4.Đơn hàng'!$B:$N,2,0)) -> NLP Practitioner | D35: =IF(C35="","",VLOOKUP($B35,'4.Đơn hàng'!$B:$E,3,0)) -> KH28 | E35: =IF(D35="","",VLOOKUP($D35,'3.Khách hàng'!$A:$I,2,0)) -> VÕ TẤN LỢI | F35: Khóa học NLP Nhà Thực Hành | G35: 20 | H35: 37894392 | I35: =H35/(1+J35) -> 35087400 | J35: 0.08 | K35: =J35*I35 -> 2806992 | L35: 37894392 | M35: =H35-L35 -> 0
A36: 46227 | B36: DH08 | C36: =IF(B36="","",VLOOKUP($B36,'4.Đơn hàng'!$B:$N,2,0)) -> Business in the Box | D36: =IF(C36="","",VLOOKUP($B36,'4.Đơn hàng'!$B:$E,3,0)) -> KH20 | E36: =IF(D36="","",VLOOKUP($D36,'3.Khách hàng'!$A:$I,2,0)) -> PHẠM TRẦN HẢI | F36: Business in the Box | G36: 23 | H36: 30000000 | I36: =H36/(1+J36) -> 27777778 | J36: 0.08 | K36: =J36*I36 -> 2222222.2 | L36: 30000000 | M36: =H36-L36 -> 0
A37: 46227 | B37: DH11 | C37: =IF(B37="","",VLOOKUP($B37,'4.Đơn hàng'!$B:$N,2,0)) -> Business in the Box | D37: =IF(C37="","",VLOOKUP($B37,'4.Đơn hàng'!$B:$E,3,0)) -> KH29 | E37: =IF(D37="","",VLOOKUP($D37,'3.Khách hàng'!$A:$I,2,0)) -> NGUYỄN THỊ NGỌC HÀ | F37: Business in the Box | H37: 10000000 | I37: =H37/(1+J37) -> 9259259.3 | J37: 0.08 | K37: =J37*I37 -> 740740.74 | M37: =H37-L37 -> 10000000
A38: 46227 | B38: DH09 | C38: =IF(B38="","",VLOOKUP($B38,'4.Đơn hàng'!$B:$N,2,0)) -> Business in the Box | D38: =IF(C38="","",VLOOKUP($B38,'4.Đơn hàng'!$B:$E,3,0)) -> KH22 | E38: =IF(D38="","",VLOOKUP($D38,'3.Khách hàng'!$A:$I,2,0)) -> NGUYỄN THỊ HIÊN | F38: Business in the Box | G38: 22 | H38: 10000000 | I38: =H38/(1+J38) -> 9259259.3 | J38: 0.08 | K38: =J38*I38 -> 740740.74 | L38: 10000000 | M38: =H38-L38 -> 0
A39: 46227 | B39: DH10 | C39: =IF(B39="","",VLOOKUP($B39,'4.Đơn hàng'!$B:$N,2,0)) -> Business in the Box | D39: =IF(C39="","",VLOOKUP($B39,'4.Đơn hàng'!$B:$E,3,0)) -> KH23 | E39: =IF(D39="","",VLOOKUP($D39,'3.Khách hàng'!$A:$I,2,0)) -> HỘ KINH DOANH NGUYỄN THANH HÙNG | F39: Business in the Box | G39: 24 | H39: 30000000 | I39: =H39/(1+J39) -> 27777778 | J39: 0.08 | K39: =J39*I39 -> 2222222.2 | L39: 30000000 | M39: =H39-L39 -> 0
A40: 46228 | B40: DH37 | C40: =IF(B40="","",VLOOKUP($B40,'4.Đơn hàng'!$B:$N,2,0)) -> NLP Practitioner | D40: =IF(C40="","",VLOOKUP($B40,'4.Đơn hàng'!$B:$E,3,0)) -> KH30 | E40: =IF(D40="","",VLOOKUP($D40,'3.Khách hàng'!$A:$I,2,0)) -> VÕ THỊ MỸ LỘC | F40: Khóa học NLP Nhà Thực Hành | H40: 42105000 | I40: =H40/(1+J40) -> 38986111 | J40: 0.08 | K40: =J40*I40 -> 3118888.9 | M40: =H40-L40 -> 42105000
...

Sheet 6.Hóa đơn
A1: Số hoá đơn | B1: Ngày tháng | C1: Đơn hàng | D1: Tên sản phẩm | E1: Mã khách hàng | F1: Khách hàng | G1: Tổng | H1: Tiền hàng | I1: Thuế suất | J1: Tiền thuế | K1: Nội dung
G2: =SUM(G3:G58) -> 1128755215 | H2: =SUM(H3:H58) -> 1045143718 | J2: =SUM(J3:J58) -> 83611497
A3: 1 | B3: 46027 | C3: DH01 | D3: =IF(C3="","",VLOOKUP($C3,'4.Đơn hàng'!$B:$N,2,0)) -> NLP Master | E3: =IF(C3="","",VLOOKUP($C3,'4.Đơn hàng'!$B:$E,3,0)) -> KH13 | F3: =IF(E3="","",VLOOKUP($E3,'3.Khách hàng'!$A:$I,2,0)) -> LỮ KIỀU ANH | G3: 46986000 | H3: =G3/(1+I3) -> 43505556 | I3: 0.08 | J3: =I3*H3 -> 3480444.4 | K3: Chương trình đào taọ NLP Master
A4: 2 | B4: 46028 | C4: DH02 | D4: =IF(C4="","",VLOOKUP($C4,'4.Đơn hàng'!$B:$N,2,0)) -> NLP Master | E4: =IF(C4="","",VLOOKUP($C4,'4.Đơn hàng'!$B:$E,3,0)) -> KH14 | F4: =IF(E4="","",VLOOKUP($E4,'3.Khách hàng'!$A:$I,2,0)) -> LÊ THỊ BÍCH NGA | G4: 46986000 | H4: =G4/(1+I4) -> 43505556 | I4: 0.08 | J4: =I4*H4 -> 3480444.4 | K4: Chương trình đào taọ NLP Master
A5: 3 | B5: 46041 | C5: DH03 | D5: =IF(C5="","",VLOOKUP($C5,'4.Đơn hàng'!$B:$N,2,0)) -> Business in the Box | E5: =IF(C5="","",VLOOKUP($C5,'4.Đơn hàng'!$B:$E,3,0)) -> KH15 | F5: =IF(E5="","",VLOOKUP($E5,'3.Khách hàng'!$A:$I,2,0)) -> NGUYỄN THỊ YẾN | G5: 81363391 | H5: =G5/(1+I5) -> 75336473 | I5: 0.08 | J5: =I5*H5 -> 6026917.9 | K5: Dịch vụ tư vấn quản lý doanh nghiệp
A6: 4 | B6: 46041 | C6: DH04 | D6: =IF(C6="","",VLOOKUP($C6,'4.Đơn hàng'!$B:$N,2,0)) -> Business in the Box | E6: =IF(C6="","",VLOOKUP($C6,'4.Đơn hàng'!$B:$E,3,0)) -> KH16 | F6: =IF(E6="","",VLOOKUP($E6,'3.Khách hàng'!$A:$I,2,0)) -> CÔNG TY TNHH TINH KHÍ VIỆT | G6: 81363391 | H6: =G6/(1+I6) -> 75336473 | I6: 0.08 | J6: =I6*H6 -> 6026917.9 | K6: Dịch vụ tư vấn quản lý doanh nghiệp
A7: 5 | B7: 46051 | C7: DH05 | D7: =IF(C7="","",VLOOKUP($C7,'4.Đơn hàng'!$B:$N,2,0)) -> Lãnh đạo chuyển hóa | E7: =IF(C7="","",VLOOKUP($C7,'4.Đơn hàng'!$B:$E,3,0)) -> KH17 | F7: =IF(E7="","",VLOOKUP($E7,'3.Khách hàng'!$A:$I,2,0)) -> CÔNG TY TNHH PAPASAN VIỆT NAM | G7: 1774801 | H7: =G7/(1+I7) -> 1643334.3 | I7: 0.08 | J7: =I7*H7 -> 131466.74 | K7: Dịch vụ đào tạo kỹ năng lãnh đạo chuyển hoá
A8: 6 | B8: 46051 | C8: DH06 | D8: =IF(C8="","",VLOOKUP($C8,'4.Đơn hàng'!$B:$N,2,0)) -> Lãnh đạo chuyển hóa | E8: =IF(C8="","",VLOOKUP($C8,'4.Đơn hàng'!$B:$E,3,0)) -> KH18 | F8: =IF(E8="","",VLOOKUP($E8,'3.Khách hàng'!$A:$I,2,0)) -> Khách lẻ (Nguyễn Thị Thắm, Nguyễn Thu Huyền) | G8: 1972000 | H8: =G8/(1+I8) -> 1825925.9 | I8: 0.08 | J8: =I8*H8 -> 146074.07 | K8: Dịch vụ đào tạo kỹ năng lãnh đạo chuyển hoá
A9: 7 | B9: 46051 | C9: DH07 | D9: =IF(C9="","",VLOOKUP($C9,'4.Đơn hàng'!$B:$N,2,0)) -> Lãnh đạo chuyển hóa | E9: =IF(C9="","",VLOOKUP($C9,'4.Đơn hàng'!$B:$E,3,0)) -> KH19 | F9: =IF(E9="","",VLOOKUP($E9,'3.Khách hàng'!$A:$I,2,0)) -> LÊ NGỌC LINH | G9: 1972000 | H9: =G9/(1+I9) -> 1825925.9 | I9: 0.08 | J9: =I9*H9 -> 146074.07 | K9: Dịch vụ đào tạo kỹ năng lãnh đạo chuyển hoá
A10: 8 | B10: 46136 | C10: DH17 | D10: =IF(C10="","",VLOOKUP($C10,'4.Đơn hàng'!$B:$N,2,0)) -> Train The Trainer | E10: =IF(C10="","",VLOOKUP($C10,'4.Đơn hàng'!$B:$E,3,0)) -> KH20 | F10: =IF(E10="","",VLOOKUP($E10,'3.Khách hàng'!$A:$I,2,0)) -> PHẠM TRẦN HẢI | G10: 120986000 | H10: =G10/(1+I10) -> 1.1202407e+08 | I10: 0.08 | J10: =I10*H10 -> 8961925.9 | K10: Chương trình đào tạo Train The Trainer
A11: 9 | B11: 46155 | C11: DH27 | D11: =IF(C11="","",VLOOKUP($C11,'4.Đơn hàng'!$B:$N,2,0)) -> Lãnh đạo chuyển hóa | E11: =IF(C11="","",VLOOKUP($C11,'4.Đơn hàng'!$B:$E,3,0)) -> KH07 | F11: =IF(E11="","",VLOOKUP($E11,'3.Khách hàng'!$A:$I,2,0)) -> DAM THI PHUONG THAO | G11: 597000 | H11: =G11/(1+I11) -> 552777.78 | I11: 0.08 | J11: =I11*H11 -> 44222.222 | K11: Chương trình Lãnh Đạo Chuyển Hóa
A12: 10 | B12: 46156 | C12: DH34 | D12: =IF(C12="","",VLOOKUP($C12,'4.Đơn hàng'!$B:$N,2,0)) | E12: =IF(C12="","",VLOOKUP($C12,'4.Đơn hàng'!$B:$E,3,0)) | F12: =IF(E12="","",VLOOKUP($E12,'3.Khách hàng'!$A:$I,2,0)) | G12: 35087000 | H12: =G12/(1+I12) -> 32487963 | I12: 0.08 | J12: =I12*H12 -> 2599037 | K12: Chương trình NLP Practitioner
A13: 11 | B13: 46156 | C13: DH20 | D13: =IF(C13="","",VLOOKUP($C13,'4.Đơn hàng'!$B:$N,2,0)) -> NLP Master | E13: =IF(C13="","",VLOOKUP($C13,'4.Đơn hàng'!$B:$E,3,0)) -> KH27 | F13: =IF(E13="","",VLOOKUP($E13,'3.Khách hàng'!$A:$I,2,0)) -> CÔNG TY TNHH JEJU SKIN VIỆT NAM | G13: 25000000 | H13: =G13/(1+I13) -> 23148148 | I13: 0.08 | J13: =I13*H13 -> 1851851.9 | K13: Chương trình Master NLP Practitioner
A14: 12 | B14: 46160 | C14: DH21 | D14: =IF(C14="","",VLOOKUP($C14,'4.Đơn hàng'!$B:$N,2,0)) -> NLP Practitioner | E14: =IF(C14="","",VLOOKUP($C14,'4.Đơn hàng'!$B:$E,3,0)) -> KH27 | F14: =IF(E14="","",VLOOKUP($E14,'3.Khách hàng'!$A:$I,2,0)) -> CÔNG TY TNHH JEJU SKIN VIỆT NAM | G14: 33287400 | H14: =G14/(1+I14) -> 30821667 | I14: 0.08 | J14: =I14*H14 -> 2465733.3 | K14: 1 Chương trình Master NLP Practitioner
A15: 13 | B15: 46160 | C15: DH19 | D15: =IF(C15="","",VLOOKUP($C15,'4.Đơn hàng'!$B:$N,2,0)) -> NLP Practitioner | E15: =IF(C15="","",VLOOKUP($C15,'4.Đơn hàng'!$B:$E,3,0)) -> KH24 | F15: =IF(E15="","",VLOOKUP($E15,'3.Khách hàng'!$A:$I,2,0)) -> CÔNG TY CỔ PHẦN DỊCH VỤ TÀI CHÍNH MINH TRÍ | G15: 36986000 | H15: =G15/(1+I15) -> 34246296 | I15: 0.08 | J15: =I15*H15 -> 2739703.7 | K15: Chương trình NLP Practitioner
A16: 14 | B16: 46160 | C16: DH35 | D16: =IF(C16="","",VLOOKUP($C16,'4.Đơn hàng'!$B:$N,2,0)) -> Train The Trainer | E16: =IF(C16="","",VLOOKUP($C16,'4.Đơn hàng'!$B:$E,3,0)) -> KH01 | F16: =IF(E16="","",VLOOKUP($E16,'3.Khách hàng'!$A:$I,2,0)) -> MAI THUY PHUONG | G16: 5000000 | H16: =G16/(1+I16) -> 4629629.6 | I16: 0.08 | J16: =I16*H16 -> 370370.37
A17: 15 | B17: 46167 | C17: DH13 | D17: =IF(C17="","",VLOOKUP($C17,'4.Đơn hàng'!$B:$N,2,0)) -> NLP Practitioner | E17: =IF(C17="","",VLOOKUP($C17,'4.Đơn hàng'!$B:$E,3,0)) -> KH25 | F17: =IF(E17="","",VLOOKUP($E17,'3.Khách hàng'!$A:$I,2,0)) -> NGUYỄN NGỌC HÀ | G17: 19972440 | H17: =G17/(1+I17) -> 18493000 | I17: 0.08 | J17: =I17*H17 -> 1479440 | K17: Chương trình NLP Practitioner
A18: 16 | B18: 46177 | C18: DH38 | D18: =IF(C18="","",VLOOKUP($C18,'4.Đơn hàng'!$B:$N,2,0)) -> NLP Practitioner | E18: =IF(C18="","",VLOOKUP($C18,'4.Đơn hàng'!$B:$E,3,0)) -> KH31 | F18: =IF(E18="","",VLOOKUP($E18,'3.Khách hàng'!$A:$I,2,0)) -> NGUYỄN THỊ KIM | G18: 33287400 | H18: =G18/(1+I18) -> 30821667 | I18: 0.08 | J18: =I18*H18 -> 2465733.3
A19: 17 | B19: 46178 | C19: DH14 | D19: =IF(C19="","",VLOOKUP($C19,'4.Đơn hàng'!$B:$N,2,0)) -> NLP Master | E19: =IF(C19="","",VLOOKUP($C19,'4.Đơn hàng'!$B:$E,3,0)) -> KH22 | F19: =IF(E19="","",VLOOKUP($E19,'3.Khách hàng'!$A:$I,2,0)) -> NGUYỄN THỊ HIÊN | G19: 46986000 | H19: =G19/(1+I19) -> 43505556 | I19: 0.08 | J19: =I19*H19 -> 3480444.4 | K19: Chương trình Master NLP Practitioner
A20: 18 | B20: 46178 | C20: DH18 | D20: =IF(C20="","",VLOOKUP($C20,'4.Đơn hàng'!$B:$N,2,0)) -> NLP Master | E20: =IF(C20="","",VLOOKUP($C20,'4.Đơn hàng'!$B:$E,3,0)) -> KH24 | F20: =IF(E20="","",VLOOKUP($E20,'3.Khách hàng'!$A:$I,2,0)) -> CÔNG TY CỔ PHẦN DỊCH VỤ TÀI CHÍNH MINH TRÍ | G20: 50744800 | H20: =G20/(1+I20) -> 46985926 | I20: 0.08 | J20: =I20*H20 -> 3758874.1 | K20: Chương trình Master NLP Practitioner
A21: 19 | B21: 46202 | C21: DH15 | D21: =IF(C21="","",VLOOKUP($C21,'4.Đơn hàng'!$B:$N,2,0)) -> Train The Trainer | E21: =IF(C21="","",VLOOKUP($C21,'4.Đơn hàng'!$B:$E,3,0)) -> KH23 | F21: =IF(E21="","",VLOOKUP($E21,'3.Khách hàng'!$A:$I,2,0)) -> HỘ KINH DOANH NGUYỄN THANH HÙNG | G21: 139310000 | H21: =G21/(1+I21) -> 1.2899074e+08 | I21: 0.08 | J21: =I21*H21 -> 10319259 | K21: NGUYEN HOANG ANH hoc Trainer NLP
A22: 20 | B22: 46227 | C22: DH12 | D22: =IF(C22="","",VLOOKUP($C22,'4.Đơn hàng'!$B:$N,2,0)) -> NLP Practitioner | E22: =IF(C22="","",VLOOKUP($C22,'4.Đơn hàng'!$B:$E,3,0)) -> KH28 | F22: =IF(E22="","",VLOOKUP($E22,'3.Khách hàng'!$A:$I,2,0)) -> VÕ TẤN LỢI | G22: 37894392 | H22: =G22/(1+I22) -> 35087400 | I22: 0.08 | J22: =I22*H22 -> 2806992 | K22: Khóa học NLP Nhà Thực Hành
A23: 21 | B23: 46235 | C23: DH10 | D23: =IF(C23="","",VLOOKUP($C23,'4.Đơn hàng'!$B:$N,2,0)) -> Business in the Box | E23: =IF(C23="","",VLOOKUP($C23,'4.Đơn hàng'!$B:$E,3,0)) -> KH23 | F23: =IF(E23="","",VLOOKUP($E23,'3.Khách hàng'!$A:$I,2,0)) -> HỘ KINH DOANH NGUYỄN THANH HÙNG | G23: 63733200 | H23: =G23/(1+I23) -> 59012222 | I23: 0.08 | J23: =I23*H23 -> 4720977.8 | K23: Business in the Box
A24: 22 | B24: 46235 | C24: DH09 | D24: =IF(C24="","",VLOOKUP($C24,'4.Đơn hàng'!$B:$N,2,0)) -> Business in the Box | E24: =IF(C24="","",VLOOKUP($C24,'4.Đơn hàng'!$B:$E,3,0)) -> KH22 | F24: =IF(E24="","",VLOOKUP($E24,'3.Khách hàng'!$A:$I,2,0)) -> NGUYỄN THỊ HIÊN | G24: 93733000 | H24: =G24/(1+I24) -> 86789815 | I24: 0.08 | J24: =I24*H24 -> 6943185.2 | K24: Business in the Box
A25: 23 | B25: 46235 | C25: DH08 | D25: =IF(C25="","",VLOOKUP($C25,'4.Đơn hàng'!$B:$N,2,0)) -> Business in the Box | E25: =IF(C25="","",VLOOKUP($C25,'4.Đơn hàng'!$B:$E,3,0)) -> KH20 | F25: =IF(E25="","",VLOOKUP($E25,'3.Khách hàng'!$A:$I,2,0)) -> PHẠM TRẦN HẢI | G25: 93733000 | H25: =G25/(1+I25) -> 86789815 | I25: 0.08 | J25: =I25*H25 -> 6943185.2 | K25: Business in the Box
A26: 24 | B26: 46227 | C26: DH10 | D26: =IF(C26="","",VLOOKUP($C26,'4.Đơn hàng'!$B:$N,2,0)) -> Business in the Box | E26: =IF(C26="","",VLOOKUP($C26,'4.Đơn hàng'!$B:$E,3,0)) -> KH23 | F26: =IF(E26="","",VLOOKUP($E26,'3.Khách hàng'!$A:$I,2,0)) -> HỘ KINH DOANH NGUYỄN THANH HÙNG | G26: 30000000 | H26: =G26/(1+I26) -> 27777778 | I26: 0.08 | J26: =I26*H26 -> 2222222.2 | K26: Business in the Box
D27: =IF(C27="","",VLOOKUP($C27,'4.Đơn hàng'!$B:$N,2,0)) | E27: =IF(C27="","",VLOOKUP($C27,'4.Đơn hàng'!$B:$E,3,0)) | F27: =IF(E27="","",VLOOKUP($E27,'3.Khách hàng'!$A:$I,2,0)) | H27: =G27/(1+I27) -> 0 | I27: 0.08 | J27: =I27*H27 -> 0
D28: =IF(C28="","",VLOOKUP($C28,'4.Đơn hàng'!$B:$N,2,0)) | E28: =IF(C28="","",VLOOKUP($C28,'4.Đơn hàng'!$B:$E,3,0)) | F28: =IF(E28="","",VLOOKUP($E28,'3.Khách hàng'!$A:$I,2,0)) | H28: =G28/(1+I28) -> 0 | I28: 0.08 | J28: =I28*H28 -> 0
D29: =IF(C29="","",VLOOKUP($C29,'4.Đơn hàng'!$B:$N,2,0)) | E29: =IF(C29="","",VLOOKUP($C29,'4.Đơn hàng'!$B:$E,3,0)) | F29: =IF(E29="","",VLOOKUP($E29,'3.Khách hàng'!$A:$I,2,0)) | H29: =G29/(1+I29) -> 0 | I29: 0.08 | J29: =I29*H29 -> 0
D30: =IF(C30="","",VLOOKUP($C30,'4.Đơn hàng'!$B:$N,2,0)) | E30: =IF(C30="","",VLOOKUP($C30,'4.Đơn hàng'!$B:$E,3,0)) | F30: =IF(E30="","",VLOOKUP($E30,'3.Khách hàng'!$A:$I,2,0)) | H30: =G30/(1+I30) -> 0 | I30: 0.08 | J30: =I30*H30 -> 0
D31: =IF(C31="","",VLOOKUP($C31,'4.Đơn hàng'!$B:$N,2,0)) | E31: =IF(C31="","",VLOOKUP($C31,'4.Đơn hàng'!$B:$E,3,0)) | F31: =IF(E31="","",VLOOKUP($E31,'3.Khách hàng'!$A:$I,2,0)) | H31: =G31/(1+I31) -> 0 | I31: 0.08 | J31: =I31*H31 -> 0
D32: =IF(C32="","",VLOOKUP($C32,'4.Đơn hàng'!$B:$N,2,0)) | E32: =IF(C32="","",VLOOKUP($C32,'4.Đơn hàng'!$B:$E,3,0)) | F32: =IF(E32="","",VLOOKUP($E32,'3.Khách hàng'!$A:$I,2,0)) | H32: =G32/(1+I32) -> 0 | I32: 0.08 | J32: =I32*H32 -> 0
D33: =IF(C33="","",VLOOKUP($C33,'4.Đơn hàng'!$B:$N,2,0)) | E33: =IF(C33="","",VLOOKUP($C33,'4.Đơn hàng'!$B:$E,3,0)) | F33: =IF(E33="","",VLOOKUP($E33,'3.Khách hàng'!$A:$I,2,0)) | H33: =G33/(1+I33) -> 0 | I33: 0.08 | J33: =I33*H33 -> 0
D34: =IF(C34="","",VLOOKUP($C34,'4.Đơn hàng'!$B:$N,2,0)) | E34: =IF(C34="","",VLOOKUP($C34,'4.Đơn hàng'!$B:$E,3,0)) | F34: =IF(E34="","",VLOOKUP($E34,'3.Khách hàng'!$A:$I,2,0)) | H34: =G34/(1+I34) -> 0 | I34: 0.08 | J34: =I34*H34 -> 0
D35: =IF(C35="","",VLOOKUP($C35,'4.Đơn hàng'!$B:$N,2,0)) | E35: =IF(C35="","",VLOOKUP($C35,'4.Đơn hàng'!$B:$E,3,0)) | F35: =IF(E35="","",VLOOKUP($E35,'3.Khách hàng'!$A:$I,2,0)) | H35: =G35/(1+I35) -> 0 | I35: 0.08 | J35: =I35*H35 -> 0
D36: =IF(C36="","",VLOOKUP($C36,'4.Đơn hàng'!$B:$N,2,0)) | E36: =IF(C36="","",VLOOKUP($C36,'4.Đơn hàng'!$B:$E,3,0)) | F36: =IF(E36="","",VLOOKUP($E36,'3.Khách hàng'!$A:$I,2,0)) | H36: =G36/(1+I36) -> 0 | I36: 0.08 | J36: =I36*H36 -> 0
D37: =IF(C37="","",VLOOKUP($C37,'4.Đơn hàng'!$B:$N,2,0)) | E37: =IF(C37="","",VLOOKUP($C37,'4.Đơn hàng'!$B:$E,3,0)) | F37: =IF(E37="","",VLOOKUP($E37,'3.Khách hàng'!$A:$I,2,0)) | H37: =G37/(1+I37) -> 0 | I37: 0.08 | J37: =I37*H37 -> 0
D38: =IF(C38="","",VLOOKUP($C38,'4.Đơn hàng'!$B:$N,2,0)) | E38: =IF(C38="","",VLOOKUP($C38,'4.Đơn hàng'!$B:$E,3,0)) | F38: =IF(E38="","",VLOOKUP($E38,'3.Khách hàng'!$A:$I,2,0)) | H38: =G38/(1+I38) -> 0 | I38: 0.08 | J38: =I38*H38 -> 0
... D58: =IF(C58="","",VLOOKUP($C58,'4.Đơn hàng'!$B:$N,2,0)) | E58: =IF(C58="","",VLOOKUP($C58,'4.Đơn hàng'!$B:$E,3,0)) | F58: =IF(E58="","",VLOOKUP($E58,'3.Khách hàng'!$A:$I,2,0)) | H58: =G58/(1+I58) -> 0 | I58: 0.08 | J58: =I58*H58 -> 0

Sheet 7.Doanh thu
A1: Mã đơn hàng | B1: Mã khách hàng | C1: KHÁCH HÀNG | D1: Sản phẩm | E1: Doanh số | F1: DOANH THU | G1: Tháng 1 | H1: Tháng 2 | I1: Tháng 3 | J1: Tháng 4 | K1: Tháng 5 | L1: Tháng 6 | M1: Tháng 7 | N1: Tháng 8 | O1: Tháng 9 | P1: Tháng 10 | Q1: Tháng 11 | R1: Tháng 12
E2: =SUM(E3:E16) -> 445700583 | F2: =SUM(F3:F16) -> 412685725 | G2: =SUM(G3:G16) -> 1.5067295e+08 | H2: =SUM(H3:H16) -> 0 | I2: =SUM(I3:I16) -> 0 | J2: =SUM(J3:J16) -> 1643334.3 | K2: =SUM(K3:K16) -> 0 | L2: =SUM(L3:L16) -> 0 | ... R2: =SUM(R3:R16) -> 0
A3: DH08 | B3: =IF(A3="","",VLOOKUP($A3,'4.Đơn hàng'!$B:$E,3,0)) -> KH20 | C3: =IF(B3="","",VLOOKUP($B3,'3.Khách hàng'!$A:$I,2,0)) -> PHẠM TRẦN HẢI | D3: =IF(A3="","",VLOOKUP($A3,'4.Đơn hàng'!$B:$N,2,0)) -> Business in the Box | E3: =SUMIF('4.Đơn hàng'!$B:$B,$A3,'4.Đơn hàng'!$H:$H) -> 93733000 | F3: =SUMIFS('4.Đơn hàng'!$I:$I,'4.Đơn hàng'!$B:$B,$A3) -> 86789815 | G3: =SUMIFS('4.Đơn hàng'!$I:$I,'4.Đơn hàng'!$B:$B,$A3,'4.Đơn hàng'!$P:$P,G$1) -> 0 | H3: =SUMIFS('4.Đơn hàng'!$I:$I,'4.Đơn hàng'!$B:$B,$A3,'4.Đơn hàng'!$P:$P,H$1) -> 0 | I3: =SUMIFS('4.Đơn hàng'!$I:$I,'4.Đơn hàng'!$B:$B,$A3,'4.Đơn hàng'!$P:$P,I$1) -> 0 | J3: =SUMIFS('4.Đơn hàng'!$I:$I,'4.Đơn hàng'!$B:$B,$A3,'4.Đơn hàng'!$P:$P,J$1) -> 0 | K3: =SUMIFS('4.Đơn hàng'!$I:$I,'4.Đơn hàng'!$B:$B,$A3,'4.Đơn hàng'!$P:$P,K$1) -> 0 | L3: =SUMIFS('4.Đơn hàng'!$I:$I,'4.Đơn hàng'!$B:$B,$A3,'4.Đơn hàng'!$P:$P,L$1) -> 0 | M3: =SUMIFS('4.Đơn hàng'!$I:$I,'4.Đơn hàng'!$B:$B,$A3,'4.Đơn hàng'!$P:$P,M$1) -> 86789815 | N3: =SUMIFS('4.Đơn hàng'!$I:$I,'4.Đơn hàng'!$B:$B,$A3,'4.Đơn hàng'!$P:$P,N$1) -> 0 | ... R3: =SUMIFS('4.Đơn hàng'!$I:$I,'4.Đơn hàng'!$B:$B,$A3,'4.Đơn hàng'!$P:$P,R$1) -> 0
A4: DH09 | B4: =IF(A4="","",VLOOKUP($A4,'4.Đơn hàng'!$B:$E,3,0)) -> KH22 | C4: =IF(B4="","",VLOOKUP($B4,'3.Khách hàng'!$A:$I,2,0)) -> NGUYỄN THỊ HIÊN | D4: =IF(A4="","",VLOOKUP($A4,'4.Đơn hàng'!$B:$N,2,0)) -> Business in the Box | E4: =SUMIF('4.Đơn hàng'!$B:$B,$A4,'4.Đơn hàng'!$H:$H) -> 93733000 | F4: =SUMIFS('4.Đơn hàng'!$I:$I,'4.Đơn hàng'!$B:$B,$A4) -> 86789815 | G4: =SUMIFS('4.Đơn hàng'!$I:$I,'4.Đơn hàng'!$B:$B,$A4,'4.Đơn hàng'!$P:$P,G$1) -> 0 | H4: =SUMIFS('4.Đơn hàng'!$I:$I,'4.Đơn hàng'!$B:$B,$A4,'4.Đơn hàng'!$P:$P,H$1) -> 0 | I4: =SUMIFS('4.Đơn hàng'!$I:$I,'4.Đơn hàng'!$B:$B,$A4,'4.Đơn hàng'!$P:$P,I$1) -> 0 | J4: =SUMIFS('4.Đơn hàng'!$I:$I,'4.Đơn hàng'!$B:$B,$A4,'4.Đơn hàng'!$P:$P,J$1) -> 0 | K4: =SUMIFS('4.Đơn hàng'!$I:$I,'4.Đơn hàng'!$B:$B,$A4,'4.Đơn hàng'!$P:$P,K$1) -> 0 | L4: =SUMIFS('4.Đơn hàng'!$I:$I,'4.Đơn hàng'!$B:$B,$A4,'4.Đơn hàng'!$P:$P,L$1) -> 0 | M4: =SUMIFS('4.Đơn hàng'!$I:$I,'4.Đơn hàng'!$B:$B,$A4,'4.Đơn hàng'!$P:$P,M$1) -> 86789815 | N4: =SUMIFS('4.Đơn hàng'!$I:$I,'4.Đơn hàng'!$B:$B,$A4,'4.Đơn hàng'!$P:$P,N$1) -> 0 | ... R4: =SUMIFS('4.Đơn hàng'!$I:$I,'4.Đơn hàng'!$B:$B,$A4,'4.Đơn hàng'!$P:$P,R$1) -> 0
A5: DH10 | B5: =IF(A5="","",VLOOKUP($A5,'4.Đơn hàng'!$B:$E,3,0)) -> KH23 | C5: =IF(B5="","",VLOOKUP($B5,'3.Khách hàng'!$A:$I,2,0)) -> HỘ KINH DOANH NGUYỄN THANH HÙNG | D5: =IF(A5="","",VLOOKUP($A5,'4.Đơn hàng'!$B:$N,2,0)) -> Business in the Box | E5: =SUMIF('4.Đơn hàng'!$B:$B,$A5,'4.Đơn hàng'!$H:$H) -> 93733000 | F5: =SUMIFS('4.Đơn hàng'!$I:$I,'4.Đơn hàng'!$B:$B,$A5) -> 86789815 | G5: =SUMIFS('4.Đơn hàng'!$I:$I,'4.Đơn hàng'!$B:$B,$A5,'4.Đơn hàng'!$P:$P,G$1) -> 0 | H5: =SUMIFS('4.Đơn hàng'!$I:$I,'4.Đơn hàng'!$B:$B,$A5,'4.Đơn hàng'!$P:$P,H$1) -> 0 | I5: =SUMIFS('4.Đơn hàng'!$I:$I,'4.Đơn hàng'!$B:$B,$A5,'4.Đơn hàng'!$P:$P,I$1) -> 0 | J5: =SUMIFS('4.Đơn hàng'!$I:$I,'4.Đơn hàng'!$B:$B,$A5,'4.Đơn hàng'!$P:$P,J$1) -> 0 | K5: =SUMIFS('4.Đơn hàng'!$I:$I,'4.Đơn hàng'!$B:$B,$A5,'4.Đơn hàng'!$P:$P,K$1) -> 0 | L5: =SUMIFS('4.Đơn hàng'!$I:$I,'4.Đơn hàng'!$B:$B,$A5,'4.Đơn hàng'!$P:$P,L$1) -> 0 | M5: =SUMIFS('4.Đơn hàng'!$I:$I,'4.Đơn hàng'!$B:$B,$A5,'4.Đơn hàng'!$P:$P,M$1) -> 86789815 | N5: =SUMIFS('4.Đơn hàng'!$I:$I,'4.Đơn hàng'!$B:$B,$A5,'4.Đơn hàng'!$P:$P,N$1) -> 0 | ... R5: =SUMIFS('4.Đơn hàng'!$I:$I,'4.Đơn hàng'!$B:$B,$A5,'4.Đơn hàng'!$P:$P,R$1) -> 0
A6: DH03 | B6: =IF(A6="","",VLOOKUP($A6,'4.Đơn hàng'!$B:$E,3,0)) -> KH15 | C6: =IF(B6="","",VLOOKUP($B6,'3.Khách hàng'!$A:$I,2,0)) -> NGUYỄN THỊ YẾN | D6: =IF(A6="","",VLOOKUP($A6,'4.Đơn hàng'!$B:$N,2,0)) -> Business in the Box | E6: =SUMIF('4.Đơn hàng'!$B:$B,$A6,'4.Đơn hàng'!$H:$H) -> 81363391 | F6: =SUMIFS('4.Đơn hàng'!$I:$I,'4.Đơn hàng'!$B:$B,$A6) -> 75336473 | G6: =SUMIFS('4.Đơn hàng'!$I:$I,'4.Đơn hàng'!$B:$B,$A6,'4.Đơn hàng'!$P:$P,G$1) -> 75336473 | H6: =SUMIFS('4.Đơn hàng'!$I:$I,'4.Đơn hàng'!$B:$B,$A6,'4.Đơn hàng'!$P:$P,H$1) -> 0 | I6: =SUMIFS('4.Đơn hàng'!$I:$I,'4.Đơn hàng'!$B:$B,$A6,'4.Đơn hàng'!$P:$P,I$1) -> 0 | J6: =SUMIFS('4.Đơn hàng'!$I:$I,'4.Đơn hàng'!$B:$B,$A6,'4.Đơn hàng'!$P:$P,J$1) -> 0 | K6: =SUMIFS('4.Đơn hàng'!$I:$I,'4.Đơn hàng'!$B:$B,$A6,'4.Đơn hàng'!$P:$P,K$1) -> 0 | L6: =SUMIFS('4.Đơn hàng'!$I:$I,'4.Đơn hàng'!$B:$B,$A6,'4.Đơn hàng'!$P:$P,L$1) -> 0 | M6: =SUMIFS('4.Đơn hàng'!$I:$I,'4.Đơn hàng'!$B:$B,$A6,'4.Đơn hàng'!$P:$P,M$1) -> 0 | N6: =SUMIFS('4.Đơn hàng'!$I:$I,'4.Đơn hàng'!$B:$B,$A6,'4.Đơn hàng'!$P:$P,N$1) -> 0 | ... R6: =SUMIFS('4.Đơn hàng'!$I:$I,'4.Đơn hàng'!$B:$B,$A6,'4.Đơn hàng'!$P:$P,R$1) -> 0
A7: DH04 | B7: =IF(A7="","",VLOOKUP($A7,'4.Đơn hàng'!$B:$E,3,0)) -> KH16 | C7: =IF(B7="","",VLOOKUP($B7,'3.Khách hàng'!$A:$I,2,0)) -> CÔNG TY TNHH TINH KHÍ VIỆT | D7: =IF(A7="","",VLOOKUP($A7,'4.Đơn hàng'!$B:$N,2,0)) -> Business in the Box | E7: =SUMIF('4.Đơn hàng'!$B:$B,$A7,'4.Đơn hàng'!$H:$H) -> 81363391 | F7: =SUMIFS('4.Đơn hàng'!$I:$I,'4.Đơn hàng'!$B:$B,$A7) -> 75336473 | G7: =SUMIFS('4.Đơn hàng'!$I:$I,'4.Đơn hàng'!$B:$B,$A7,'4.Đơn hàng'!$P:$P,G$1) -> 75336473 | H7: =SUMIFS('4.Đơn hàng'!$I:$I,'4.Đơn hàng'!$B:$B,$A7,'4.Đơn hàng'!$P:$P,H$1) -> 0 | I7: =SUMIFS('4.Đơn hàng'!$I:$I,'4.Đơn hàng'!$B:$B,$A7,'4.Đơn hàng'!$P:$P,I$1) -> 0 | J7: =SUMIFS('4.Đơn hàng'!$I:$I,'4.Đơn hàng'!$B:$B,$A7,'4.Đơn hàng'!$P:$P,J$1) -> 0 | K7: =SUMIFS('4.Đơn hàng'!$I:$I,'4.Đơn hàng'!$B:$B,$A7,'4.Đơn hàng'!$P:$P,K$1) -> 0 | L7: =SUMIFS('4.Đơn hàng'!$I:$I,'4.Đơn hàng'!$B:$B,$A7,'4.Đơn hàng'!$P:$P,L$1) -> 0 | M7: =SUMIFS('4.Đơn hàng'!$I:$I,'4.Đơn hàng'!$B:$B,$A7,'4.Đơn hàng'!$P:$P,M$1) -> 0 | N7: =SUMIFS('4.Đơn hàng'!$I:$I,'4.Đơn hàng'!$B:$B,$A7,'4.Đơn hàng'!$P:$P,N$1) -> 0 | ... R7: =SUMIFS('4.Đơn hàng'!$I:$I,'4.Đơn hàng'!$B:$B,$A7,'4.Đơn hàng'!$P:$P,R$1) -> 0
A8: DH05 | B8: =IF(A8="","",VLOOKUP($A8,'4.Đơn hàng'!$B:$E,3,0)) -> KH17 | C8: =IF(B8="","",VLOOKUP($B8,'3.Khách hàng'!$A:$I,2,0)) -> CÔNG TY TNHH PAPASAN VIỆT NAM | D8: =IF(A8="","",VLOOKUP($A8,'4.Đơn hàng'!$B:$N,2,0)) -> Lãnh đạo chuyển hóa | E8: =SUMIF('4.Đơn hàng'!$B:$B,$A8,'4.Đơn hàng'!$H:$H) -> 1774801 | F8: =SUMIFS('4.Đơn hàng'!$I:$I,'4.Đơn hàng'!$B:$B,$A8) -> 1643334.3 | G8: =SUMIFS('4.Đơn hàng'!$I:$I,'4.Đơn hàng'!$B:$B,$A8,'4.Đơn hàng'!$P:$P,G$1) -> 0 | H8: =SUMIFS('4.Đơn hàng'!$I:$I,'4.Đơn hàng'!$B:$B,$A8,'4.Đơn hàng'!$P:$P,H$1) -> 0 | I8: =SUMIFS('4.Đơn hàng'!$I:$I,'4.Đơn hàng'!$B:$B,$A8,'4.Đơn hàng'!$P:$P,I$1) -> 0 | J8: =SUMIFS('4.Đơn hàng'!$I:$I,'4.Đơn hàng'!$B:$B,$A8,'4.Đơn hàng'!$P:$P,J$1) -> 1643334.3 | K8: =SUMIFS('4.Đơn hàng'!$I:$I,'4.Đơn hàng'!$B:$B,$A8,'4.Đơn hàng'!$P:$P,K$1) -> 0 | L8: =SUMIFS('4.Đơn hàng'!$I:$I,'4.Đơn hàng'!$B:$B,$A8,'4.Đơn hàng'!$P:$P,L$1) -> 0 | M8: =SUMIFS('4.Đơn hàng'!$I:$I,'4.Đơn hàng'!$B:$B,$A8,'4.Đơn hàng'!$P:$P,M$1) -> 0 | N8: =SUMIFS('4.Đơn hàng'!$I:$I,'4.Đơn hàng'!$B:$B,$A8,'4.Đơn hàng'!$P:$P,N$1) -> 0 | ... R8: =SUMIFS('4.Đơn hàng'!$I:$I,'4.Đơn hàng'!$B:$B,$A8,'4.Đơn hàng'!$P:$P,R$1) -> 0
B9: =IF(A9="","",VLOOKUP($A9,'4.Đơn hàng'!$B:$E,3,0)) | C9: =IF(B9="","",VLOOKUP($B9,'3.Khách hàng'!$A:$I,2,0)) | D9: =IF(A9="","",VLOOKUP($A9,'4.Đơn hàng'!$B:$N,2,0)) | E9: =SUMIF('4.Đơn hàng'!$B:$B,$A9,'4.Đơn hàng'!$H:$H) -> 0 | F9: =SUMIFS('4.Đơn hàng'!$I:$I,'4.Đơn hàng'!$B:$B,$A9) -> 0 | G9: =SUMIFS('4.Đơn hàng'!$I:$I,'4.Đơn hàng'!$B:$B,$A9,'4.Đơn hàng'!$P:$P,G$1) -> 0 | H9: =SUMIFS('4.Đơn hàng'!$I:$I,'4.Đơn hàng'!$B:$B,$A9,'4.Đơn hàng'!$P:$P,H$1) -> 0 | I9: =SUMIFS('4.Đơn hàng'!$I:$I,'4.Đơn hàng'!$B:$B,$A9,'4.Đơn hàng'!$P:$P,I$1) -> 0 | J9: =SUMIFS('4.Đơn hàng'!$I:$I,'4.Đơn hàng'!$B:$B,$A9,'4.Đơn hàng'!$P:$P,J$1) -> 0 | K9: =SUMIFS('4.Đơn hàng'!$I:$I,'4.Đơn hàng'!$B:$B,$A9,'4.Đơn hàng'!$P:$P,K$1) -> 0 | L9: =SUMIFS('4.Đơn hàng'!$I:$I,'4.Đơn hàng'!$B:$B,$A9,'4.Đơn hàng'!$P:$P,L$1) -> 0 | M9: =SUMIFS('4.Đơn hàng'!$I:$I,'4.Đơn hàng'!$B:$B,$A9,'4.Đơn hàng'!$P:$P,M$1) -> 0 | N9: =SUMIFS('4.Đơn hàng'!$I:$I,'4.Đơn hàng'!$B:$B,$A9,'4.Đơn hàng'!$P:$P,N$1) -> 0 | ... R9: =SUMIFS('4.Đơn hàng'!$I:$I,'4.Đơn hàng'!$B:$B,$A9,'4.Đơn hàng'!$P:$P,R$1) -> 0
B10: =IF(A10="","",VLOOKUP($A10,'4.Đơn hàng'!$B:$E,3,0)) | C10: =IF(B10="","",VLOOKUP($B10,'3.Khách hàng'!$A:$I,2,0)) | D10: =IF(A10="","",VLOOKUP($A10,'4.Đơn hàng'!$B:$N,2,0)) | E10: =SUMIF('4.Đơn hàng'!$B:$B,$A10,'4.Đơn hàng'!$H:$H) -> 0 | F10: =SUMIFS('4.Đơn hàng'!$I:$I,'4.Đơn hàng'!$B:$B,$A10) -> 0 | G10: =SUMIFS('4.Đơn hàng'!$I:$I,'4.Đơn hàng'!$B:$B,$A10,'4.Đơn hàng'!$P:$P,G$1) -> 0 | H10: =SUMIFS('4.Đơn hàng'!$I:$I,'4.Đơn hàng'!$B:$B,$A10,'4.Đơn hàng'!$P:$P,H$1) -> 0 | I10: =SUMIFS('4.Đơn hàng'!$I:$I,'4.Đơn hàng'!$B:$B,$A10,'4.Đơn hàng'!$P:$P,I$1) -> 0 | J10: =SUMIFS('4.Đơn hàng'!$I:$I,'4.Đơn hàng'!$B:$B,$A10,'4.Đơn hàng'!$P:$P,J$1) -> 0 | K10: =SUMIFS('4.Đơn hàng'!$I:$I,'4.Đơn hàng'!$B:$B,$A10,'4.Đơn hàng'!$P:$P,K$1) -> 0 | L10: =SUMIFS('4.Đơn hàng'!$I:$I,'4.Đơn hàng'!$B:$B,$A10,'4.Đơn hàng'!$P:$P,L$1) -> 0 | M10: =SUMIFS('4.Đơn hàng'!$I:$I,'4.Đơn hàng'!$B:$B,$A10,'4.Đơn hàng'!$P:$P,M$1) -> 0 | N10: =SUMIFS('4.Đơn hàng'!$I:$I,'4.Đơn hàng'!$B:$B,$A10,'4.Đơn hàng'!$P:$P,N$1) -> 0 | ... R10: =SUMIFS('4.Đơn hàng'!$I:$I,'4.Đơn hàng'!$B:$B,$A10,'4.Đơn hàng'!$P:$P,R$1) -> 0
B11: =IF(A11="","",VLOOKUP($A11,'4.Đơn hàng'!$B:$E,3,0)) | C11: =IF(B11="","",VLOOKUP($B11,'3.Khách hàng'!$A:$I,2,0)) | D11: =IF(A11="","",VLOOKUP($A11,'4.Đơn hàng'!$B:$N,2,0)) | E11: =SUMIF('4.Đơn hàng'!$B:$B,$A11,'4.Đơn hàng'!$H:$H) -> 0 | F11: =SUMIFS('4.Đơn hàng'!$I:$I,'4.Đơn hàng'!$B:$B,$A11) -> 0 | G11: =SUMIFS('4.Đơn hàng'!$I:$I,'4.Đơn hàng'!$B:$B,$A11,'4.Đơn hàng'!$P:$P,G$1) -> 0 | H11: =SUMIFS('4.Đơn hàng'!$I:$I,'4.Đơn hàng'!$B:$B,$A11,'4.Đơn hàng'!$P:$P,H$1) -> 0 | I11: =SUMIFS('4.Đơn hàng'!$I:$I,'4.Đơn hàng'!$B:$B,$A11,'4.Đơn hàng'!$P:$P,I$1) -> 0 | J11: =SUMIFS('4.Đơn hàng'!$I:$I,'4.Đơn hàng'!$B:$B,$A11,'4.Đơn hàng'!$P:$P,J$1) -> 0 | K11: =SUMIFS('4.Đơn hàng'!$I:$I,'4.Đơn hàng'!$B:$B,$A11,'4.Đơn hàng'!$P:$P,K$1) -> 0 | L11: =SUMIFS('4.Đơn hàng'!$I:$I,'4.Đơn hàng'!$B:$B,$A11,'4.Đơn hàng'!$P:$P,L$1) -> 0 | M11: =SUMIFS('4.Đơn hàng'!$I:$I,'4.Đơn hàng'!$B:$B,$A11,'4.Đơn hàng'!$P:$P,M$1) -> 0 | N11: =SUMIFS('4.Đơn hàng'!$I:$I,'4.Đơn hàng'!$B:$B,$A11,'4.Đơn hàng'!$P:$P,N$1) -> 0 | ... R11: =SUMIFS('4.Đơn hàng'!$I:$I,'4.Đơn hàng'!$B:$B,$A11,'4.Đơn hàng'!$P:$P,R$1) -> 0
B12: =IF(A12="","",VLOOKUP($A12,'4.Đơn hàng'!$B:$E,3,0)) | C12: =IF(B12="","",VLOOKUP($B12,'3.Khách hàng'!$A:$I,2,0)) | D12: =IF(A12="","",VLOOKUP($A12,'4.Đơn hàng'!$B:$N,2,0)) | E12: =SUMIF('4.Đơn hàng'!$B:$B,$A12,'4.Đơn hàng'!$H:$H) -> 0 | F12: =SUMIFS('4.Đơn hàng'!$I:$I,'4.Đơn hàng'!$B:$B,$A12) -> 0 | G12: =SUMIFS('4.Đơn hàng'!$I:$I,'4.Đơn hàng'!$B:$B,$A12,'4.Đơn hàng'!$P:$P,G$1) -> 0 | H12: =SUMIFS('4.Đơn hàng'!$I:$I,'4.Đơn hàng'!$B:$B,$A12,'4.Đơn hàng'!$P:$P,H$1) -> 0 | I12: =SUMIFS('4.Đơn hàng'!$I:$I,'4.Đơn hàng'!$B:$B,$A12,'4.Đơn hàng'!$P:$P,I$1) -> 0 | J12: =SUMIFS('4.Đơn hàng'!$I:$I,'4.Đơn hàng'!$B:$B,$A12,'4.Đơn hàng'!$P:$P,J$1) -> 0 | K12: =SUMIFS('4.Đơn hàng'!$I:$I,'4.Đơn hàng'!$B:$B,$A12,'4.Đơn hàng'!$P:$P,K$1) -> 0 | L12: =SUMIFS('4.Đơn hàng'!$I:$I,'4.Đơn hàng'!$B:$B,$A12,'4.Đơn hàng'!$P:$P,L$1) -> 0 | M12: =SUMIFS('4.Đơn hàng'!$I:$I,'4.Đơn hàng'!$B:$B,$A12,'4.Đơn hàng'!$P:$P,M$1) -> 0 | N12: =SUMIFS('4.Đơn hàng'!$I:$I,'4.Đơn hàng'!$B:$B,$A12,'4.Đơn hàng'!$P:$P,N$1) -> 0 | ... R12: =SUMIFS('4.Đơn hàng'!$I:$I,'4.Đơn hàng'!$B:$B,$A12,'4.Đơn hàng'!$P:$P,R$1) -> 0
B13: =IF(A13="","",VLOOKUP($A13,'4.Đơn hàng'!$B:$E,3,0)) | C13: =IF(B13="","",VLOOKUP($B13,'3.Khách hàng'!$A:$I,2,0)) | D13: =IF(A13="","",VLOOKUP($A13,'4.Đơn hàng'!$B:$N,2,0)) | E13: =SUMIF('4.Đơn hàng'!$B:$B,$A13,'4.Đơn hàng'!$H:$H) -> 0 | F13: =SUMIFS('4.Đơn hàng'!$I:$I,'4.Đơn hàng'!$B:$B,$A13) -> 0 | G13: =SUMIFS('4.Đơn hàng'!$I:$I,'4.Đơn hàng'!$B:$B,$A13,'4.Đơn hàng'!$P:$P,G$1) -> 0 | H13: =SUMIFS('4.Đơn hàng'!$I:$I,'4.Đơn hàng'!$B:$B,$A13,'4.Đơn hàng'!$P:$P,H$1) -> 0 | I13: =SUMIFS('4.Đơn hàng'!$I:$I,'4.Đơn hàng'!$B:$B,$A13,'4.Đơn hàng'!$P:$P,I$1) -> 0 | J13: =SUMIFS('4.Đơn hàng'!$I:$I,'4.Đơn hàng'!$B:$B,$A13,'4.Đơn hàng'!$P:$P,J$1) -> 0 | K13: =SUMIFS('4.Đơn hàng'!$I:$I,'4.Đơn hàng'!$B:$B,$A13,'4.Đơn hàng'!$P:$P,K$1) -> 0 | L13: =SUMIFS('4.Đơn hàng'!$I:$I,'4.Đơn hàng'!$B:$B,$A13,'4.Đơn hàng'!$P:$P,L$1) -> 0 | M13: =SUMIFS('4.Đơn hàng'!$I:$I,'4.Đơn hàng'!$B:$B,$A13,'4.Đơn hàng'!$P:$P,M$1) -> 0 | N13: =SUMIFS('4.Đơn hàng'!$I:$I,'4.Đơn hàng'!$B:$B,$A13,'4.Đơn hàng'!$P:$P,N$1) -> 0 | ... R13: =SUMIFS('4.Đơn hàng'!$I:$I,'4.Đơn hàng'!$B:$B,$A13,'4.Đơn hàng'!$P:$P,R$1) -> 0
